{
  "version": 8,
  "blockIdVersion": 11,
  "anchorX": 0,
  "anchorY": 1,
  "anchorZ": 0,
  "blocks": [
    {
      "x": -7,
      "y": 6,
      "z": -6,
      "name": "*Wood_Darkwood_Roof_Steep_State_Definitions_Corner_Left",
      "rotation": 2
    },
    {
      "x": -7,
      "y": 7,
      "z": -6,
      "name": "*Wood_Darkwood_Roof_Steep_State_Definitions_Corner_Left",
      "filler": 1024,
      "rotation": 2
    },
    {
      "x": -7,
      "y": 1,
      "z": -5,
      "name": "Rock_Marble_Brick_Smooth_Half",
      "rotation": 7
    },
    {
      "x": -7,
      "y": 3,
      "z": -5,
      "name": "Rock_Marble_Brick_Smooth_Half",
      "rotation": 7
    },
    {
      "x": -7,
      "y": 6,
      "z": -5,
      "name": "Wood_Darkwood_Roof_Steep",
      "rotation": 3
    },
    {
      "x": -7,
      "y": 7,
      "z": -5,
      "name": "Wood_Darkwood_Roof_Steep",
      "filler": 1024,
      "rotation": 3
    },
    {
      "x": -7,
      "y": 1,
      "z": -4,
      "name": "Rock_Marble_Brick_Smooth_Half",
      "rotation": 7
    },
    {
      "x": -7,
      "y": 3,
      "z": -4,
      "name": "Rock_Marble_Brick_Smooth_Half",
      "rotation": 7
    },
    {
      "x": -7,
      "y": 6,
      "z": -4,
      "name": "Wood_Darkwood_Roof_Steep",
      "rotation": 3
    },
    {
      "x": -7,
      "y": 7,
      "z": -4,
      "name": "Wood_Darkwood_Roof_Steep",
      "filler": 1024,
      "rotation": 3
    },
    {
      "x": -7,
      "y": 1,
      "z": -3,
      "name": "Rock_Marble_Brick_Smooth_Half",
      "rotation": 7
    },
    {
      "x": -7,
      "y": 3,
      "z": -3,
      "name": "Rock_Marble_Brick_Smooth_Half",
      "rotation": 7
    },
    {
      "x": -7,
      "y": 6,
      "z": -3,
      "name": "Wood_Darkwood_Roof_Steep",
      "rotation": 3
    },
    {
      "x": -7,
      "y": 7,
      "z": -3,
      "name": "Wood_Darkwood_Roof_Steep",
      "filler": 1024,
      "rotation": 3
    },
    {
      "x": -7,
      "y": 1,
      "z": -2,
      "name": "Rock_Marble_Brick_Smooth_Half",
      "rotation": 7
    },
    {
      "x": -7,
      "y": 3,
      "z": -2,
      "name": "Rock_Marble_Brick_Smooth_Half",
      "rotation": 7
    },
    {
      "x": -7,
      "y": 6,
      "z": -2,
      "name": "Wood_Darkwood_Roof_Steep",
      "rotation": 3
    },
    {
      "x": -7,
      "y": 7,
      "z": -2,
      "name": "Wood_Darkwood_Roof_Steep",
      "filler": 1024,
      "rotation": 3
    },
    {
      "x": -7,
      "y": 1,
      "z": -1,
      "name": "Rock_Marble_Brick_Smooth_Half",
      "rotation": 7
    },
    {
      "x": -7,
      "y": 3,
      "z": -1,
      "name": "Rock_Marble_Brick_Smooth_Half",
      "rotation": 7
    },
    {
      "x": -7,
      "y": 6,
      "z": -1,
      "name": "Wood_Darkwood_Roof_Steep",
      "rotation": 3
    },
    {
      "x": -7,
      "y": 7,
      "z": -1,
      "name": "Wood_Darkwood_Roof_Steep",
      "filler": 1024,
      "rotation": 3
    },
    {
      "x": -7,
      "y": 1,
      "z": 0,
      "name": "Rock_Marble_Brick_Smooth_Half",
      "rotation": 7
    },
    {
      "x": -7,
      "y": 3,
      "z": 0,
      "name": "Rock_Marble_Brick_Smooth_Half",
      "rotation": 7
    },
    {
      "x": -7,
      "y": 6,
      "z": 0,
      "name": "Wood_Darkwood_Roof_Steep",
      "rotation": 3
    },
    {
      "x": -7,
      "y": 7,
      "z": 0,
      "name": "Wood_Darkwood_Roof_Steep",
      "filler": 1024,
      "rotation": 3
    },
    {
      "x": -7,
      "y": 1,
      "z": 1,
      "name": "Rock_Marble_Brick_Smooth_Half",
      "rotation": 7
    },
    {
      "x": -7,
      "y": 3,
      "z": 1,
      "name": "Rock_Marble_Brick_Smooth_Half",
      "rotation": 7
    },
    {
      "x": -7,
      "y": 6,
      "z": 1,
      "name": "Wood_Darkwood_Roof_Steep",
      "rotation": 3
    },
    {
      "x": -7,
      "y": 7,
      "z": 1,
      "name": "Wood_Darkwood_Roof_Steep",
      "filler": 1024,
      "rotation": 3
    },
    {
      "x": -7,
      "y": 1,
      "z": 2,
      "name": "Rock_Marble_Brick_Smooth_Half",
      "rotation": 7
    },
    {
      "x": -7,
      "y": 3,
      "z": 2,
      "name": "Rock_Marble_Brick_Smooth_Half",
      "rotation": 7
    },
    {
      "x": -7,
      "y": 6,
      "z": 2,
      "name": "Wood_Darkwood_Roof_Steep",
      "rotation": 3
    },
    {
      "x": -7,
      "y": 7,
      "z": 2,
      "name": "Wood_Darkwood_Roof_Steep",
      "filler": 1024,
      "rotation": 3
    },
    {
      "x": -7,
      "y": 1,
      "z": 3,
      "name": "Rock_Marble_Brick_Smooth_Half",
      "rotation": 7
    },
    {
      "x": -7,
      "y": 3,
      "z": 3,
      "name": "Rock_Marble_Brick_Smooth_Half",
      "rotation": 7
    },
    {
      "x": -7,
      "y": 6,
      "z": 3,
      "name": "Wood_Darkwood_Roof_Steep",
      "rotation": 3
    },
    {
      "x": -7,
      "y": 7,
      "z": 3,
      "name": "Wood_Darkwood_Roof_Steep",
      "filler": 1024,
      "rotation": 3
    },
    {
      "x": -7,
      "y": 6,
      "z": 4,
      "name": "*Wood_Darkwood_Roof_Steep_State_Definitions_Corner_Left",
      "rotation": 3
    },
    {
      "x": -7,
      "y": 7,
      "z": 4,
      "name": "*Wood_Darkwood_Roof_Steep_State_Definitions_Corner_Left",
      "filler": 1024,
      "rotation": 3
    },
    {
      "x": -6,
      "y": 1,
      "z": -6,
      "name": "Rock_Marble_Brick_Smooth_Half",
      "rotation": 6
    },
    {
      "x": -6,
      "y": 3,
      "z": -6,
      "name": "Rock_Marble_Brick_Smooth_Half",
      "rotation": 6
    },
    {
      "x": -6,
      "y": 6,
      "z": -6,
      "name": "Wood_Darkwood_Roof_Steep",
      "rotation": 2
    },
    {
      "x": -6,
      "y": 7,
      "z": -6,
      "name": "Wood_Darkwood_Roof_Steep",
      "filler": 1024,
      "rotation": 2
    },
    {
      "x": -6,
      "y": 0,
      "z": -5,
      "name": "Rock_Stone"
    },
    {
      "x": -6,
      "y": 1,
      "z": -5,
      "name": "Rock_Marble_Brick"
    },
    {
      "x": -6,
      "y": 2,
      "z": -5,
      "name": "Rock_Marble_Brick"
    },
    {
      "x": -6,
      "y": 3,
      "z": -5,
      "name": "Rock_Marble_Brick"
    },
    {
      "x": -6,
      "y": 4,
      "z": -5,
      "name": "Rock_Marble_Brick"
    },
    {
      "x": -6,
      "y": 5,
      "z": -5,
      "name": "Rock_Marble_Brick"
    },
    {
      "x": -6,
      "y": 8,
      "z": -5,
      "name": "*Wood_Darkwood_Roof_Hollow_State_Definitions_Corner_Left",
      "rotation": 2
    },
    {
      "x": -6,
      "y": 0,
      "z": -4,
      "name": "Rock_Stone"
    },
    {
      "x": -6,
      "y": 1,
      "z": -4,
      "name": "Rock_Marble_Brick"
    },
    {
      "x": -6,
      "y": 2,
      "z": -4,
      "name": "Rock_Marble_Brick"
    },
    {
      "x": -6,
      "y": 3,
      "z": -4,
      "name": "Rock_Marble_Brick"
    },
    {
      "x": -6,
      "y": 4,
      "z": -4,
      "name": "Rock_Marble_Brick"
    },
    {
      "x": -6,
      "y": 5,
      "z": -4,
      "name": "Rock_Marble_Brick"
    },
    {
      "x": -6,
      "y": 8,
      "z": -4,
      "name": "Wood_Darkwood_Roof_Hollow",
      "rotation": 3
    },
    {
      "x": -6,
      "y": 0,
      "z": -3,
      "name": "Rock_Stone"
    },
    {
      "x": -6,
      "y": 1,
      "z": -3,
      "name": "Rock_Marble_Brick"
    },
    {
      "x": -6,
      "y": 2,
      "z": -3,
      "name": "Rock_Marble_Brick"
    },
    {
      "x": -6,
      "y": 3,
      "z": -3,
      "name": "Rock_Marble_Brick"
    },
    {
      "x": -6,
      "y": 4,
      "z": -3,
      "name": "Furniture_Temple_Light_Window",
      "rotation": 1
    },
    {
      "x": -6,
      "y": 5,
      "z": -3,
      "name": "Rock_Marble_Brick"
    },
    {
      "x": -6,
      "y": 8,
      "z": -3,
      "name": "Wood_Darkwood_Roof_Hollow",
      "rotation": 3
    },
    {
      "x": -6,
      "y": 0,
      "z": -2,
      "name": "Rock_Stone"
    },
    {
      "x": -6,
      "y": 1,
      "z": -2,
      "name": "Rock_Marble_Brick"
    },
    {
      "x": -6,
      "y": 2,
      "z": -2,
      "name": "Rock_Marble_Brick"
    },
    {
      "x": -6,
      "y": 3,
      "z": -2,
      "name": "Rock_Marble_Brick"
    },
    {
      "x": -6,
      "y": 4,
      "z": -2,
      "name": "Rock_Marble_Brick"
    },
    {
      "x": -6,
      "y": 5,
      "z": -2,
      "name": "Rock_Marble_Brick"
    },
    {
      "x": -6,
      "y": 8,
      "z": -2,
      "name": "Wood_Darkwood_Roof_Hollow",
      "rotation": 3
    },
    {
      "x": -6,
      "y": 0,
      "z": -1,
      "name": "Rock_Stone"
    },
    {
      "x": -6,
      "y": 1,
      "z": -1,
      "name": "Rock_Marble_Brick"
    },
    {
      "x": -6,
      "y": 2,
      "z": -1,
      "name": "Rock_Marble_Brick"
    },
    {
      "x": -6,
      "y": 3,
      "z": -1,
      "name": "Rock_Marble_Brick"
    },
    {
      "x": -6,
      "y": 4,
      "z": -1,
      "name": "Furniture_Temple_Light_Window",
      "rotation": 1
    },
    {
      "x": -6,
      "y": 5,
      "z": -1,
      "name": "Rock_Marble_Brick"
    },
    {
      "x": -6,
      "y": 8,
      "z": -1,
      "name": "Wood_Darkwood_Roof_Hollow",
      "rotation": 3
    },
    {
      "x": -6,
      "y": 0,
      "z": 0,
      "name": "Rock_Stone"
    },
    {
      "x": -6,
      "y": 1,
      "z": 0,
      "name": "Rock_Marble_Brick"
    },
    {
      "x": -6,
      "y": 2,
      "z": 0,
      "name": "Rock_Marble_Brick"
    },
    {
      "x": -6,
      "y": 3,
      "z": 0,
      "name": "Rock_Marble_Brick"
    },
    {
      "x": -6,
      "y": 4,
      "z": 0,
      "name": "Rock_Marble_Brick"
    },
    {
      "x": -6,
      "y": 5,
      "z": 0,
      "name": "Rock_Marble_Brick"
    },
    {
      "x": -6,
      "y": 8,
      "z": 0,
      "name": "Wood_Darkwood_Roof_Hollow",
      "rotation": 3
    },
    {
      "x": -6,
      "y": 0,
      "z": 1,
      "name": "Rock_Stone"
    },
    {
      "x": -6,
      "y": 1,
      "z": 1,
      "name": "Rock_Marble_Brick"
    },
    {
      "x": -6,
      "y": 2,
      "z": 1,
      "name": "Rock_Marble_Brick"
    },
    {
      "x": -6,
      "y": 3,
      "z": 1,
      "name": "Rock_Marble_Brick"
    },
    {
      "x": -6,
      "y": 4,
      "z": 1,
      "name": "Furniture_Temple_Light_Window",
      "rotation": 1
    },
    {
      "x": -6,
      "y": 5,
      "z": 1,
      "name": "Rock_Marble_Brick"
    },
    {
      "x": -6,
      "y": 8,
      "z": 1,
      "name": "Wood_Darkwood_Roof_Hollow",
      "rotation": 3
    },
    {
      "x": -6,
      "y": 0,
      "z": 2,
      "name": "Rock_Stone"
    },
    {
      "x": -6,
      "y": 1,
      "z": 2,
      "name": "Rock_Marble_Brick"
    },
    {
      "x": -6,
      "y": 2,
      "z": 2,
      "name": "Rock_Marble_Brick"
    },
    {
      "x": -6,
      "y": 3,
      "z": 2,
      "name": "Rock_Marble_Brick"
    },
    {
      "x": -6,
      "y": 4,
      "z": 2,
      "name": "Rock_Marble_Brick"
    },
    {
      "x": -6,
      "y": 5,
      "z": 2,
      "name": "Rock_Marble_Brick"
    },
    {
      "x": -6,
      "y": 8,
      "z": 2,
      "name": "Wood_Darkwood_Roof_Hollow",
      "rotation": 3
    },
    {
      "x": -6,
      "y": 0,
      "z": 3,
      "name": "Rock_Stone"
    },
    {
      "x": -6,
      "y": 1,
      "z": 3,
      "name": "Rock_Marble_Brick"
    },
    {
      "x": -6,
      "y": 2,
      "z": 3,
      "name": "Rock_Marble_Brick"
    },
    {
      "x": -6,
      "y": 3,
      "z": 3,
      "name": "Rock_Marble_Brick"
    },
    {
      "x": -6,
      "y": 4,
      "z": 3,
      "name": "Rock_Marble_Brick"
    },
    {
      "x": -6,
      "y": 5,
      "z": 3,
      "name": "Rock_Marble_Brick"
    },
    {
      "x": -6,
      "y": 8,
      "z": 3,
      "name": "*Wood_Darkwood_Roof_Hollow_State_Definitions_Corner_Left",
      "rotation": 3
    },
    {
      "x": -6,
      "y": 1,
      "z": 4,
      "name": "Rock_Marble_Brick_Smooth_Half",
      "rotation": 4
    },
    {
      "x": -6,
      "y": 3,
      "z": 4,
      "name": "Rock_Marble_Brick_Smooth_Half",
      "rotation": 4
    },
    {
      "x": -6,
      "y": 6,
      "z": 4,
      "name": "Wood_Darkwood_Roof_Steep"
    },
    {
      "x": -6,
      "y": 7,
      "z": 4,
      "name": "Wood_Darkwood_Roof_Steep",
      "filler": 1024
    },
    {
      "x": -5,
      "y": 1,
      "z": -8,
      "name": "Empty"
    },
    {
      "x": -5,
      "y": 2,
      "z": -8,
      "name": "Empty"
    },
    {
      "x": -5,
      "y": 3,
      "z": -8,
      "name": "Empty"
    },
    {
      "x": -5,
      "y": 0,
      "z": -7,
      "name": "Soil_Grass"
    },
    {
      "x": -5,
      "y": 1,
      "z": -7,
      "name": "Empty"
    },
    {
      "x": -5,
      "y": 2,
      "z": -7,
      "name": "Empty"
    },
    {
      "x": -5,
      "y": 3,
      "z": -7,
      "name": "Empty"
    },
    {
      "x": -5,
      "y": 0,
      "z": -6,
      "name": "Soil_Grass"
    },
    {
      "x": -5,
      "y": 1,
      "z": -6,
      "name": "Rock_Marble_Brick_Smooth_Half",
      "rotation": 6
    },
    {
      "x": -5,
      "y": 3,
      "z": -6,
      "name": "Rock_Marble_Brick_Smooth_Half",
      "rotation": 6
    },
    {
      "x": -5,
      "y": 6,
      "z": -6,
      "name": "Wood_Darkwood_Roof_Steep",
      "rotation": 2
    },
    {
      "x": -5,
      "y": 7,
      "z": -6,
      "name": "Wood_Darkwood_Roof_Steep",
      "filler": 1024,
      "rotation": 2
    },
    {
      "x": -5,
      "y": 0,
      "z": -5,
      "name": "Rock_Stone"
    },
    {
      "x": -5,
      "y": 1,
      "z": -5,
      "name": "Rock_Marble_Brick"
    },
    {
      "x": -5,
      "y": 2,
      "z": -5,
      "name": "Rock_Marble_Brick"
    },
    {
      "x": -5,
      "y": 3,
      "z": -5,
      "name": "Rock_Marble_Brick"
    },
    {
      "x": -5,
      "y": 4,
      "z": -5,
      "name": "Rock_Marble_Brick"
    },
    {
      "x": -5,
      "y": 5,
      "z": -5,
      "name": "Rock_Marble_Brick"
    },
    {
      "x": -5,
      "y": 8,
      "z": -5,
      "name": "Wood_Darkwood_Roof_Hollow",
      "rotation": 2
    },
    {
      "x": -5,
      "y": 0,
      "z": -4,
      "name": "Rock_Stone"
    },
    {
      "x": -5,
      "y": 1,
      "z": -4,
      "name": "Rock_Lime_Brick_Smooth"
    },
    {
      "x": -5,
      "y": 2,
      "z": -4,
      "name": "Furniture_Village_Table"
    },
    {
      "x": -5,
      "y": 5,
      "z": -4,
      "name": "Deco_Lantern_Ceiling"
    },
    {
      "x": -5,
      "y": 6,
      "z": -4,
      "name": "Wood_Drywood_Decorative"
    },
    {
      "x": -5,
      "y": 7,
      "z": -4,
      "name": "Deco_Lantern"
    },
    {
      "x": -5,
      "y": 9,
      "z": -4,
      "name": "Wood_Darkwood_Roof_Flat",
      "rotation": 1
    },
    {
      "x": -5,
      "y": 0,
      "z": -3,
      "name": "Rock_Stone"
    },
    {
      "x": -5,
      "y": 1,
      "z": -3,
      "name": "Rock_Lime_Brick_Smooth"
    },
    {
      "x": -5,
      "y": 2,
      "z": -3,
      "name": "Furniture_Village_Table",
      "filler": 32
    },
    {
      "x": -5,
      "y": 5,
      "z": -3,
      "name": "Wood_Drywood_Planks_Half",
      "rotation": 8
    },
    {
      "x": -5,
      "y": 9,
      "z": -3,
      "name": "Wood_Darkwood_Roof_Flat",
      "rotation": 1
    },
    {
      "x": -5,
      "y": 0,
      "z": -2,
      "name": "Rock_Stone"
    },
    {
      "x": -5,
      "y": 1,
      "z": -2,
      "name": "Rock_Lime_Brick_Smooth"
    },
    {
      "x": -5,
      "y": 2,
      "z": -2,
      "name": "Furniture_Village_Stool",
      "components": {
        "Components": {}
      },
      "rotation": 2
    },
    {
      "x": -5,
      "y": 5,
      "z": -2,
      "name": "Wood_Drywood_Planks_Half",
      "rotation": 8
    },
    {
      "x": -5,
      "y": 9,
      "z": -2,
      "name": "Wood_Darkwood_Roof_Flat",
      "rotation": 1
    },
    {
      "x": -5,
      "y": 0,
      "z": -1,
      "name": "Rock_Stone"
    },
    {
      "x": -5,
      "y": 1,
      "z": -1,
      "name": "Rock_Lime_Brick_Smooth"
    },
    {
      "x": -5,
      "y": 5,
      "z": -1,
      "name": "Wood_Drywood_Planks_Half",
      "rotation": 8
    },
    {
      "x": -5,
      "y": 9,
      "z": -1,
      "name": "Wood_Darkwood_Roof_Flat",
      "rotation": 1
    },
    {
      "x": -5,
      "y": 0,
      "z": 0,
      "name": "Rock_Stone"
    },
    {
      "x": -5,
      "y": 1,
      "z": 0,
      "name": "Rock_Lime_Brick_Smooth"
    },
    {
      "x": -5,
      "y": 5,
      "z": 0,
      "name": "Wood_Drywood_Planks_Half",
      "rotation": 8
    },
    {
      "x": -5,
      "y": 9,
      "z": 0,
      "name": "Wood_Darkwood_Roof_Flat",
      "rotation": 1
    },
    {
      "x": -5,
      "y": 0,
      "z": 1,
      "name": "Rock_Stone"
    },
    {
      "x": -5,
      "y": 1,
      "z": 1,
      "name": "Rock_Lime_Brick_Smooth"
    },
    {
      "x": -5,
      "y": 5,
      "z": 1,
      "name": "Wood_Drywood_Planks_Half",
      "rotation": 8
    },
    {
      "x": -5,
      "y": 9,
      "z": 1,
      "name": "Wood_Darkwood_Roof_Flat",
      "rotation": 1
    },
    {
      "x": -5,
      "y": 0,
      "z": 2,
      "name": "Rock_Stone"
    },
    {
      "x": -5,
      "y": 1,
      "z": 2,
      "name": "Rock_Lime_Brick_Smooth"
    },
    {
      "x": -5,
      "y": 5,
      "z": 2,
      "name": "Deco_Lantern_Ceiling"
    },
    {
      "x": -5,
      "y": 6,
      "z": 2,
      "name": "Wood_Drywood_Decorative"
    },
    {
      "x": -5,
      "y": 7,
      "z": 2,
      "name": "Deco_Lantern"
    },
    {
      "x": -5,
      "y": 9,
      "z": 2,
      "name": "Wood_Darkwood_Roof_Flat",
      "rotation": 1
    },
    {
      "x": -5,
      "y": 0,
      "z": 3,
      "name": "Rock_Stone"
    },
    {
      "x": -5,
      "y": 1,
      "z": 3,
      "name": "Rock_Marble_Brick"
    },
    {
      "x": -5,
      "y": 2,
      "z": 3,
      "name": "Rock_Marble_Brick"
    },
    {
      "x": -5,
      "y": 3,
      "z": 3,
      "name": "Rock_Marble_Brick"
    },
    {
      "x": -5,
      "y": 4,
      "z": 3,
      "name": "Rock_Marble_Brick"
    },
    {
      "x": -5,
      "y": 5,
      "z": 3,
      "name": "Rock_Marble_Brick"
    },
    {
      "x": -5,
      "y": 8,
      "z": 3,
      "name": "Wood_Darkwood_Roof_Hollow"
    },
    {
      "x": -5,
      "y": 1,
      "z": 4,
      "name": "Rock_Marble_Brick_Smooth_Half",
      "rotation": 4
    },
    {
      "x": -5,
      "y": 3,
      "z": 4,
      "name": "Rock_Marble_Brick_Smooth_Half",
      "rotation": 4
    },
    {
      "x": -5,
      "y": 6,
      "z": 4,
      "name": "Wood_Darkwood_Roof_Steep"
    },
    {
      "x": -5,
      "y": 7,
      "z": 4,
      "name": "Wood_Darkwood_Roof_Steep",
      "filler": 1024
    },
    {
      "x": -4,
      "y": 1,
      "z": -8,
      "name": "Empty"
    },
    {
      "x": -4,
      "y": 2,
      "z": -8,
      "name": "Empty"
    },
    {
      "x": -4,
      "y": 3,
      "z": -8,
      "name": "Empty"
    },
    {
      "x": -4,
      "y": 0,
      "z": -7,
      "name": "Soil_Grass"
    },
    {
      "x": -4,
      "y": 1,
      "z": -7,
      "name": "Bench_Trough",
      "filler": 31
    },
    {
      "x": -4,
      "y": 2,
      "z": -7,
      "name": "Empty"
    },
    {
      "x": -4,
      "y": 3,
      "z": -7,
      "name": "Empty"
    },
    {
      "x": -4,
      "y": 0,
      "z": -6,
      "name": "Soil_Grass"
    },
    {
      "x": -4,
      "y": 1,
      "z": -6,
      "name": "Rock_Marble_Brick_Smooth_Half",
      "rotation": 6
    },
    {
      "x": -4,
      "y": 3,
      "z": -6,
      "name": "Rock_Marble_Brick_Smooth_Half",
      "rotation": 6
    },
    {
      "x": -4,
      "y": 6,
      "z": -6,
      "name": "Wood_Darkwood_Roof_Steep",
      "rotation": 2
    },
    {
      "x": -4,
      "y": 7,
      "z": -6,
      "name": "Wood_Darkwood_Roof_Steep",
      "filler": 1024,
      "rotation": 2
    },
    {
      "x": -4,
      "y": 0,
      "z": -5,
      "name": "Rock_Stone"
    },
    {
      "x": -4,
      "y": 1,
      "z": -5,
      "name": "Rock_Marble_Brick"
    },
    {
      "x": -4,
      "y": 2,
      "z": -5,
      "name": "Rock_Marble_Brick"
    },
    {
      "x": -4,
      "y": 3,
      "z": -5,
      "name": "Rock_Marble_Brick"
    },
    {
      "x": -4,
      "y": 4,
      "z": -5,
      "name": "Furniture_Temple_Light_Window"
    },
    {
      "x": -4,
      "y": 5,
      "z": -5,
      "name": "Rock_Marble_Brick"
    },
    {
      "x": -4,
      "y": 8,
      "z": -5,
      "name": "Wood_Darkwood_Roof_Hollow",
      "rotation": 2
    },
    {
      "x": -4,
      "y": 0,
      "z": -4,
      "name": "Rock_Stone"
    },
    {
      "x": -4,
      "y": 1,
      "z": -4,
      "name": "Rock_Lime_Brick_Smooth"
    },
    {
      "x": -4,
      "y": 2,
      "z": -4,
      "name": "Furniture_Village_Table",
      "filler": 1
    },
    {
      "x": -4,
      "y": 5,
      "z": -4,
      "name": "Wood_Drywood_Planks_Half",
      "rotation": 8
    },
    {
      "x": -4,
      "y": 9,
      "z": -4,
      "name": "Wood_Darkwood_Roof_Flat",
      "rotation": 1
    },
    {
      "x": -4,
      "y": 0,
      "z": -3,
      "name": "Rock_Stone"
    },
    {
      "x": -4,
      "y": 1,
      "z": -3,
      "name": "Rock_Lime_Brick_Smooth"
    },
    {
      "x": -4,
      "y": 2,
      "z": -3,
      "name": "Furniture_Village_Table",
      "filler": 33
    },
    {
      "x": -4,
      "y": 5,
      "z": -3,
      "name": "Wood_Drywood_Planks_Half",
      "rotation": 8
    },
    {
      "x": -4,
      "y": 9,
      "z": -3,
      "name": "Wood_Darkwood_Roof_Flat",
      "rotation": 1
    },
    {
      "x": -4,
      "y": 0,
      "z": -2,
      "name": "Rock_Stone"
    },
    {
      "x": -4,
      "y": 1,
      "z": -2,
      "name": "Rock_Lime_Brick_Smooth"
    },
    {
      "x": -4,
      "y": 2,
      "z": -2,
      "name": "Furniture_Village_Stool",
      "components": {
        "Components": {}
      },
      "rotation": 2
    },
    {
      "x": -4,
      "y": 5,
      "z": -2,
      "name": "Wood_Drywood_Planks_Half",
      "rotation": 8
    },
    {
      "x": -4,
      "y": 9,
      "z": -2,
      "name": "Wood_Darkwood_Roof_Flat",
      "rotation": 1
    },
    {
      "x": -4,
      "y": 0,
      "z": -1,
      "name": "Rock_Stone"
    },
    {
      "x": -4,
      "y": 1,
      "z": -1,
      "name": "Rock_Lime_Brick_Smooth"
    },
    {
      "x": -4,
      "y": 5,
      "z": -1,
      "name": "Wood_Drywood_Planks_Half",
      "rotation": 8
    },
    {
      "x": -4,
      "y": 9,
      "z": -1,
      "name": "Wood_Darkwood_Roof_Flat",
      "rotation": 1
    },
    {
      "x": -4,
      "y": 0,
      "z": 0,
      "name": "Rock_Stone"
    },
    {
      "x": -4,
      "y": 1,
      "z": 0,
      "name": "Rock_Lime_Brick_Smooth"
    },
    {
      "x": -4,
      "y": 5,
      "z": 0,
      "name": "Wood_Drywood_Planks_Half",
      "rotation": 8
    },
    {
      "x": -4,
      "y": 9,
      "z": 0,
      "name": "Wood_Darkwood_Roof_Flat",
      "rotation": 1
    },
    {
      "x": -4,
      "y": 0,
      "z": 1,
      "name": "Rock_Stone"
    },
    {
      "x": -4,
      "y": 1,
      "z": 1,
      "name": "Rock_Lime_Brick_Smooth"
    },
    {
      "x": -4,
      "y": 5,
      "z": 1,
      "name": "Wood_Drywood_Planks_Half",
      "rotation": 8
    },
    {
      "x": -4,
      "y": 9,
      "z": 1,
      "name": "Wood_Darkwood_Roof_Flat",
      "rotation": 1
    },
    {
      "x": -4,
      "y": 0,
      "z": 2,
      "name": "Rock_Stone"
    },
    {
      "x": -4,
      "y": 1,
      "z": 2,
      "name": "Rock_Lime_Brick_Smooth"
    },
    {
      "x": -4,
      "y": 3,
      "z": 2,
      "name": "Furniture_Tavern_Painting",
      "rotation": 2
    },
    {
      "x": -4,
      "y": 5,
      "z": 2,
      "name": "Wood_Drywood_Planks_Half",
      "rotation": 8
    },
    {
      "x": -4,
      "y": 9,
      "z": 2,
      "name": "Wood_Darkwood_Roof_Flat",
      "rotation": 1
    },
    {
      "x": -4,
      "y": 0,
      "z": 3,
      "name": "Rock_Stone"
    },
    {
      "x": -4,
      "y": 1,
      "z": 3,
      "name": "Rock_Marble_Brick"
    },
    {
      "x": -4,
      "y": 2,
      "z": 3,
      "name": "Rock_Marble_Brick"
    },
    {
      "x": -4,
      "y": 3,
      "z": 3,
      "name": "Rock_Marble_Brick"
    },
    {
      "x": -4,
      "y": 4,
      "z": 3,
      "name": "Rock_Marble_Brick"
    },
    {
      "x": -4,
      "y": 5,
      "z": 3,
      "name": "Rock_Marble_Brick"
    },
    {
      "x": -4,
      "y": 8,
      "z": 3,
      "name": "Wood_Darkwood_Roof_Hollow"
    },
    {
      "x": -4,
      "y": 1,
      "z": 4,
      "name": "Rock_Marble_Brick_Smooth_Half",
      "rotation": 4
    },
    {
      "x": -4,
      "y": 3,
      "z": 4,
      "name": "Rock_Marble_Brick_Smooth_Half",
      "rotation": 4
    },
    {
      "x": -4,
      "y": 6,
      "z": 4,
      "name": "Wood_Darkwood_Roof_Steep"
    },
    {
      "x": -4,
      "y": 7,
      "z": 4,
      "name": "Wood_Darkwood_Roof_Steep",
      "filler": 1024
    },
    {
      "x": -3,
      "y": 1,
      "z": -8,
      "name": "Empty"
    },
    {
      "x": -3,
      "y": 2,
      "z": -8,
      "name": "Empty"
    },
    {
      "x": -3,
      "y": 3,
      "z": -8,
      "name": "Empty"
    },
    {
      "x": -3,
      "y": 0,
      "z": -7,
      "name": "Soil_Grass"
    },
    {
      "x": -3,
      "y": 1,
      "z": -7,
      "name": "Bench_Trough",
      "components": {
        "Components": {
          "PlacedByInteraction": {
            "WhoPlacedUuid": {
              "$binary": "iJnnVdMjR5iqsjPMr3DIyQ==",
              "$type": "04"
            }
          },
          "crafting": {
            "TierLevel": 1,
            "UpgradeItems": []
          }
        }
      }
    },
    {
      "x": -3,
      "y": 2,
      "z": -7,
      "name": "Empty"
    },
    {
      "x": -3,
      "y": 3,
      "z": -7,
      "name": "Empty"
    },
    {
      "x": -3,
      "y": 0,
      "z": -6,
      "name": "Soil_Grass"
    },
    {
      "x": -3,
      "y": 1,
      "z": -6,
      "name": "Rock_Marble_Brick_Smooth_Half",
      "rotation": 6
    },
    {
      "x": -3,
      "y": 3,
      "z": -6,
      "name": "Rock_Marble_Brick_Smooth_Half",
      "rotation": 6
    },
    {
      "x": -3,
      "y": 6,
      "z": -6,
      "name": "Wood_Darkwood_Roof_Steep",
      "rotation": 2
    },
    {
      "x": -3,
      "y": 7,
      "z": -6,
      "name": "Wood_Darkwood_Roof_Steep",
      "filler": 1024,
      "rotation": 2
    },
    {
      "x": -3,
      "y": 0,
      "z": -5,
      "name": "Rock_Stone"
    },
    {
      "x": -3,
      "y": 1,
      "z": -5,
      "name": "Rock_Marble_Brick"
    },
    {
      "x": -3,
      "y": 2,
      "z": -5,
      "name": "Rock_Marble_Brick"
    },
    {
      "x": -3,
      "y": 3,
      "z": -5,
      "name": "Rock_Marble_Brick"
    },
    {
      "x": -3,
      "y": 4,
      "z": -5,
      "name": "Furniture_Temple_Light_Window"
    },
    {
      "x": -3,
      "y": 5,
      "z": -5,
      "name": "Rock_Marble_Brick"
    },
    {
      "x": -3,
      "y": 8,
      "z": -5,
      "name": "Wood_Darkwood_Roof_Hollow",
      "rotation": 2
    },
    {
      "x": -3,
      "y": 0,
      "z": -4,
      "name": "Rock_Stone"
    },
    {
      "x": -3,
      "y": 1,
      "z": -4,
      "name": "Rock_Lime_Brick_Smooth"
    },
    {
      "x": -3,
      "y": 5,
      "z": -4,
      "name": "Wood_Drywood_Planks_Half",
      "rotation": 8
    },
    {
      "x": -3,
      "y": 9,
      "z": -4,
      "name": "Wood_Darkwood_Roof_Flat",
      "rotation": 1
    },
    {
      "x": -3,
      "y": 0,
      "z": -3,
      "name": "Rock_Stone"
    },
    {
      "x": -3,
      "y": 1,
      "z": -3,
      "name": "Rock_Lime_Brick_Smooth"
    },
    {
      "x": -3,
      "y": 5,
      "z": -3,
      "name": "Wood_Drywood_Planks_Half",
      "rotation": 8
    },
    {
      "x": -3,
      "y": 9,
      "z": -3,
      "name": "Wood_Darkwood_Roof_Flat",
      "rotation": 1
    },
    {
      "x": -3,
      "y": 0,
      "z": -2,
      "name": "Rock_Stone"
    },
    {
      "x": -3,
      "y": 1,
      "z": -2,
      "name": "Rock_Lime_Brick_Smooth"
    },
    {
      "x": -3,
      "y": 5,
      "z": -2,
      "name": "Wood_Drywood_Planks_Half",
      "rotation": 8
    },
    {
      "x": -3,
      "y": 9,
      "z": -2,
      "name": "Wood_Darkwood_Roof_Flat",
      "rotation": 1
    },
    {
      "x": -3,
      "y": 0,
      "z": -1,
      "name": "Rock_Stone"
    },
    {
      "x": -3,
      "y": 1,
      "z": -1,
      "name": "Rock_Lime_Brick_Smooth"
    },
    {
      "x": -3,
      "y": 5,
      "z": -1,
      "name": "Wood_Drywood_Planks_Half",
      "rotation": 8
    },
    {
      "x": -3,
      "y": 9,
      "z": -1,
      "name": "Wood_Darkwood_Roof_Flat",
      "rotation": 1
    },
    {
      "x": -3,
      "y": 0,
      "z": 0,
      "name": "Rock_Stone"
    },
    {
      "x": -3,
      "y": 1,
      "z": 0,
      "name": "Rock_Lime_Brick_Smooth"
    },
    {
      "x": -3,
      "y": 5,
      "z": 0,
      "name": "Wood_Drywood_Planks_Half",
      "rotation": 8
    },
    {
      "x": -3,
      "y": 9,
      "z": 0,
      "name": "Wood_Darkwood_Roof_Flat",
      "rotation": 1
    },
    {
      "x": -3,
      "y": 0,
      "z": 1,
      "name": "Rock_Stone"
    },
    {
      "x": -3,
      "y": 1,
      "z": 1,
      "name": "Rock_Lime_Brick_Smooth"
    },
    {
      "x": -3,
      "y": 5,
      "z": 1,
      "name": "Wood_Drywood_Planks_Half",
      "rotation": 8
    },
    {
      "x": -3,
      "y": 9,
      "z": 1,
      "name": "Wood_Darkwood_Roof_Flat",
      "rotation": 1
    },
    {
      "x": -3,
      "y": 0,
      "z": 2,
      "name": "Rock_Stone"
    },
    {
      "x": -3,
      "y": 1,
      "z": 2,
      "name": "Rock_Lime_Brick_Smooth"
    },
    {
      "x": -3,
      "y": 2,
      "z": 2,
      "name": "Bench_Pkmn_PC",
      "components": {
        "Components": {
          "processingBench": {
            "TierLevel": 1,
            "UpgradeItems": [],
            "InputContainer": {
              "Id": "Simple",
              "Capacity": 5,
              "Items": {}
            },
            "FuelContainer": {
              "Id": "Simple",
              "Capacity": 1,
              "Items": {}
            },
            "OutputContainer": {
              "Id": "Simple",
              "Capacity": 6,
              "Items": {}
            },
            "Progress": 0.0,
            "FuelTime": 0.0,
            "Active": false,
            "NextExtra": 4
          },
          "PlacedByInteraction": {
            "WhoPlacedUuid": {
              "$binary": "iJnnVdMjR5iqsjPMr3DIyQ==",
              "$type": "04"
            }
          }
        }
      },
      "rotation": 2
    },
    {
      "x": -3,
      "y": 3,
      "z": 2,
      "name": "Bench_Pkmn_PC",
      "filler": 1024,
      "rotation": 2
    },
    {
      "x": -3,
      "y": 5,
      "z": 2,
      "name": "Wood_Drywood_Planks_Half",
      "rotation": 8
    },
    {
      "x": -3,
      "y": 9,
      "z": 2,
      "name": "Wood_Darkwood_Roof_Flat",
      "rotation": 1
    },
    {
      "x": -3,
      "y": 0,
      "z": 3,
      "name": "Rock_Stone"
    },
    {
      "x": -3,
      "y": 1,
      "z": 3,
      "name": "Rock_Marble_Brick"
    },
    {
      "x": -3,
      "y": 2,
      "z": 3,
      "name": "Rock_Marble_Brick"
    },
    {
      "x": -3,
      "y": 3,
      "z": 3,
      "name": "Rock_Marble_Brick"
    },
    {
      "x": -3,
      "y": 4,
      "z": 3,
      "name": "Rock_Marble_Brick"
    },
    {
      "x": -3,
      "y": 5,
      "z": 3,
      "name": "Rock_Marble_Brick"
    },
    {
      "x": -3,
      "y": 8,
      "z": 3,
      "name": "Wood_Darkwood_Roof_Hollow"
    },
    {
      "x": -3,
      "y": 4,
      "z": 4,
      "name": "Wood_Darkwood_Roof_Hollow",
      "rotation": 3
    },
    {
      "x": -3,
      "y": 6,
      "z": 4,
      "name": "Wood_Darkwood_Roof_Steep"
    },
    {
      "x": -3,
      "y": 7,
      "z": 4,
      "name": "Wood_Darkwood_Roof_Steep",
      "filler": 1024
    },
    {
      "x": -3,
      "y": 1,
      "z": 5,
      "name": "Rock_Marble_Brick_Smooth_Half",
      "rotation": 7
    },
    {
      "x": -3,
      "y": 3,
      "z": 5,
      "name": "Rock_Marble_Brick_Smooth_Half",
      "rotation": 7
    },
    {
      "x": -3,
      "y": 4,
      "z": 5,
      "name": "Wood_Darkwood_Roof_Hollow",
      "rotation": 3
    },
    {
      "x": -3,
      "y": 1,
      "z": 6,
      "name": "Rock_Marble_Brick_Smooth_Half",
      "rotation": 7
    },
    {
      "x": -3,
      "y": 3,
      "z": 6,
      "name": "Rock_Marble_Brick_Smooth_Half",
      "rotation": 7
    },
    {
      "x": -3,
      "y": 4,
      "z": 6,
      "name": "Wood_Darkwood_Roof_Hollow",
      "rotation": 3
    },
    {
      "x": -3,
      "y": 1,
      "z": 7,
      "name": "Rock_Marble_Brick_Smooth_Half",
      "rotation": 7
    },
    {
      "x": -3,
      "y": 3,
      "z": 7,
      "name": "Rock_Marble_Brick_Smooth_Half",
      "rotation": 7
    },
    {
      "x": -3,
      "y": 4,
      "z": 7,
      "name": "Wood_Darkwood_Roof_Hollow",
      "rotation": 3
    },
    {
      "x": -3,
      "y": 4,
      "z": 8,
      "name": "*Wood_Darkwood_Roof_Hollow_State_Definitions_Corner_Left",
      "rotation": 3
    },
    {
      "x": -2,
      "y": 0,
      "z": -8,
      "name": "Soil_Grass"
    },
    {
      "x": -2,
      "y": 1,
      "z": -8,
      "name": "Empty"
    },
    {
      "x": -2,
      "y": 2,
      "z": -8,
      "name": "Empty"
    },
    {
      "x": -2,
      "y": 3,
      "z": -8,
      "name": "Empty"
    },
    {
      "x": -2,
      "y": 4,
      "z": -8,
      "name": "Empty"
    },
    {
      "x": -2,
      "y": 5,
      "z": -8,
      "name": "Empty"
    },
    {
      "x": -2,
      "y": 6,
      "z": -8,
      "name": "Empty"
    },
    {
      "x": -2,
      "y": 0,
      "z": -7,
      "name": "Rock_Stone"
    },
    {
      "x": -2,
      "y": 1,
      "z": -7,
      "name": "*Rock_Marble_Brick_Stairs_State_Definitions_Corner_Right",
      "rotation": 3
    },
    {
      "x": -2,
      "y": 2,
      "z": -7,
      "name": "Empty"
    },
    {
      "x": -2,
      "y": 3,
      "z": -7,
      "name": "Empty"
    },
    {
      "x": -2,
      "y": 4,
      "z": -7,
      "name": "Empty"
    },
    {
      "x": -2,
      "y": 5,
      "z": -7,
      "name": "Empty"
    },
    {
      "x": -2,
      "y": 6,
      "z": -7,
      "name": "Empty"
    },
    {
      "x": -2,
      "y": 0,
      "z": -6,
      "name": "Rock_Stone"
    },
    {
      "x": -2,
      "y": 1,
      "z": -6,
      "name": "Rock_Marble_Brick_Pillar_Base"
    },
    {
      "x": -2,
      "y": 2,
      "z": -6,
      "name": "Rock_Marble_Brick_Beam"
    },
    {
      "x": -2,
      "y": 3,
      "z": -6,
      "name": "Rock_Marble_Brick_Beam"
    },
    {
      "x": -2,
      "y": 4,
      "z": -6,
      "name": "Rock_Marble_Brick_Beam"
    },
    {
      "x": -2,
      "y": 5,
      "z": -6,
      "name": "Rock_Marble_Brick_Pillar_Base",
      "rotation": 8
    },
    {
      "x": -2,
      "y": 6,
      "z": -6,
      "name": "Rock_Marble_Brick_Smooth"
    },
    {
      "x": -2,
      "y": 7,
      "z": -6,
      "name": "Wood_Darkwood_Roof",
      "rotation": 2
    },
    {
      "x": -2,
      "y": 0,
      "z": -5,
      "name": "Rock_Stone"
    },
    {
      "x": -2,
      "y": 1,
      "z": -5,
      "name": "Rock_Marble_Brick"
    },
    {
      "x": -2,
      "y": 2,
      "z": -5,
      "name": "Rock_Marble_Brick"
    },
    {
      "x": -2,
      "y": 3,
      "z": -5,
      "name": "Rock_Marble_Brick"
    },
    {
      "x": -2,
      "y": 4,
      "z": -5,
      "name": "Rock_Marble_Brick"
    },
    {
      "x": -2,
      "y": 5,
      "z": -5,
      "name": "Rock_Marble_Brick"
    },
    {
      "x": -2,
      "y": 8,
      "z": -5,
      "name": "Wood_Darkwood_Roof_Hollow",
      "rotation": 2
    },
    {
      "x": -2,
      "y": 0,
      "z": -4,
      "name": "Rock_Stone"
    },
    {
      "x": -2,
      "y": 1,
      "z": -4,
      "name": "Rock_Lime_Brick_Smooth"
    },
    {
      "x": -2,
      "y": 5,
      "z": -4,
      "name": "Wood_Drywood_Planks_Half",
      "rotation": 8
    },
    {
      "x": -2,
      "y": 9,
      "z": -4,
      "name": "Wood_Darkwood_Roof_Flat",
      "rotation": 1
    },
    {
      "x": -2,
      "y": 0,
      "z": -3,
      "name": "Rock_Stone"
    },
    {
      "x": -2,
      "y": 1,
      "z": -3,
      "name": "Rock_Lime_Brick_Smooth"
    },
    {
      "x": -2,
      "y": 5,
      "z": -3,
      "name": "Wood_Drywood_Planks_Half",
      "rotation": 8
    },
    {
      "x": -2,
      "y": 9,
      "z": -3,
      "name": "Wood_Darkwood_Roof_Flat",
      "rotation": 1
    },
    {
      "x": -2,
      "y": 0,
      "z": -2,
      "name": "Rock_Stone"
    },
    {
      "x": -2,
      "y": 1,
      "z": -2,
      "name": "Rock_Lime_Brick_Smooth"
    },
    {
      "x": -2,
      "y": 5,
      "z": -2,
      "name": "Wood_Drywood_Planks_Half",
      "rotation": 8
    },
    {
      "x": -2,
      "y": 9,
      "z": -2,
      "name": "Wood_Darkwood_Roof_Flat",
      "rotation": 1
    },
    {
      "x": -2,
      "y": 0,
      "z": -1,
      "name": "Rock_Stone"
    },
    {
      "x": -2,
      "y": 1,
      "z": -1,
      "name": "Rock_Lime_Brick_Smooth"
    },
    {
      "x": -2,
      "y": 5,
      "z": -1,
      "name": "Wood_Drywood_Planks_Half",
      "rotation": 8
    },
    {
      "x": -2,
      "y": 9,
      "z": -1,
      "name": "Wood_Darkwood_Roof_Flat",
      "rotation": 1
    },
    {
      "x": -2,
      "y": 0,
      "z": 0,
      "name": "Rock_Stone"
    },
    {
      "x": -2,
      "y": 1,
      "z": 0,
      "name": "Rock_Lime_Brick_Smooth"
    },
    {
      "x": -2,
      "y": 2,
      "z": 0,
      "name": "*Rock_Peach_Brick_Stairs_State_Definitions_Inverted_Corner_Left",
      "rotation": 11
    },
    {
      "x": -2,
      "y": 5,
      "z": 0,
      "name": "Wood_Drywood_Planks_Half",
      "rotation": 8
    },
    {
      "x": -2,
      "y": 9,
      "z": 0,
      "name": "Wood_Darkwood_Roof_Flat",
      "rotation": 1
    },
    {
      "x": -2,
      "y": 0,
      "z": 1,
      "name": "Rock_Stone"
    },
    {
      "x": -2,
      "y": 1,
      "z": 1,
      "name": "Rock_Lime_Brick_Smooth"
    },
    {
      "x": -2,
      "y": 2,
      "z": 1,
      "name": "*Wood_Redwood_Fence_Gate_State_Definitions_CloseDoorOut",
      "rotation": 3
    },
    {
      "x": -2,
      "y": 5,
      "z": 1,
      "name": "Wood_Drywood_Planks_Half",
      "rotation": 8
    },
    {
      "x": -2,
      "y": 9,
      "z": 1,
      "name": "Wood_Darkwood_Roof_Flat",
      "rotation": 1
    },
    {
      "x": -2,
      "y": 0,
      "z": 2,
      "name": "Rock_Stone"
    },
    {
      "x": -2,
      "y": 1,
      "z": 2,
      "name": "Rock_Lime_Brick_Smooth"
    },
    {
      "x": -2,
      "y": 2,
      "z": 2,
      "name": "Rock_Peach_Brick_Stairs",
      "rotation": 11
    },
    {
      "x": -2,
      "y": 3,
      "z": 2,
      "name": "Furniture_Temple_Light_Shelf",
      "rotation": 2
    },
    {
      "x": -2,
      "y": 4,
      "z": 2,
      "name": "Potion_Health_Lesser"
    },
    {
      "x": -2,
      "y": 5,
      "z": 2,
      "name": "Wood_Drywood_Planks_Half",
      "rotation": 8
    },
    {
      "x": -2,
      "y": 9,
      "z": 2,
      "name": "Wood_Darkwood_Roof_Flat",
      "rotation": 1
    },
    {
      "x": -2,
      "y": 0,
      "z": 3,
      "name": "Rock_Stone"
    },
    {
      "x": -2,
      "y": 1,
      "z": 3,
      "name": "Rock_Marble_Brick"
    },
    {
      "x": -2,
      "y": 2,
      "z": 3,
      "name": "Rock_Marble_Brick"
    },
    {
      "x": -2,
      "y": 3,
      "z": 3,
      "name": "Rock_Marble_Brick"
    },
    {
      "x": -2,
      "y": 4,
      "z": 3,
      "name": "Rock_Marble_Brick"
    },
    {
      "x": -2,
      "y": 5,
      "z": 3,
      "name": "Rock_Marble_Brick"
    },
    {
      "x": -2,
      "y": 8,
      "z": 3,
      "name": "Wood_Darkwood_Roof_Hollow"
    },
    {
      "x": -2,
      "y": 0,
      "z": 4,
      "name": "Rock_Stone"
    },
    {
      "x": -2,
      "y": 1,
      "z": 4,
      "name": "Rock_Marble_Brick"
    },
    {
      "x": -2,
      "y": 2,
      "z": 4,
      "name": "Rock_Marble_Brick"
    },
    {
      "x": -2,
      "y": 3,
      "z": 4,
      "name": "Rock_Marble_Brick"
    },
    {
      "x": -2,
      "y": 4,
      "z": 4,
      "name": "Rock_Marble_Brick"
    },
    {
      "x": -2,
      "y": 5,
      "z": 4,
      "name": "Wood_Darkwood_Roof_Flat",
      "rotation": 3
    },
    {
      "x": -2,
      "y": 6,
      "z": 4,
      "name": "Wood_Darkwood_Roof_Steep"
    },
    {
      "x": -2,
      "y": 7,
      "z": 4,
      "name": "Wood_Darkwood_Roof_Steep",
      "filler": 1024
    },
    {
      "x": -2,
      "y": 0,
      "z": 5,
      "name": "Rock_Stone"
    },
    {
      "x": -2,
      "y": 1,
      "z": 5,
      "name": "Rock_Marble_Brick"
    },
    {
      "x": -2,
      "y": 2,
      "z": 5,
      "name": "Rock_Marble_Brick"
    },
    {
      "x": -2,
      "y": 3,
      "z": 5,
      "name": "Rock_Marble_Brick"
    },
    {
      "x": -2,
      "y": 4,
      "z": 5,
      "name": "Rock_Marble_Brick"
    },
    {
      "x": -2,
      "y": 5,
      "z": 5,
      "name": "Wood_Darkwood_Roof_Flat",
      "rotation": 3
    },
    {
      "x": -2,
      "y": 0,
      "z": 6,
      "name": "Rock_Stone"
    },
    {
      "x": -2,
      "y": 1,
      "z": 6,
      "name": "Rock_Marble_Brick"
    },
    {
      "x": -2,
      "y": 2,
      "z": 6,
      "name": "Rock_Marble_Brick"
    },
    {
      "x": -2,
      "y": 3,
      "z": 6,
      "name": "Rock_Marble_Brick"
    },
    {
      "x": -2,
      "y": 4,
      "z": 6,
      "name": "Rock_Marble_Brick"
    },
    {
      "x": -2,
      "y": 5,
      "z": 6,
      "name": "Wood_Darkwood_Roof_Flat",
      "rotation": 3
    },
    {
      "x": -2,
      "y": 0,
      "z": 7,
      "name": "Rock_Stone"
    },
    {
      "x": -2,
      "y": 1,
      "z": 7,
      "name": "Rock_Marble_Brick"
    },
    {
      "x": -2,
      "y": 2,
      "z": 7,
      "name": "Rock_Marble_Brick"
    },
    {
      "x": -2,
      "y": 3,
      "z": 7,
      "name": "Rock_Marble_Brick"
    },
    {
      "x": -2,
      "y": 4,
      "z": 7,
      "name": "Rock_Marble_Brick"
    },
    {
      "x": -2,
      "y": 5,
      "z": 7,
      "name": "Wood_Darkwood_Roof_Flat",
      "rotation": 3
    },
    {
      "x": -2,
      "y": 1,
      "z": 8,
      "name": "Rock_Marble_Brick_Smooth_Half",
      "rotation": 4
    },
    {
      "x": -2,
      "y": 3,
      "z": 8,
      "name": "Rock_Marble_Brick_Smooth_Half",
      "rotation": 4
    },
    {
      "x": -2,
      "y": 4,
      "z": 8,
      "name": "Wood_Darkwood_Roof_Hollow"
    },
    {
      "x": -1,
      "y": 0,
      "z": -8,
      "name": "Soil_Grass"
    },
    {
      "x": -1,
      "y": 1,
      "z": -8,
      "name": "Empty"
    },
    {
      "x": -1,
      "y": 2,
      "z": -8,
      "name": "Empty"
    },
    {
      "x": -1,
      "y": 3,
      "z": -8,
      "name": "Empty"
    },
    {
      "x": -1,
      "y": 4,
      "z": -8,
      "name": "Empty"
    },
    {
      "x": -1,
      "y": 5,
      "z": -8,
      "name": "Empty"
    },
    {
      "x": -1,
      "y": 6,
      "z": -8,
      "name": "Empty"
    },
    {
      "x": -1,
      "y": 0,
      "z": -7,
      "name": "Rock_Stone"
    },
    {
      "x": -1,
      "y": 1,
      "z": -7,
      "name": "Rock_Marble_Brick_Stairs",
      "rotation": 2
    },
    {
      "x": -1,
      "y": 2,
      "z": -7,
      "name": "Empty"
    },
    {
      "x": -1,
      "y": 3,
      "z": -7,
      "name": "Empty"
    },
    {
      "x": -1,
      "y": 4,
      "z": -7,
      "name": "Empty"
    },
    {
      "x": -1,
      "y": 5,
      "z": -7,
      "name": "Empty"
    },
    {
      "x": -1,
      "y": 6,
      "z": -7,
      "name": "Empty"
    },
    {
      "x": -1,
      "y": 0,
      "z": -6,
      "name": "Rock_Stone"
    },
    {
      "x": -1,
      "y": 1,
      "z": -6,
      "name": "Cloth_Block_Wool_Red"
    },
    {
      "x": -1,
      "y": 5,
      "z": -6,
      "name": "Rock_Marble_Brick_Smooth_Half",
      "rotation": 8
    },
    {
      "x": -1,
      "y": 6,
      "z": -6,
      "name": "Rock_Marble_Brick_Smooth"
    },
    {
      "x": -1,
      "y": 7,
      "z": -6,
      "name": "Rock_Marble_Brick_Smooth_Half"
    },
    {
      "x": -1,
      "y": 0,
      "z": -5,
      "name": "Rock_Stone"
    },
    {
      "x": -1,
      "y": 1,
      "z": -5,
      "name": "Cloth_Block_Wool_Red"
    },
    {
      "x": -1,
      "y": 2,
      "z": -5,
      "name": "*Furniture_Temple_Light_Door_Medilum_State_Definitions_CloseDoorOut",
      "filler": 30,
      "rotation": 2
    },
    {
      "x": -1,
      "y": 3,
      "z": -5,
      "name": "*Furniture_Temple_Light_Door_Medilum_State_Definitions_CloseDoorOut",
      "filler": 1054,
      "rotation": 2
    },
    {
      "x": -1,
      "y": 4,
      "z": -5,
      "name": "*Furniture_Temple_Light_Door_Medilum_State_Definitions_CloseDoorOut",
      "filler": 2078,
      "rotation": 2
    },
    {
      "x": -1,
      "y": 5,
      "z": -5,
      "name": "Rock_Marble_Brick"
    },
    {
      "x": -1,
      "y": 6,
      "z": -5,
      "name": "Wood_Darkwood_Planks_Half",
      "rotation": 4
    },
    {
      "x": -1,
      "y": 7,
      "z": -5,
      "name": "Wood_Darkwood_Planks_Half",
      "rotation": 4
    },
    {
      "x": -1,
      "y": 8,
      "z": -5,
      "name": "Wood_Darkwood_Roof_Hollow",
      "rotation": 2
    },
    {
      "x": -1,
      "y": 0,
      "z": -4,
      "name": "Rock_Stone"
    },
    {
      "x": -1,
      "y": 1,
      "z": -4,
      "name": "Cloth_Block_Wool_Red"
    },
    {
      "x": -1,
      "y": 5,
      "z": -4,
      "name": "Wood_Drywood_Planks_Half",
      "rotation": 8
    },
    {
      "x": -1,
      "y": 9,
      "z": -4,
      "name": "Wood_Darkwood_Roof_Flat",
      "rotation": 1
    },
    {
      "x": -1,
      "y": 0,
      "z": -3,
      "name": "Rock_Stone"
    },
    {
      "x": -1,
      "y": 1,
      "z": -3,
      "name": "Rock_Lime_Brick_Smooth"
    },
    {
      "x": -1,
      "y": 5,
      "z": -3,
      "name": "Wood_Drywood_Planks_Half",
      "rotation": 8
    },
    {
      "x": -1,
      "y": 9,
      "z": -3,
      "name": "Wood_Darkwood_Roof_Flat",
      "rotation": 1
    },
    {
      "x": -1,
      "y": 0,
      "z": -2,
      "name": "Rock_Stone"
    },
    {
      "x": -1,
      "y": 1,
      "z": -2,
      "name": "Rock_Lime_Brick_Smooth"
    },
    {
      "x": -1,
      "y": 5,
      "z": -2,
      "name": "Wood_Drywood_Planks_Half",
      "rotation": 8
    },
    {
      "x": -1,
      "y": 9,
      "z": -2,
      "name": "Wood_Darkwood_Roof_Flat",
      "rotation": 1
    },
    {
      "x": -1,
      "y": 0,
      "z": -1,
      "name": "Rock_Stone"
    },
    {
      "x": -1,
      "y": 1,
      "z": -1,
      "name": "Rock_Lime_Brick_Smooth"
    },
    {
      "x": -1,
      "y": 5,
      "z": -1,
      "name": "Wood_Drywood_Planks_Half",
      "rotation": 8
    },
    {
      "x": -1,
      "y": 9,
      "z": -1,
      "name": "Wood_Darkwood_Roof_Flat",
      "rotation": 1
    },
    {
      "x": -1,
      "y": 0,
      "z": 0,
      "name": "Rock_Stone"
    },
    {
      "x": -1,
      "y": 1,
      "z": 0,
      "name": "Rock_Lime_Brick_Smooth"
    },
    {
      "x": -1,
      "y": 2,
      "z": 0,
      "name": "Rock_Peach_Brick_Stairs",
      "rotation": 10
    },
    {
      "x": -1,
      "y": 5,
      "z": 0,
      "name": "Wood_Drywood_Planks_Half",
      "rotation": 8
    },
    {
      "x": -1,
      "y": 9,
      "z": 0,
      "name": "Wood_Darkwood_Roof_Flat",
      "rotation": 1
    },
    {
      "x": -1,
      "y": 0,
      "z": 1,
      "name": "Rock_Stone"
    },
    {
      "x": -1,
      "y": 1,
      "z": 1,
      "name": "Rock_Lime_Brick_Smooth"
    },
    {
      "x": -1,
      "y": 5,
      "z": 1,
      "name": "Wood_Drywood_Planks_Half",
      "rotation": 8
    },
    {
      "x": -1,
      "y": 9,
      "z": 1,
      "name": "Wood_Darkwood_Roof_Flat",
      "rotation": 1
    },
    {
      "x": -1,
      "y": 0,
      "z": 2,
      "name": "Rock_Stone"
    },
    {
      "x": -1,
      "y": 1,
      "z": 2,
      "name": "Rock_Lime_Brick_Smooth"
    },
    {
      "x": -1,
      "y": 5,
      "z": 2,
      "name": "Wood_Drywood_Planks_Half",
      "rotation": 8
    },
    {
      "x": -1,
      "y": 9,
      "z": 2,
      "name": "Wood_Darkwood_Roof_Flat",
      "rotation": 1
    },
    {
      "x": -1,
      "y": 0,
      "z": 3,
      "name": "Rock_Stone"
    },
    {
      "x": -1,
      "y": 1,
      "z": 3,
      "name": "Rock_Lime_Brick_Smooth"
    },
    {
      "x": -1,
      "y": 2,
      "z": 3,
      "name": "*Furniture_Temple_Light_Door_State_Definitions_CloseDoorIn"
    },
    {
      "x": -1,
      "y": 3,
      "z": 3,
      "name": "*Furniture_Temple_Light_Door_State_Definitions_CloseDoorIn",
      "filler": 1024
    },
    {
      "x": -1,
      "y": 4,
      "z": 3,
      "name": "Rock_Marble_Brick"
    },
    {
      "x": -1,
      "y": 5,
      "z": 3,
      "name": "Rock_Marble_Brick"
    },
    {
      "x": -1,
      "y": 8,
      "z": 3,
      "name": "Wood_Darkwood_Roof_Hollow"
    },
    {
      "x": -1,
      "y": 0,
      "z": 4,
      "name": "Rock_Stone"
    },
    {
      "x": -1,
      "y": 1,
      "z": 4,
      "name": "Rock_Lime_Brick_Smooth"
    },
    {
      "x": -1,
      "y": 4,
      "z": 4,
      "name": "Furniture_Temple_Light_Lantern_Ceiling"
    },
    {
      "x": -1,
      "y": 5,
      "z": 4,
      "name": "Wood_Darkwood_Roof_Flat",
      "rotation": 3
    },
    {
      "x": -1,
      "y": 6,
      "z": 4,
      "name": "Wood_Darkwood_Roof_Steep"
    },
    {
      "x": -1,
      "y": 7,
      "z": 4,
      "name": "Wood_Darkwood_Roof_Steep",
      "filler": 1024
    },
    {
      "x": -1,
      "y": 0,
      "z": 5,
      "name": "Rock_Stone"
    },
    {
      "x": -1,
      "y": 1,
      "z": 5,
      "name": "Rock_Lime_Brick_Smooth"
    },
    {
      "x": -1,
      "y": 5,
      "z": 5,
      "name": "Wood_Darkwood_Roof_Flat",
      "rotation": 3
    },
    {
      "x": -1,
      "y": 0,
      "z": 6,
      "name": "Rock_Stone"
    },
    {
      "x": -1,
      "y": 1,
      "z": 6,
      "name": "Rock_Lime_Brick_Smooth"
    },
    {
      "x": -1,
      "y": 2,
      "z": 6,
      "name": "Bench_Alchemy",
      "components": {
        "Components": {
          "PlacedByInteraction": {
            "WhoPlacedUuid": {
              "$binary": "iJnnVdMjR5iqsjPMr3DIyQ==",
              "$type": "04"
            }
          },
          "crafting": {
            "TierLevel": 1,
            "UpgradeItems": []
          }
        }
      },
      "rotation": 2
    },
    {
      "x": -1,
      "y": 3,
      "z": 6,
      "name": "Bench_Alchemy",
      "filler": 1024,
      "rotation": 2
    },
    {
      "x": -1,
      "y": 5,
      "z": 6,
      "name": "Wood_Darkwood_Roof_Flat",
      "rotation": 3
    },
    {
      "x": -1,
      "y": 0,
      "z": 7,
      "name": "Rock_Stone"
    },
    {
      "x": -1,
      "y": 1,
      "z": 7,
      "name": "Rock_Marble_Brick"
    },
    {
      "x": -1,
      "y": 2,
      "z": 7,
      "name": "Rock_Marble_Brick"
    },
    {
      "x": -1,
      "y": 3,
      "z": 7,
      "name": "Rock_Marble_Brick"
    },
    {
      "x": -1,
      "y": 4,
      "z": 7,
      "name": "Rock_Marble_Brick"
    },
    {
      "x": -1,
      "y": 5,
      "z": 7,
      "name": "Wood_Darkwood_Roof_Flat",
      "rotation": 3
    },
    {
      "x": -1,
      "y": 1,
      "z": 8,
      "name": "Rock_Marble_Brick_Smooth_Half",
      "rotation": 4
    },
    {
      "x": -1,
      "y": 3,
      "z": 8,
      "name": "Rock_Marble_Brick_Smooth_Half",
      "rotation": 4
    },
    {
      "x": -1,
      "y": 4,
      "z": 8,
      "name": "Wood_Darkwood_Roof_Hollow"
    },
    {
      "x": 0,
      "y": 0,
      "z": -8,
      "name": "Soil_Grass"
    },
    {
      "x": 0,
      "y": 1,
      "z": -8,
      "name": "Empty"
    },
    {
      "x": 0,
      "y": 2,
      "z": -8,
      "name": "Empty"
    },
    {
      "x": 0,
      "y": 3,
      "z": -8,
      "name": "Empty"
    },
    {
      "x": 0,
      "y": 4,
      "z": -8,
      "name": "Empty"
    },
    {
      "x": 0,
      "y": 5,
      "z": -8,
      "name": "Empty"
    },
    {
      "x": 0,
      "y": 6,
      "z": -8,
      "name": "Empty"
    },
    {
      "x": 0,
      "y": 0,
      "z": -7,
      "name": "Rock_Stone"
    },
    {
      "x": 0,
      "y": 1,
      "z": -7,
      "name": "Rock_Marble_Brick_Stairs",
      "rotation": 2
    },
    {
      "x": 0,
      "y": 2,
      "z": -7,
      "name": "Empty"
    },
    {
      "x": 0,
      "y": 3,
      "z": -7,
      "name": "Empty"
    },
    {
      "x": 0,
      "y": 4,
      "z": -7,
      "name": "Empty"
    },
    {
      "x": 0,
      "y": 5,
      "z": -7,
      "name": "Empty"
    },
    {
      "x": 0,
      "y": 6,
      "z": -7,
      "name": "Furniture_Lumberjack_Painting",
      "rotation": 2
    },
    {
      "x": 0,
      "y": 0,
      "z": -6,
      "name": "Rock_Stone"
    },
    {
      "x": 0,
      "y": 1,
      "z": -6,
      "name": "Cloth_Block_Wool_Red"
    },
    {
      "x": 0,
      "y": 5,
      "z": -6,
      "name": "*Rock_Marble_Brick_Smooth_Half_State_Definitions_Block",
      "rotation": 8
    },
    {
      "x": 0,
      "y": 6,
      "z": -6,
      "name": "Rock_Crystal_Red_Block"
    },
    {
      "x": 0,
      "y": 7,
      "z": -6,
      "name": "*Rock_Marble_Brick_Smooth_Half_State_Definitions_Block"
    },
    {
      "x": 0,
      "y": 0,
      "z": -5,
      "name": "Rock_Stone"
    },
    {
      "x": 0,
      "y": 1,
      "z": -5,
      "name": "Cloth_Block_Wool_Red"
    },
    {
      "x": 0,
      "y": 2,
      "z": -5,
      "name": "*Furniture_Temple_Light_Door_Medilum_State_Definitions_CloseDoorOut",
      "filler": 31,
      "rotation": 2
    },
    {
      "x": 0,
      "y": 3,
      "z": -5,
      "name": "*Furniture_Temple_Light_Door_Medilum_State_Definitions_CloseDoorOut",
      "filler": 1055,
      "rotation": 2
    },
    {
      "x": 0,
      "y": 4,
      "z": -5,
      "name": "*Furniture_Temple_Light_Door_Medilum_State_Definitions_CloseDoorOut",
      "filler": 2079,
      "rotation": 2
    },
    {
      "x": 0,
      "y": 5,
      "z": -5,
      "name": "Rock_Marble_Brick"
    },
    {
      "x": 0,
      "y": 6,
      "z": -5,
      "name": "Wood_Darkwood_Planks_Half",
      "rotation": 4
    },
    {
      "x": 0,
      "y": 7,
      "z": -5,
      "name": "Wood_Darkwood_Planks_Half",
      "rotation": 4
    },
    {
      "x": 0,
      "y": 8,
      "z": -5,
      "name": "Wood_Darkwood_Roof_Hollow",
      "rotation": 2
    },
    {
      "x": 0,
      "y": 0,
      "z": -4,
      "name": "Rock_Stone"
    },
    {
      "x": 0,
      "y": 1,
      "z": -4,
      "name": "Cloth_Block_Wool_Red"
    },
    {
      "x": 0,
      "y": 5,
      "z": -4,
      "name": "Wood_Drywood_Planks_Half",
      "rotation": 8
    },
    {
      "x": 0,
      "y": 9,
      "z": -4,
      "name": "Wood_Darkwood_Roof_Flat",
      "rotation": 1
    },
    {
      "x": 0,
      "y": 0,
      "z": -3,
      "name": "Rock_Stone"
    },
    {
      "x": 0,
      "y": 1,
      "z": -3,
      "name": "Rock_Lime_Brick_Smooth"
    },
    {
      "x": 0,
      "y": 5,
      "z": -3,
      "name": "Wood_Drywood_Planks_Half",
      "rotation": 8
    },
    {
      "x": 0,
      "y": 9,
      "z": -3,
      "name": "Wood_Darkwood_Roof_Flat",
      "rotation": 1
    },
    {
      "x": 0,
      "y": 0,
      "z": -2,
      "name": "Rock_Stone"
    },
    {
      "x": 0,
      "y": 1,
      "z": -2,
      "name": "Rock_Lime_Brick_Smooth"
    },
    {
      "x": 0,
      "y": 5,
      "z": -2,
      "name": "Wood_Drywood_Planks_Half",
      "rotation": 8
    },
    {
      "x": 0,
      "y": 9,
      "z": -2,
      "name": "Wood_Darkwood_Roof_Flat",
      "rotation": 1
    },
    {
      "x": 0,
      "y": 0,
      "z": -1,
      "name": "Rock_Stone"
    },
    {
      "x": 0,
      "y": 1,
      "z": -1,
      "name": "Rock_Lime_Brick_Smooth"
    },
    {
      "x": 0,
      "y": 5,
      "z": -1,
      "name": "Wood_Drywood_Planks_Half",
      "rotation": 8
    },
    {
      "x": 0,
      "y": 9,
      "z": -1,
      "name": "Wood_Darkwood_Roof_Flat",
      "rotation": 1
    },
    {
      "x": 0,
      "y": 0,
      "z": 0,
      "name": "Rock_Stone"
    },
    {
      "x": 0,
      "y": 1,
      "z": 0,
      "name": "Rock_Lime_Brick_Smooth"
    },
    {
      "x": 0,
      "y": 2,
      "z": 0,
      "name": "Rock_Peach_Brick_Stairs",
      "rotation": 10
    },
    {
      "x": 0,
      "y": 5,
      "z": 0,
      "name": "Wood_Drywood_Planks_Half",
      "rotation": 8
    },
    {
      "x": 0,
      "y": 9,
      "z": 0,
      "name": "Wood_Darkwood_Roof_Flat",
      "rotation": 1
    },
    {
      "x": 0,
      "y": 0,
      "z": 1,
      "name": "Rock_Stone"
    },
    {
      "x": 0,
      "y": 1,
      "z": 1,
      "name": "Rock_Lime_Brick_Smooth"
    },
    {
      "x": 0,
      "y": 5,
      "z": 1,
      "name": "Wood_Drywood_Planks_Half",
      "rotation": 8
    },
    {
      "x": 0,
      "y": 9,
      "z": 1,
      "name": "Wood_Darkwood_Roof_Flat",
      "rotation": 1
    },
    {
      "x": 0,
      "y": 0,
      "z": 2,
      "name": "Rock_Stone"
    },
    {
      "x": 0,
      "y": 1,
      "z": 2,
      "name": "Rock_Lime_Brick_Smooth"
    },
    {
      "x": 0,
      "y": 4,
      "z": 2,
      "name": "Furniture_Tavern_Painting",
      "rotation": 2
    },
    {
      "x": 0,
      "y": 5,
      "z": 2,
      "name": "Wood_Drywood_Planks_Half",
      "rotation": 8
    },
    {
      "x": 0,
      "y": 9,
      "z": 2,
      "name": "Wood_Darkwood_Roof_Flat",
      "rotation": 1
    },
    {
      "x": 0,
      "y": 0,
      "z": 3,
      "name": "Rock_Stone"
    },
    {
      "x": 0,
      "y": 1,
      "z": 3,
      "name": "Rock_Lime_Brick_Smooth"
    },
    {
      "x": 0,
      "y": 2,
      "z": 3,
      "name": "Rock_Marble_Brick_Half",
      "rotation": 4
    },
    {
      "x": 0,
      "y": 3,
      "z": 3,
      "name": "Rock_Marble_Brick_Half",
      "rotation": 4
    },
    {
      "x": 0,
      "y": 4,
      "z": 3,
      "name": "Rock_Marble_Brick"
    },
    {
      "x": 0,
      "y": 5,
      "z": 3,
      "name": "Rock_Marble_Brick"
    },
    {
      "x": 0,
      "y": 8,
      "z": 3,
      "name": "Wood_Darkwood_Roof_Hollow"
    },
    {
      "x": 0,
      "y": 0,
      "z": 4,
      "name": "Rock_Stone"
    },
    {
      "x": 0,
      "y": 1,
      "z": 4,
      "name": "Rock_Lime_Brick_Smooth"
    },
    {
      "x": 0,
      "y": 5,
      "z": 4,
      "name": "Wood_Darkwood_Roof_Flat",
      "rotation": 3
    },
    {
      "x": 0,
      "y": 6,
      "z": 4,
      "name": "Wood_Darkwood_Roof_Steep"
    },
    {
      "x": 0,
      "y": 7,
      "z": 4,
      "name": "Wood_Darkwood_Roof_Steep",
      "filler": 1024
    },
    {
      "x": 0,
      "y": 0,
      "z": 5,
      "name": "Rock_Stone"
    },
    {
      "x": 0,
      "y": 1,
      "z": 5,
      "name": "Rock_Lime_Brick_Smooth"
    },
    {
      "x": 0,
      "y": 5,
      "z": 5,
      "name": "Wood_Darkwood_Roof_Flat",
      "rotation": 3
    },
    {
      "x": 0,
      "y": 0,
      "z": 6,
      "name": "Rock_Stone"
    },
    {
      "x": 0,
      "y": 1,
      "z": 6,
      "name": "Rock_Lime_Brick_Smooth"
    },
    {
      "x": 0,
      "y": 2,
      "z": 6,
      "name": "Bench_Alchemy",
      "filler": 1,
      "rotation": 2
    },
    {
      "x": 0,
      "y": 3,
      "z": 6,
      "name": "Bench_Alchemy",
      "filler": 1025,
      "rotation": 2
    },
    {
      "x": 0,
      "y": 5,
      "z": 6,
      "name": "Wood_Darkwood_Roof_Flat",
      "rotation": 3
    },
    {
      "x": 0,
      "y": 0,
      "z": 7,
      "name": "Rock_Stone"
    },
    {
      "x": 0,
      "y": 1,
      "z": 7,
      "name": "Rock_Marble_Brick"
    },
    {
      "x": 0,
      "y": 2,
      "z": 7,
      "name": "Rock_Marble_Brick"
    },
    {
      "x": 0,
      "y": 3,
      "z": 7,
      "name": "Rock_Marble_Brick"
    },
    {
      "x": 0,
      "y": 4,
      "z": 7,
      "name": "Rock_Marble_Brick"
    },
    {
      "x": 0,
      "y": 5,
      "z": 7,
      "name": "Wood_Darkwood_Roof_Flat",
      "rotation": 3
    },
    {
      "x": 0,
      "y": 1,
      "z": 8,
      "name": "Rock_Marble_Brick_Smooth_Half",
      "rotation": 4
    },
    {
      "x": 0,
      "y": 3,
      "z": 8,
      "name": "Rock_Marble_Brick_Smooth_Half",
      "rotation": 4
    },
    {
      "x": 0,
      "y": 4,
      "z": 8,
      "name": "Wood_Darkwood_Roof_Hollow"
    },
    {
      "x": 1,
      "y": 0,
      "z": -8,
      "name": "Soil_Grass"
    },
    {
      "x": 1,
      "y": 1,
      "z": -8,
      "name": "Empty"
    },
    {
      "x": 1,
      "y": 2,
      "z": -8,
      "name": "Empty"
    },
    {
      "x": 1,
      "y": 3,
      "z": -8,
      "name": "Empty"
    },
    {
      "x": 1,
      "y": 4,
      "z": -8,
      "name": "Empty"
    },
    {
      "x": 1,
      "y": 5,
      "z": -8,
      "name": "Empty"
    },
    {
      "x": 1,
      "y": 6,
      "z": -8,
      "name": "Empty"
    },
    {
      "x": 1,
      "y": 0,
      "z": -7,
      "name": "Rock_Stone"
    },
    {
      "x": 1,
      "y": 1,
      "z": -7,
      "name": "Rock_Marble_Brick_Stairs",
      "rotation": 2
    },
    {
      "x": 1,
      "y": 2,
      "z": -7,
      "name": "Empty"
    },
    {
      "x": 1,
      "y": 3,
      "z": -7,
      "name": "Empty"
    },
    {
      "x": 1,
      "y": 4,
      "z": -7,
      "name": "Empty"
    },
    {
      "x": 1,
      "y": 5,
      "z": -7,
      "name": "Empty"
    },
    {
      "x": 1,
      "y": 6,
      "z": -7,
      "name": "Empty"
    },
    {
      "x": 1,
      "y": 0,
      "z": -6,
      "name": "Rock_Stone"
    },
    {
      "x": 1,
      "y": 1,
      "z": -6,
      "name": "Cloth_Block_Wool_Red"
    },
    {
      "x": 1,
      "y": 5,
      "z": -6,
      "name": "Rock_Marble_Brick_Smooth_Half",
      "rotation": 8
    },
    {
      "x": 1,
      "y": 6,
      "z": -6,
      "name": "Rock_Marble_Brick_Smooth"
    },
    {
      "x": 1,
      "y": 7,
      "z": -6,
      "name": "Rock_Marble_Brick_Smooth_Half"
    },
    {
      "x": 1,
      "y": 0,
      "z": -5,
      "name": "Rock_Stone"
    },
    {
      "x": 1,
      "y": 1,
      "z": -5,
      "name": "Cloth_Block_Wool_Red"
    },
    {
      "x": 1,
      "y": 2,
      "z": -5,
      "name": "*Furniture_Temple_Light_Door_Medilum_State_Definitions_CloseDoorOut",
      "rotation": 2
    },
    {
      "x": 1,
      "y": 3,
      "z": -5,
      "name": "*Furniture_Temple_Light_Door_Medilum_State_Definitions_CloseDoorOut",
      "filler": 1024,
      "rotation": 2
    },
    {
      "x": 1,
      "y": 4,
      "z": -5,
      "name": "*Furniture_Temple_Light_Door_Medilum_State_Definitions_CloseDoorOut",
      "filler": 2048,
      "rotation": 2
    },
    {
      "x": 1,
      "y": 5,
      "z": -5,
      "name": "Rock_Marble_Brick"
    },
    {
      "x": 1,
      "y": 6,
      "z": -5,
      "name": "Wood_Darkwood_Planks_Half",
      "rotation": 4
    },
    {
      "x": 1,
      "y": 7,
      "z": -5,
      "name": "Wood_Darkwood_Planks_Half",
      "rotation": 4
    },
    {
      "x": 1,
      "y": 8,
      "z": -5,
      "name": "Wood_Darkwood_Roof_Hollow",
      "rotation": 2
    },
    {
      "x": 1,
      "y": 0,
      "z": -4,
      "name": "Rock_Stone"
    },
    {
      "x": 1,
      "y": 1,
      "z": -4,
      "name": "Cloth_Block_Wool_Red"
    },
    {
      "x": 1,
      "y": 5,
      "z": -4,
      "name": "Wood_Drywood_Planks_Half",
      "rotation": 8
    },
    {
      "x": 1,
      "y": 9,
      "z": -4,
      "name": "Wood_Darkwood_Roof_Flat",
      "rotation": 1
    },
    {
      "x": 1,
      "y": 0,
      "z": -3,
      "name": "Rock_Stone"
    },
    {
      "x": 1,
      "y": 1,
      "z": -3,
      "name": "Rock_Lime_Brick_Smooth"
    },
    {
      "x": 1,
      "y": 5,
      "z": -3,
      "name": "Wood_Drywood_Planks_Half",
      "rotation": 8
    },
    {
      "x": 1,
      "y": 9,
      "z": -3,
      "name": "Wood_Darkwood_Roof_Flat",
      "rotation": 1
    },
    {
      "x": 1,
      "y": 0,
      "z": -2,
      "name": "Rock_Stone"
    },
    {
      "x": 1,
      "y": 1,
      "z": -2,
      "name": "Rock_Lime_Brick_Smooth"
    },
    {
      "x": 1,
      "y": 5,
      "z": -2,
      "name": "Wood_Drywood_Planks_Half",
      "rotation": 8
    },
    {
      "x": 1,
      "y": 9,
      "z": -2,
      "name": "Wood_Darkwood_Roof_Flat",
      "rotation": 1
    },
    {
      "x": 1,
      "y": 0,
      "z": -1,
      "name": "Rock_Stone"
    },
    {
      "x": 1,
      "y": 1,
      "z": -1,
      "name": "Rock_Lime_Brick_Smooth"
    },
    {
      "x": 1,
      "y": 5,
      "z": -1,
      "name": "Wood_Drywood_Planks_Half",
      "rotation": 8
    },
    {
      "x": 1,
      "y": 9,
      "z": -1,
      "name": "Wood_Darkwood_Roof_Flat",
      "rotation": 1
    },
    {
      "x": 1,
      "y": 0,
      "z": 0,
      "name": "Rock_Stone"
    },
    {
      "x": 1,
      "y": 1,
      "z": 0,
      "name": "*Furniture_Pkmn_Chest_Small_State_Definitions_CloseWindow",
      "components": {
        "Components": {
          "container": {
            "Custom": false,
            "AllowViewing": true,
            "ItemContainer": {
              "Capacity": 36,
              "Items": {
                "0": {
                  "Id": "Pokeball",
                  "Quantity": 1,
                  "Durability": 0.0,
                  "MaxDurability": 0.0,
                  "OverrideDroppedItemAnimation": false
                },
                "35": {
                  "Id": "Potion_Empty_Small",
                  "Quantity": 2,
                  "Durability": 0.0,
                  "MaxDurability": 0.0,
                  "OverrideDroppedItemAnimation": false
                },
                "6": {
                  "Id": "Plant_Fruit_Apricorn",
                  "Quantity": 3,
                  "Durability": 0.0,
                  "MaxDurability": 0.0,
                  "OverrideDroppedItemAnimation": false
                },
                "32": {
                  "Id": "Pokeball",
                  "Quantity": 1,
                  "Durability": 0.0,
                  "MaxDurability": 0.0,
                  "OverrideDroppedItemAnimation": false
                },
                "3": {
                  "Id": "Potion_Health_Lesser",
                  "Quantity": 1,
                  "Durability": 0.0,
                  "MaxDurability": 0.0,
                  "OverrideDroppedItemAnimation": false
                },
                "34": {
                  "Id": "Potion_Empty_Small",
                  "Quantity": 1,
                  "Durability": 0.0,
                  "MaxDurability": 0.0,
                  "OverrideDroppedItemAnimation": false
                },
                "19": {
                  "Id": "Potion_Health_Lesser",
                  "Quantity": 1,
                  "Durability": 0.0,
                  "MaxDurability": 0.0,
                  "OverrideDroppedItemAnimation": false
                }
              }
            }
          }
        }
      }
    },
    {
      "x": 1,
      "y": 2,
      "z": 0,
      "name": "Rock_Peach_Brick_Stairs",
      "rotation": 10
    },
    {
      "x": 1,
      "y": 5,
      "z": 0,
      "name": "Wood_Drywood_Planks_Half",
      "rotation": 8
    },
    {
      "x": 1,
      "y": 9,
      "z": 0,
      "name": "Wood_Darkwood_Roof_Flat",
      "rotation": 1
    },
    {
      "x": 1,
      "y": 0,
      "z": 1,
      "name": "Rock_Stone"
    },
    {
      "x": 1,
      "y": 1,
      "z": 1,
      "name": "Rock_Lime_Brick_Smooth"
    },
    {
      "x": 1,
      "y": 5,
      "z": 1,
      "name": "Wood_Drywood_Planks_Half",
      "rotation": 8
    },
    {
      "x": 1,
      "y": 9,
      "z": 1,
      "name": "Wood_Darkwood_Roof_Flat",
      "rotation": 1
    },
    {
      "x": 1,
      "y": 0,
      "z": 2,
      "name": "Rock_Stone"
    },
    {
      "x": 1,
      "y": 1,
      "z": 2,
      "name": "Rock_Lime_Brick_Smooth"
    },
    {
      "x": 1,
      "y": 2,
      "z": 2,
      "name": "Furniture_Pkmn_Healing_Table",
      "filler": 1023,
      "rotation": 2
    },
    {
      "x": 1,
      "y": 4,
      "z": 2,
      "name": "Furniture_Tavern_Painting",
      "rotation": 2
    },
    {
      "x": 1,
      "y": 5,
      "z": 2,
      "name": "Wood_Drywood_Planks_Half",
      "rotation": 8
    },
    {
      "x": 1,
      "y": 9,
      "z": 2,
      "name": "Wood_Darkwood_Roof_Flat",
      "rotation": 1
    },
    {
      "x": 1,
      "y": 0,
      "z": 3,
      "name": "Rock_Stone"
    },
    {
      "x": 1,
      "y": 1,
      "z": 3,
      "name": "Rock_Lime_Brick_Smooth"
    },
    {
      "x": 1,
      "y": 2,
      "z": 3,
      "name": "Furniture_Pkmn_Healing_Table",
      "filler": 31,
      "rotation": 2
    },
    {
      "x": 1,
      "y": 3,
      "z": 3,
      "name": "Cloth_Roof_Red_Vertical"
    },
    {
      "x": 1,
      "y": 4,
      "z": 3,
      "name": "Rock_Marble_Brick"
    },
    {
      "x": 1,
      "y": 5,
      "z": 3,
      "name": "Rock_Marble_Brick"
    },
    {
      "x": 1,
      "y": 8,
      "z": 3,
      "name": "Wood_Darkwood_Roof_Hollow"
    },
    {
      "x": 1,
      "y": 0,
      "z": 4,
      "name": "Rock_Stone"
    },
    {
      "x": 1,
      "y": 1,
      "z": 4,
      "name": "Rock_Lime_Brick_Smooth"
    },
    {
      "x": 1,
      "y": 5,
      "z": 4,
      "name": "Wood_Darkwood_Roof_Flat",
      "rotation": 3
    },
    {
      "x": 1,
      "y": 6,
      "z": 4,
      "name": "Wood_Darkwood_Roof_Steep"
    },
    {
      "x": 1,
      "y": 7,
      "z": 4,
      "name": "Wood_Darkwood_Roof_Steep",
      "filler": 1024
    },
    {
      "x": 1,
      "y": 0,
      "z": 5,
      "name": "Rock_Stone"
    },
    {
      "x": 1,
      "y": 1,
      "z": 5,
      "name": "Rock_Lime_Brick_Smooth"
    },
    {
      "x": 1,
      "y": 5,
      "z": 5,
      "name": "Wood_Darkwood_Roof_Flat",
      "rotation": 3
    },
    {
      "x": 1,
      "y": 0,
      "z": 6,
      "name": "Rock_Stone"
    },
    {
      "x": 1,
      "y": 1,
      "z": 6,
      "name": "Rock_Lime_Brick_Smooth"
    },
    {
      "x": 1,
      "y": 2,
      "z": 6,
      "name": "*Furniture_Temple_Light_Trapdoor_State_Definitions_OpenDoorOut",
      "rotation": 2
    },
    {
      "x": 1,
      "y": 3,
      "z": 6,
      "name": "*Furniture_Temple_Light_Trapdoor_State_Definitions_OpenDoorOut",
      "rotation": 2
    },
    {
      "x": 1,
      "y": 5,
      "z": 6,
      "name": "Wood_Darkwood_Roof_Flat",
      "rotation": 3
    },
    {
      "x": 1,
      "y": 0,
      "z": 7,
      "name": "Rock_Stone"
    },
    {
      "x": 1,
      "y": 1,
      "z": 7,
      "name": "Rock_Lime_Brick_Smooth"
    },
    {
      "x": 1,
      "y": 2,
      "z": 7,
      "name": "Bench_Furnace",
      "components": {
        "Components": {
          "processingBench": {
            "TierLevel": 1,
            "UpgradeItems": [],
            "InputContainer": {
              "Id": "Simple",
              "Capacity": 2,
              "Items": {}
            },
            "FuelContainer": {
              "Id": "Simple",
              "Capacity": 1,
              "Items": {}
            },
            "OutputContainer": {
              "Id": "Simple",
              "Capacity": 4,
              "Items": {}
            },
            "Progress": 0.0,
            "FuelTime": 0.0,
            "Active": false,
            "NextExtra": 2
          },
          "PlacedByInteraction": {
            "WhoPlacedUuid": {
              "$binary": "iJnnVdMjR5iqsjPMr3DIyQ==",
              "$type": "04"
            }
          }
        }
      },
      "rotation": 2
    },
    {
      "x": 1,
      "y": 3,
      "z": 7,
      "name": "Bench_Furnace",
      "filler": 1024,
      "rotation": 2
    },
    {
      "x": 1,
      "y": 4,
      "z": 7,
      "name": "Rock_Stone_Cobble_Stairs",
      "rotation": 10
    },
    {
      "x": 1,
      "y": 5,
      "z": 7,
      "name": "Furniture_Village_Planter"
    },
    {
      "x": 1,
      "y": 1,
      "z": 8,
      "name": "Rock_Marble_Brick_Half",
      "rotation": 4
    },
    {
      "x": 1,
      "y": 2,
      "z": 8,
      "name": "Rock_Marble_Brick_Half",
      "rotation": 4
    },
    {
      "x": 1,
      "y": 3,
      "z": 8,
      "name": "Rock_Marble_Brick_Half",
      "rotation": 4
    },
    {
      "x": 1,
      "y": 4,
      "z": 8,
      "name": "Wood_Darkwood_Roof_Hollow"
    },
    {
      "x": 2,
      "y": 0,
      "z": -8,
      "name": "Soil_Grass"
    },
    {
      "x": 2,
      "y": 1,
      "z": -8,
      "name": "Empty"
    },
    {
      "x": 2,
      "y": 2,
      "z": -8,
      "name": "Empty"
    },
    {
      "x": 2,
      "y": 3,
      "z": -8,
      "name": "Empty"
    },
    {
      "x": 2,
      "y": 4,
      "z": -8,
      "name": "Empty"
    },
    {
      "x": 2,
      "y": 5,
      "z": -8,
      "name": "Empty"
    },
    {
      "x": 2,
      "y": 6,
      "z": -8,
      "name": "Empty"
    },
    {
      "x": 2,
      "y": 0,
      "z": -7,
      "name": "Rock_Stone"
    },
    {
      "x": 2,
      "y": 1,
      "z": -7,
      "name": "*Rock_Marble_Brick_Stairs_State_Definitions_Corner_Left",
      "rotation": 1
    },
    {
      "x": 2,
      "y": 2,
      "z": -7,
      "name": "Empty"
    },
    {
      "x": 2,
      "y": 3,
      "z": -7,
      "name": "Empty"
    },
    {
      "x": 2,
      "y": 4,
      "z": -7,
      "name": "Empty"
    },
    {
      "x": 2,
      "y": 5,
      "z": -7,
      "name": "Empty"
    },
    {
      "x": 2,
      "y": 6,
      "z": -7,
      "name": "Empty"
    },
    {
      "x": 2,
      "y": 0,
      "z": -6,
      "name": "Rock_Stone"
    },
    {
      "x": 2,
      "y": 1,
      "z": -6,
      "name": "Rock_Marble_Brick_Pillar_Base"
    },
    {
      "x": 2,
      "y": 2,
      "z": -6,
      "name": "Rock_Marble_Brick_Beam"
    },
    {
      "x": 2,
      "y": 3,
      "z": -6,
      "name": "Rock_Marble_Brick_Beam"
    },
    {
      "x": 2,
      "y": 4,
      "z": -6,
      "name": "Rock_Marble_Brick_Beam"
    },
    {
      "x": 2,
      "y": 5,
      "z": -6,
      "name": "Rock_Marble_Brick_Pillar_Base",
      "rotation": 8
    },
    {
      "x": 2,
      "y": 6,
      "z": -6,
      "name": "Rock_Marble_Brick_Smooth"
    },
    {
      "x": 2,
      "y": 7,
      "z": -6,
      "name": "Wood_Darkwood_Roof",
      "rotation": 2
    },
    {
      "x": 2,
      "y": 0,
      "z": -5,
      "name": "Rock_Stone"
    },
    {
      "x": 2,
      "y": 1,
      "z": -5,
      "name": "Rock_Marble_Brick"
    },
    {
      "x": 2,
      "y": 2,
      "z": -5,
      "name": "Rock_Marble_Brick"
    },
    {
      "x": 2,
      "y": 3,
      "z": -5,
      "name": "Rock_Marble_Brick"
    },
    {
      "x": 2,
      "y": 4,
      "z": -5,
      "name": "Rock_Marble_Brick"
    },
    {
      "x": 2,
      "y": 5,
      "z": -5,
      "name": "Rock_Marble_Brick"
    },
    {
      "x": 2,
      "y": 8,
      "z": -5,
      "name": "Wood_Darkwood_Roof_Hollow",
      "rotation": 2
    },
    {
      "x": 2,
      "y": 0,
      "z": -4,
      "name": "Rock_Stone"
    },
    {
      "x": 2,
      "y": 1,
      "z": -4,
      "name": "Rock_Lime_Brick_Smooth"
    },
    {
      "x": 2,
      "y": 5,
      "z": -4,
      "name": "Wood_Drywood_Planks_Half",
      "rotation": 8
    },
    {
      "x": 2,
      "y": 6,
      "z": -4,
      "name": "Wood_Drywood_Fence",
      "rotation": 1
    },
    {
      "x": 2,
      "y": 9,
      "z": -4,
      "name": "Wood_Darkwood_Roof_Flat",
      "rotation": 1
    },
    {
      "x": 2,
      "y": 0,
      "z": -3,
      "name": "Rock_Stone"
    },
    {
      "x": 2,
      "y": 1,
      "z": -3,
      "name": "Rock_Lime_Brick_Smooth"
    },
    {
      "x": 2,
      "y": 5,
      "z": -3,
      "name": "Wood_Drywood_Planks_Half",
      "rotation": 8
    },
    {
      "x": 2,
      "y": 6,
      "z": -3,
      "name": "*Wood_Drywood_Fence_State_Definitions_Corner",
      "rotation": 2
    },
    {
      "x": 2,
      "y": 9,
      "z": -3,
      "name": "Wood_Darkwood_Roof_Flat",
      "rotation": 1
    },
    {
      "x": 2,
      "y": 0,
      "z": -2,
      "name": "Rock_Stone"
    },
    {
      "x": 2,
      "y": 1,
      "z": -2,
      "name": "Rock_Lime_Brick_Smooth"
    },
    {
      "x": 2,
      "y": 5,
      "z": -2,
      "name": "Wood_Drywood_Planks_Half",
      "rotation": 8
    },
    {
      "x": 2,
      "y": 9,
      "z": -2,
      "name": "Wood_Darkwood_Roof_Flat",
      "rotation": 1
    },
    {
      "x": 2,
      "y": 0,
      "z": -1,
      "name": "Rock_Stone"
    },
    {
      "x": 2,
      "y": 1,
      "z": -1,
      "name": "Rock_Lime_Brick_Smooth"
    },
    {
      "x": 2,
      "y": 5,
      "z": -1,
      "name": "Wood_Drywood_Planks_Half",
      "rotation": 8
    },
    {
      "x": 2,
      "y": 9,
      "z": -1,
      "name": "Wood_Darkwood_Roof_Flat",
      "rotation": 1
    },
    {
      "x": 2,
      "y": 0,
      "z": 0,
      "name": "Rock_Stone"
    },
    {
      "x": 2,
      "y": 1,
      "z": 0,
      "name": "Rock_Lime_Brick_Smooth"
    },
    {
      "x": 2,
      "y": 2,
      "z": 0,
      "name": "Rock_Peach_Brick_Stairs",
      "rotation": 10
    },
    {
      "x": 2,
      "y": 5,
      "z": 0,
      "name": "Wood_Drywood_Planks_Half",
      "rotation": 8
    },
    {
      "x": 2,
      "y": 9,
      "z": 0,
      "name": "Wood_Darkwood_Roof_Flat",
      "rotation": 1
    },
    {
      "x": 2,
      "y": 0,
      "z": 1,
      "name": "Rock_Stone"
    },
    {
      "x": 2,
      "y": 1,
      "z": 1,
      "name": "Rock_Lime_Brick_Smooth"
    },
    {
      "x": 2,
      "y": 5,
      "z": 1,
      "name": "Wood_Drywood_Planks_Half",
      "rotation": 8
    },
    {
      "x": 2,
      "y": 9,
      "z": 1,
      "name": "Wood_Darkwood_Roof_Flat",
      "rotation": 1
    },
    {
      "x": 2,
      "y": 0,
      "z": 2,
      "name": "Rock_Stone"
    },
    {
      "x": 2,
      "y": 1,
      "z": 2,
      "name": "Rock_Lime_Brick_Smooth"
    },
    {
      "x": 2,
      "y": 2,
      "z": 2,
      "name": "Furniture_Pkmn_Healing_Table",
      "filler": 992,
      "rotation": 2
    },
    {
      "x": 2,
      "y": 5,
      "z": 2,
      "name": "Wood_Drywood_Planks_Half",
      "rotation": 8
    },
    {
      "x": 2,
      "y": 9,
      "z": 2,
      "name": "Wood_Darkwood_Roof_Flat",
      "rotation": 1
    },
    {
      "x": 2,
      "y": 0,
      "z": 3,
      "name": "Rock_Stone"
    },
    {
      "x": 2,
      "y": 1,
      "z": 3,
      "name": "Rock_Lime_Brick_Smooth"
    },
    {
      "x": 2,
      "y": 2,
      "z": 3,
      "name": "Furniture_Pkmn_Healing_Table",
      "components": {
        "Components": {
          "PlacedByInteraction": {
            "WhoPlacedUuid": {
              "$binary": "iJnnVdMjR5iqsjPMr3DIyQ==",
              "$type": "04"
            }
          },
          "RespawnBlock": {}
        }
      },
      "rotation": 2
    },
    {
      "x": 2,
      "y": 3,
      "z": 3,
      "name": "Cloth_Roof_Red_Vertical"
    },
    {
      "x": 2,
      "y": 4,
      "z": 3,
      "name": "Rock_Marble_Brick"
    },
    {
      "x": 2,
      "y": 5,
      "z": 3,
      "name": "Rock_Marble_Brick"
    },
    {
      "x": 2,
      "y": 8,
      "z": 3,
      "name": "Wood_Darkwood_Roof_Hollow"
    },
    {
      "x": 2,
      "y": 0,
      "z": 4,
      "name": "Rock_Stone"
    },
    {
      "x": 2,
      "y": 1,
      "z": 4,
      "name": "Rock_Lime_Brick_Smooth"
    },
    {
      "x": 2,
      "y": 4,
      "z": 4,
      "name": "Furniture_Temple_Light_Lantern_Ceiling"
    },
    {
      "x": 2,
      "y": 5,
      "z": 4,
      "name": "Wood_Darkwood_Roof_Flat",
      "rotation": 3
    },
    {
      "x": 2,
      "y": 6,
      "z": 4,
      "name": "Wood_Darkwood_Roof_Steep"
    },
    {
      "x": 2,
      "y": 7,
      "z": 4,
      "name": "Wood_Darkwood_Roof_Steep",
      "filler": 1024
    },
    {
      "x": 2,
      "y": 0,
      "z": 5,
      "name": "Rock_Stone"
    },
    {
      "x": 2,
      "y": 1,
      "z": 5,
      "name": "Rock_Lime_Brick_Smooth"
    },
    {
      "x": 2,
      "y": 5,
      "z": 5,
      "name": "Wood_Darkwood_Roof_Flat",
      "rotation": 3
    },
    {
      "x": 2,
      "y": 0,
      "z": 6,
      "name": "Rock_Stone"
    },
    {
      "x": 2,
      "y": 1,
      "z": 6,
      "name": "Rock_Lime_Brick_Smooth"
    },
    {
      "x": 2,
      "y": 2,
      "z": 6,
      "name": "Funnel",
      "components": {
        "Components": {
          "Funnel_Block": {
            "ItemContainer": {
              "Capacity": 5,
              "Items": {}
            },
            "Custom": false,
            "AllowViewing": true
          },
          "PlacedByInteraction": {
            "WhoPlacedUuid": {
              "$binary": "iJnnVdMjR5iqsjPMr3DIyQ==",
              "$type": "04"
            }
          }
        }
      },
      "rotation": 2
    },
    {
      "x": 2,
      "y": 3,
      "z": 6,
      "name": "*Furniture_Temple_Light_Trapdoor_State_Definitions_OpenDoorOut",
      "rotation": 2
    },
    {
      "x": 2,
      "y": 5,
      "z": 6,
      "name": "Wood_Darkwood_Roof_Flat",
      "rotation": 3
    },
    {
      "x": 2,
      "y": 0,
      "z": 7,
      "name": "Rock_Stone"
    },
    {
      "x": 2,
      "y": 1,
      "z": 7,
      "name": "Rock_Lime_Brick_Smooth"
    },
    {
      "x": 2,
      "y": 2,
      "z": 7,
      "name": "Bench_Furnace",
      "filler": 1,
      "rotation": 2
    },
    {
      "x": 2,
      "y": 3,
      "z": 7,
      "name": "Bench_Furnace",
      "filler": 1025,
      "rotation": 2
    },
    {
      "x": 2,
      "y": 4,
      "z": 7,
      "name": "Rock_Marble_Brick"
    },
    {
      "x": 2,
      "y": 5,
      "z": 7,
      "name": "Wood_Darkwood_Roof_Flat",
      "rotation": 3
    },
    {
      "x": 2,
      "y": 1,
      "z": 8,
      "name": "Rock_Marble_Brick_Half",
      "rotation": 4
    },
    {
      "x": 2,
      "y": 2,
      "z": 8,
      "name": "Rock_Marble_Brick_Half",
      "rotation": 4
    },
    {
      "x": 2,
      "y": 3,
      "z": 8,
      "name": "Rock_Marble_Brick_Half",
      "rotation": 4
    },
    {
      "x": 2,
      "y": 4,
      "z": 8,
      "name": "Wood_Darkwood_Roof_Hollow"
    },
    {
      "x": 3,
      "y": 1,
      "z": -8,
      "name": "Empty"
    },
    {
      "x": 3,
      "y": 2,
      "z": -8,
      "name": "Empty"
    },
    {
      "x": 3,
      "y": 0,
      "z": -7,
      "name": "Soil_Grass"
    },
    {
      "x": 3,
      "y": 1,
      "z": -7,
      "name": "Empty"
    },
    {
      "x": 3,
      "y": 2,
      "z": -7,
      "name": "Empty"
    },
    {
      "x": 3,
      "y": 0,
      "z": -6,
      "name": "Soil_Grass"
    },
    {
      "x": 3,
      "y": 1,
      "z": -6,
      "name": "Rock_Marble_Brick_Smooth_Half",
      "rotation": 6
    },
    {
      "x": 3,
      "y": 3,
      "z": -6,
      "name": "Rock_Marble_Brick_Smooth_Half",
      "rotation": 6
    },
    {
      "x": 3,
      "y": 6,
      "z": -6,
      "name": "Wood_Darkwood_Roof_Steep",
      "rotation": 2
    },
    {
      "x": 3,
      "y": 7,
      "z": -6,
      "name": "Wood_Darkwood_Roof_Steep",
      "filler": 1024,
      "rotation": 2
    },
    {
      "x": 3,
      "y": 0,
      "z": -5,
      "name": "Rock_Stone"
    },
    {
      "x": 3,
      "y": 1,
      "z": -5,
      "name": "Rock_Marble_Brick"
    },
    {
      "x": 3,
      "y": 2,
      "z": -5,
      "name": "Rock_Marble_Brick"
    },
    {
      "x": 3,
      "y": 3,
      "z": -5,
      "name": "Rock_Marble_Brick"
    },
    {
      "x": 3,
      "y": 4,
      "z": -5,
      "name": "Furniture_Temple_Light_Window"
    },
    {
      "x": 3,
      "y": 5,
      "z": -5,
      "name": "Rock_Marble_Brick"
    },
    {
      "x": 3,
      "y": 8,
      "z": -5,
      "name": "Wood_Darkwood_Roof_Hollow",
      "rotation": 2
    },
    {
      "x": 3,
      "y": 0,
      "z": -4,
      "name": "Rock_Stone"
    },
    {
      "x": 3,
      "y": 1,
      "z": -4,
      "name": "Rock_Lime_Brick_Smooth"
    },
    {
      "x": 3,
      "y": 2,
      "z": -4,
      "name": "Wood_Drywood_Stairs",
      "rotation": 3
    },
    {
      "x": 3,
      "y": 9,
      "z": -4,
      "name": "Wood_Darkwood_Roof_Flat",
      "rotation": 1
    },
    {
      "x": 3,
      "y": 0,
      "z": -3,
      "name": "Rock_Stone"
    },
    {
      "x": 3,
      "y": 1,
      "z": -3,
      "name": "Rock_Lime_Brick_Smooth"
    },
    {
      "x": 3,
      "y": 5,
      "z": -3,
      "name": "Wood_Drywood_Planks_Half",
      "rotation": 8
    },
    {
      "x": 3,
      "y": 6,
      "z": -3,
      "name": "Wood_Drywood_Fence"
    },
    {
      "x": 3,
      "y": 9,
      "z": -3,
      "name": "Wood_Darkwood_Roof_Flat",
      "rotation": 1
    },
    {
      "x": 3,
      "y": 0,
      "z": -2,
      "name": "Rock_Stone"
    },
    {
      "x": 3,
      "y": 1,
      "z": -2,
      "name": "Rock_Lime_Brick_Smooth"
    },
    {
      "x": 3,
      "y": 5,
      "z": -2,
      "name": "Wood_Drywood_Planks_Half",
      "rotation": 8
    },
    {
      "x": 3,
      "y": 9,
      "z": -2,
      "name": "Wood_Darkwood_Roof_Flat",
      "rotation": 1
    },
    {
      "x": 3,
      "y": 0,
      "z": -1,
      "name": "Rock_Stone"
    },
    {
      "x": 3,
      "y": 1,
      "z": -1,
      "name": "Rock_Lime_Brick_Smooth"
    },
    {
      "x": 3,
      "y": 5,
      "z": -1,
      "name": "Wood_Drywood_Planks_Half",
      "rotation": 8
    },
    {
      "x": 3,
      "y": 9,
      "z": -1,
      "name": "Wood_Darkwood_Roof_Flat",
      "rotation": 1
    },
    {
      "x": 3,
      "y": 0,
      "z": 0,
      "name": "Rock_Stone"
    },
    {
      "x": 3,
      "y": 1,
      "z": 0,
      "name": "Rock_Lime_Brick_Smooth"
    },
    {
      "x": 3,
      "y": 2,
      "z": 0,
      "name": "*Rock_Peach_Brick_Stairs_State_Definitions_Inverted_Corner_Right",
      "rotation": 9
    },
    {
      "x": 3,
      "y": 5,
      "z": 0,
      "name": "Wood_Drywood_Planks_Half",
      "rotation": 8
    },
    {
      "x": 3,
      "y": 9,
      "z": 0,
      "name": "Wood_Darkwood_Roof_Flat",
      "rotation": 1
    },
    {
      "x": 3,
      "y": 0,
      "z": 1,
      "name": "Rock_Stone"
    },
    {
      "x": 3,
      "y": 1,
      "z": 1,
      "name": "Rock_Lime_Brick_Smooth"
    },
    {
      "x": 3,
      "y": 2,
      "z": 1,
      "name": "Rock_Peach_Brick_Stairs",
      "rotation": 9
    },
    {
      "x": 3,
      "y": 5,
      "z": 1,
      "name": "Wood_Drywood_Planks_Half",
      "rotation": 8
    },
    {
      "x": 3,
      "y": 9,
      "z": 1,
      "name": "Wood_Darkwood_Roof_Flat",
      "rotation": 1
    },
    {
      "x": 3,
      "y": 0,
      "z": 2,
      "name": "Rock_Stone"
    },
    {
      "x": 3,
      "y": 1,
      "z": 2,
      "name": "Rock_Lime_Brick_Smooth"
    },
    {
      "x": 3,
      "y": 2,
      "z": 2,
      "name": "Rock_Peach_Brick_Stairs",
      "rotation": 9
    },
    {
      "x": 3,
      "y": 3,
      "z": 2,
      "name": "Furniture_Temple_Light_Shelf",
      "rotation": 2
    },
    {
      "x": 3,
      "y": 4,
      "z": 2,
      "name": "Potion_Stamina_Small"
    },
    {
      "x": 3,
      "y": 5,
      "z": 2,
      "name": "Wood_Drywood_Planks_Half",
      "rotation": 8
    },
    {
      "x": 3,
      "y": 9,
      "z": 2,
      "name": "Wood_Darkwood_Roof_Flat",
      "rotation": 1
    },
    {
      "x": 3,
      "y": 0,
      "z": 3,
      "name": "Rock_Stone"
    },
    {
      "x": 3,
      "y": 1,
      "z": 3,
      "name": "Rock_Marble_Brick"
    },
    {
      "x": 3,
      "y": 2,
      "z": 3,
      "name": "Rock_Marble_Brick"
    },
    {
      "x": 3,
      "y": 3,
      "z": 3,
      "name": "Rock_Marble_Brick"
    },
    {
      "x": 3,
      "y": 4,
      "z": 3,
      "name": "Rock_Marble_Brick"
    },
    {
      "x": 3,
      "y": 5,
      "z": 3,
      "name": "Rock_Marble_Brick"
    },
    {
      "x": 3,
      "y": 8,
      "z": 3,
      "name": "Wood_Darkwood_Roof_Hollow"
    },
    {
      "x": 3,
      "y": 0,
      "z": 4,
      "name": "Rock_Stone"
    },
    {
      "x": 3,
      "y": 1,
      "z": 4,
      "name": "Rock_Marble_Brick"
    },
    {
      "x": 3,
      "y": 2,
      "z": 4,
      "name": "Rock_Marble_Brick"
    },
    {
      "x": 3,
      "y": 3,
      "z": 4,
      "name": "Rock_Marble_Brick"
    },
    {
      "x": 3,
      "y": 4,
      "z": 4,
      "name": "Rock_Marble_Brick"
    },
    {
      "x": 3,
      "y": 5,
      "z": 4,
      "name": "Wood_Darkwood_Roof_Flat",
      "rotation": 3
    },
    {
      "x": 3,
      "y": 6,
      "z": 4,
      "name": "Wood_Darkwood_Roof_Steep"
    },
    {
      "x": 3,
      "y": 7,
      "z": 4,
      "name": "Wood_Darkwood_Roof_Steep",
      "filler": 1024
    },
    {
      "x": 3,
      "y": 0,
      "z": 5,
      "name": "Rock_Stone"
    },
    {
      "x": 3,
      "y": 1,
      "z": 5,
      "name": "Rock_Marble_Brick"
    },
    {
      "x": 3,
      "y": 2,
      "z": 5,
      "name": "Rock_Marble_Brick"
    },
    {
      "x": 3,
      "y": 3,
      "z": 5,
      "name": "Rock_Marble_Brick"
    },
    {
      "x": 3,
      "y": 4,
      "z": 5,
      "name": "Rock_Marble_Brick"
    },
    {
      "x": 3,
      "y": 5,
      "z": 5,
      "name": "Wood_Darkwood_Roof_Flat",
      "rotation": 3
    },
    {
      "x": 3,
      "y": 0,
      "z": 6,
      "name": "Rock_Stone"
    },
    {
      "x": 3,
      "y": 1,
      "z": 6,
      "name": "Rock_Marble_Brick"
    },
    {
      "x": 3,
      "y": 2,
      "z": 6,
      "name": "Rock_Marble_Brick"
    },
    {
      "x": 3,
      "y": 3,
      "z": 6,
      "name": "Rock_Marble_Brick"
    },
    {
      "x": 3,
      "y": 4,
      "z": 6,
      "name": "Rock_Marble_Brick"
    },
    {
      "x": 3,
      "y": 5,
      "z": 6,
      "name": "Wood_Darkwood_Roof_Flat",
      "rotation": 3
    },
    {
      "x": 3,
      "y": 0,
      "z": 7,
      "name": "Rock_Stone"
    },
    {
      "x": 3,
      "y": 1,
      "z": 7,
      "name": "Rock_Marble_Brick"
    },
    {
      "x": 3,
      "y": 2,
      "z": 7,
      "name": "Rock_Marble_Brick"
    },
    {
      "x": 3,
      "y": 3,
      "z": 7,
      "name": "Rock_Marble_Brick"
    },
    {
      "x": 3,
      "y": 4,
      "z": 7,
      "name": "Rock_Marble_Brick"
    },
    {
      "x": 3,
      "y": 5,
      "z": 7,
      "name": "Wood_Darkwood_Roof_Flat",
      "rotation": 3
    },
    {
      "x": 3,
      "y": 1,
      "z": 8,
      "name": "Rock_Marble_Brick_Smooth_Half",
      "rotation": 4
    },
    {
      "x": 3,
      "y": 3,
      "z": 8,
      "name": "Rock_Marble_Brick_Smooth_Half",
      "rotation": 4
    },
    {
      "x": 3,
      "y": 4,
      "z": 8,
      "name": "Wood_Darkwood_Roof_Hollow"
    },
    {
      "x": 4,
      "y": 1,
      "z": -8,
      "name": "Empty"
    },
    {
      "x": 4,
      "y": 2,
      "z": -8,
      "name": "Empty"
    },
    {
      "x": 4,
      "y": 0,
      "z": -7,
      "name": "Soil_Grass"
    },
    {
      "x": 4,
      "y": 1,
      "z": -7,
      "name": "Empty"
    },
    {
      "x": 4,
      "y": 2,
      "z": -7,
      "name": "Empty"
    },
    {
      "x": 4,
      "y": 0,
      "z": -6,
      "name": "Soil_Grass"
    },
    {
      "x": 4,
      "y": 1,
      "z": -6,
      "name": "Rock_Marble_Brick_Smooth_Half",
      "rotation": 6
    },
    {
      "x": 4,
      "y": 2,
      "z": -6,
      "name": "Furniture_Tavern_Painting",
      "rotation": 2
    },
    {
      "x": 4,
      "y": 3,
      "z": -6,
      "name": "Rock_Marble_Brick_Smooth_Half",
      "rotation": 6
    },
    {
      "x": 4,
      "y": 6,
      "z": -6,
      "name": "Wood_Darkwood_Roof_Steep",
      "rotation": 2
    },
    {
      "x": 4,
      "y": 7,
      "z": -6,
      "name": "Wood_Darkwood_Roof_Steep",
      "filler": 1024,
      "rotation": 2
    },
    {
      "x": 4,
      "y": 0,
      "z": -5,
      "name": "Rock_Stone"
    },
    {
      "x": 4,
      "y": 1,
      "z": -5,
      "name": "Rock_Marble_Brick"
    },
    {
      "x": 4,
      "y": 2,
      "z": -5,
      "name": "Rock_Marble_Brick"
    },
    {
      "x": 4,
      "y": 3,
      "z": -5,
      "name": "Rock_Marble_Brick"
    },
    {
      "x": 4,
      "y": 4,
      "z": -5,
      "name": "Furniture_Temple_Light_Window"
    },
    {
      "x": 4,
      "y": 5,
      "z": -5,
      "name": "Rock_Marble_Brick"
    },
    {
      "x": 4,
      "y": 8,
      "z": -5,
      "name": "Wood_Darkwood_Roof_Hollow",
      "rotation": 2
    },
    {
      "x": 4,
      "y": 0,
      "z": -4,
      "name": "Rock_Stone"
    },
    {
      "x": 4,
      "y": 1,
      "z": -4,
      "name": "Rock_Lime_Brick_Smooth"
    },
    {
      "x": 4,
      "y": 2,
      "z": -4,
      "name": "Wood_Drywood_Stairs",
      "rotation": 11
    },
    {
      "x": 4,
      "y": 3,
      "z": -4,
      "name": "Wood_Drywood_Stairs",
      "rotation": 3
    },
    {
      "x": 4,
      "y": 9,
      "z": -4,
      "name": "Wood_Darkwood_Roof_Flat",
      "rotation": 3
    },
    {
      "x": 4,
      "y": 0,
      "z": -3,
      "name": "Rock_Stone"
    },
    {
      "x": 4,
      "y": 1,
      "z": -3,
      "name": "Rock_Lime_Brick_Smooth"
    },
    {
      "x": 4,
      "y": 5,
      "z": -3,
      "name": "Wood_Drywood_Planks_Half",
      "rotation": 8
    },
    {
      "x": 4,
      "y": 6,
      "z": -3,
      "name": "*Wood_Drywood_Fence_State_Definitions_Corner"
    },
    {
      "x": 4,
      "y": 9,
      "z": -3,
      "name": "Wood_Darkwood_Roof_Flat",
      "rotation": 3
    },
    {
      "x": 4,
      "y": 0,
      "z": -2,
      "name": "Rock_Stone"
    },
    {
      "x": 4,
      "y": 1,
      "z": -2,
      "name": "Rock_Lime_Brick_Smooth"
    },
    {
      "x": 4,
      "y": 5,
      "z": -2,
      "name": "Wood_Drywood_Planks_Half",
      "rotation": 8
    },
    {
      "x": 4,
      "y": 6,
      "z": -2,
      "name": "Wood_Drywood_Fence",
      "rotation": 1
    },
    {
      "x": 4,
      "y": 9,
      "z": -2,
      "name": "Wood_Darkwood_Roof_Flat",
      "rotation": 3
    },
    {
      "x": 4,
      "y": 0,
      "z": -1,
      "name": "Rock_Stone"
    },
    {
      "x": 4,
      "y": 1,
      "z": -1,
      "name": "Rock_Lime_Brick_Smooth"
    },
    {
      "x": 4,
      "y": 5,
      "z": -1,
      "name": "Wood_Drywood_Planks_Half",
      "rotation": 8
    },
    {
      "x": 4,
      "y": 9,
      "z": -1,
      "name": "Wood_Darkwood_Roof_Flat",
      "rotation": 3
    },
    {
      "x": 4,
      "y": 0,
      "z": 0,
      "name": "Rock_Stone"
    },
    {
      "x": 4,
      "y": 1,
      "z": 0,
      "name": "Rock_Lime_Brick_Smooth"
    },
    {
      "x": 4,
      "y": 5,
      "z": 0,
      "name": "Wood_Drywood_Planks_Half",
      "rotation": 8
    },
    {
      "x": 4,
      "y": 9,
      "z": 0,
      "name": "Wood_Darkwood_Roof_Flat",
      "rotation": 3
    },
    {
      "x": 4,
      "y": 0,
      "z": 1,
      "name": "Rock_Stone"
    },
    {
      "x": 4,
      "y": 1,
      "z": 1,
      "name": "Rock_Lime_Brick_Smooth"
    },
    {
      "x": 4,
      "y": 5,
      "z": 1,
      "name": "Wood_Drywood_Planks_Half",
      "rotation": 8
    },
    {
      "x": 4,
      "y": 9,
      "z": 1,
      "name": "Wood_Darkwood_Roof_Flat",
      "rotation": 3
    },
    {
      "x": 4,
      "y": 0,
      "z": 2,
      "name": "Rock_Stone"
    },
    {
      "x": 4,
      "y": 1,
      "z": 2,
      "name": "Rock_Lime_Brick_Smooth"
    },
    {
      "x": 4,
      "y": 2,
      "z": 2,
      "name": "Furniture_Village_Bookcase",
      "rotation": 2
    },
    {
      "x": 4,
      "y": 3,
      "z": 2,
      "name": "Furniture_Village_Bookcase",
      "rotation": 2
    },
    {
      "x": 4,
      "y": 5,
      "z": 2,
      "name": "Wood_Drywood_Planks_Half",
      "rotation": 8
    },
    {
      "x": 4,
      "y": 9,
      "z": 2,
      "name": "Wood_Darkwood_Roof_Flat",
      "rotation": 3
    },
    {
      "x": 4,
      "y": 0,
      "z": 3,
      "name": "Rock_Stone"
    },
    {
      "x": 4,
      "y": 1,
      "z": 3,
      "name": "Rock_Marble_Brick"
    },
    {
      "x": 4,
      "y": 2,
      "z": 3,
      "name": "Rock_Marble_Brick"
    },
    {
      "x": 4,
      "y": 3,
      "z": 3,
      "name": "Rock_Marble_Brick"
    },
    {
      "x": 4,
      "y": 4,
      "z": 3,
      "name": "Rock_Marble_Brick"
    },
    {
      "x": 4,
      "y": 5,
      "z": 3,
      "name": "Rock_Marble_Brick"
    },
    {
      "x": 4,
      "y": 8,
      "z": 3,
      "name": "Wood_Darkwood_Roof_Hollow"
    },
    {
      "x": 4,
      "y": 4,
      "z": 4,
      "name": "Wood_Darkwood_Roof_Hollow",
      "rotation": 1
    },
    {
      "x": 4,
      "y": 6,
      "z": 4,
      "name": "Wood_Darkwood_Roof_Steep"
    },
    {
      "x": 4,
      "y": 7,
      "z": 4,
      "name": "Wood_Darkwood_Roof_Steep",
      "filler": 1024
    },
    {
      "x": 4,
      "y": 1,
      "z": 5,
      "name": "Rock_Marble_Brick_Smooth_Half",
      "rotation": 5
    },
    {
      "x": 4,
      "y": 3,
      "z": 5,
      "name": "Rock_Marble_Brick_Smooth_Half",
      "rotation": 5
    },
    {
      "x": 4,
      "y": 4,
      "z": 5,
      "name": "Wood_Darkwood_Roof_Hollow",
      "rotation": 1
    },
    {
      "x": 4,
      "y": 1,
      "z": 6,
      "name": "Rock_Marble_Brick_Smooth_Half",
      "rotation": 5
    },
    {
      "x": 4,
      "y": 3,
      "z": 6,
      "name": "Rock_Marble_Brick_Smooth_Half",
      "rotation": 5
    },
    {
      "x": 4,
      "y": 4,
      "z": 6,
      "name": "Wood_Darkwood_Roof_Hollow",
      "rotation": 1
    },
    {
      "x": 4,
      "y": 1,
      "z": 7,
      "name": "Rock_Marble_Brick_Smooth_Half",
      "rotation": 5
    },
    {
      "x": 4,
      "y": 3,
      "z": 7,
      "name": "Rock_Marble_Brick_Smooth_Half",
      "rotation": 5
    },
    {
      "x": 4,
      "y": 4,
      "z": 7,
      "name": "Wood_Darkwood_Roof_Hollow",
      "rotation": 1
    },
    {
      "x": 4,
      "y": 4,
      "z": 8,
      "name": "*Wood_Darkwood_Roof_Hollow_State_Definitions_Corner_Left"
    },
    {
      "x": 5,
      "y": 1,
      "z": -8,
      "name": "Empty"
    },
    {
      "x": 5,
      "y": 2,
      "z": -8,
      "name": "Empty"
    },
    {
      "x": 5,
      "y": 0,
      "z": -7,
      "name": "Soil_Grass"
    },
    {
      "x": 5,
      "y": 1,
      "z": -7,
      "name": "Empty"
    },
    {
      "x": 5,
      "y": 2,
      "z": -7,
      "name": "Empty"
    },
    {
      "x": 5,
      "y": 0,
      "z": -6,
      "name": "Soil_Grass"
    },
    {
      "x": 5,
