{
  "version": 8,
  "blockIdVersion": 11,
  "anchorX": 0,
  "anchorY": 0,
  "anchorZ": 0,
  "blocks": [
    {
      "x": -7,
      "y": 0,
      "z": -10,
      "name": "Soil_Grass"
    },
    {
      "x": -7,
      "y": 0,
      "z": -9,
      "name": "Soil_Grass"
    },
    {
      "x": -7,
      "y": 7,
      "z": -9,
      "name": "Cloth_Roof_White_Vertical",
      "rotation": 3
    },
    {
      "x": -7,
      "y": 0,
      "z": -8,
      "name": "Soil_Grass"
    },
    {
      "x": -7,
      "y": 2,
      "z": -8,
      "name": "Cloth_Roof_White_Vertical",
      "rotation": 3
    },
    {
      "x": -7,
      "y": 3,
      "z": -8,
      "name": "Cloth_Roof_White_Vertical",
      "rotation": 3
    },
    {
      "x": -7,
      "y": 4,
      "z": -8,
      "name": "Cloth_Roof_White_Vertical",
      "rotation": 3
    },
    {
      "x": -7,
      "y": 6,
      "z": -8,
      "name": "Cloth_Roof_White_Vertical",
      "rotation": 3
    },
    {
      "x": -7,
      "y": 7,
      "z": -8,
      "name": "Soil_Clay_Smooth_White"
    },
    {
      "x": -7,
      "y": 8,
      "z": -8,
      "name": "Cloth_Roof_Red_Vertical",
      "rotation": 3
    },
    {
      "x": -7,
      "y": 9,
      "z": -8,
      "name": "Cloth_Roof_Red_Vertical",
      "rotation": 3
    },
    {
      "x": -7,
      "y": 0,
      "z": -7,
      "name": "Soil_Grass"
    },
    {
      "x": -7,
      "y": 2,
      "z": -7,
      "name": "Cloth_Roof_White_Vertical",
      "rotation": 3
    },
    {
      "x": -7,
      "y": 3,
      "z": -7,
      "name": "Cloth_Roof_White_Vertical",
      "rotation": 3
    },
    {
      "x": -7,
      "y": 4,
      "z": -7,
      "name": "Cloth_Roof_White_Vertical",
      "rotation": 3
    },
    {
      "x": -7,
      "y": 7,
      "z": -7,
      "name": "Soil_Clay_Smooth_White"
    },
    {
      "x": -7,
      "y": 8,
      "z": -7,
      "name": "Cloth_Roof_Red_Vertical",
      "rotation": 3
    },
    {
      "x": -7,
      "y": 9,
      "z": -7,
      "name": "Cloth_Roof_Red_Vertical",
      "rotation": 3
    },
    {
      "x": -7,
      "y": 0,
      "z": -6,
      "name": "Soil_Grass"
    },
    {
      "x": -7,
      "y": 2,
      "z": -6,
      "name": "Cloth_Roof_White_Vertical",
      "rotation": 3
    },
    {
      "x": -7,
      "y": 3,
      "z": -6,
      "name": "Cloth_Roof_White_Vertical",
      "rotation": 3
    },
    {
      "x": -7,
      "y": 4,
      "z": -6,
      "name": "Cloth_Roof_White_Vertical",
      "rotation": 3
    },
    {
      "x": -7,
      "y": 7,
      "z": -6,
      "name": "Soil_Clay_Smooth_White"
    },
    {
      "x": -7,
      "y": 8,
      "z": -6,
      "name": "Cloth_Roof_Red_Vertical",
      "rotation": 3
    },
    {
      "x": -7,
      "y": 9,
      "z": -6,
      "name": "Cloth_Roof_Red_Vertical",
      "rotation": 3
    },
    {
      "x": -7,
      "y": 0,
      "z": -5,
      "name": "Soil_Grass"
    },
    {
      "x": -7,
      "y": 2,
      "z": -5,
      "name": "Cloth_Roof_White_Vertical",
      "rotation": 3
    },
    {
      "x": -7,
      "y": 3,
      "z": -5,
      "name": "Cloth_Roof_White_Vertical",
      "rotation": 3
    },
    {
      "x": -7,
      "y": 4,
      "z": -5,
      "name": "Cloth_Roof_White_Vertical",
      "rotation": 3
    },
    {
      "x": -7,
      "y": 7,
      "z": -5,
      "name": "Soil_Clay_Smooth_White"
    },
    {
      "x": -7,
      "y": 8,
      "z": -5,
      "name": "Cloth_Roof_Red_Vertical",
      "rotation": 3
    },
    {
      "x": -7,
      "y": 9,
      "z": -5,
      "name": "Cloth_Roof_Red_Vertical",
      "rotation": 3
    },
    {
      "x": -7,
      "y": 0,
      "z": -4,
      "name": "Soil_Grass"
    },
    {
      "x": -7,
      "y": 2,
      "z": -4,
      "name": "Cloth_Roof_White_Vertical",
      "rotation": 3
    },
    {
      "x": -7,
      "y": 3,
      "z": -4,
      "name": "Cloth_Roof_White_Vertical",
      "rotation": 3
    },
    {
      "x": -7,
      "y": 4,
      "z": -4,
      "name": "Cloth_Roof_White_Vertical",
      "rotation": 3
    },
    {
      "x": -7,
      "y": 7,
      "z": -4,
      "name": "Soil_Clay_Smooth_White"
    },
    {
      "x": -7,
      "y": 8,
      "z": -4,
      "name": "Cloth_Roof_Red_Vertical",
      "rotation": 3
    },
    {
      "x": -7,
      "y": 9,
      "z": -4,
      "name": "Cloth_Roof_Red_Vertical",
      "rotation": 3
    },
    {
      "x": -7,
      "y": 0,
      "z": -3,
      "name": "Soil_Grass"
    },
    {
      "x": -7,
      "y": 2,
      "z": -3,
      "name": "Cloth_Roof_White_Vertical",
      "rotation": 3
    },
    {
      "x": -7,
      "y": 3,
      "z": -3,
      "name": "Cloth_Roof_White_Vertical",
      "rotation": 3
    },
    {
      "x": -7,
      "y": 4,
      "z": -3,
      "name": "Cloth_Roof_White_Vertical",
      "rotation": 3
    },
    {
      "x": -7,
      "y": 7,
      "z": -3,
      "name": "Soil_Clay_Smooth_White"
    },
    {
      "x": -7,
      "y": 8,
      "z": -3,
      "name": "Cloth_Roof_Red_Vertical",
      "rotation": 3
    },
    {
      "x": -7,
      "y": 9,
      "z": -3,
      "name": "Cloth_Roof_Red_Vertical",
      "rotation": 3
    },
    {
      "x": -7,
      "y": 0,
      "z": -2,
      "name": "Soil_Grass"
    },
    {
      "x": -7,
      "y": 2,
      "z": -2,
      "name": "Cloth_Roof_White_Vertical",
      "rotation": 3
    },
    {
      "x": -7,
      "y": 3,
      "z": -2,
      "name": "Cloth_Roof_White_Vertical",
      "rotation": 3
    },
    {
      "x": -7,
      "y": 4,
      "z": -2,
      "name": "Cloth_Roof_White_Vertical",
      "rotation": 3
    },
    {
      "x": -7,
      "y": 7,
      "z": -2,
      "name": "Soil_Clay_Smooth_White"
    },
    {
      "x": -7,
      "y": 8,
      "z": -2,
      "name": "Cloth_Roof_Red_Vertical",
      "rotation": 3
    },
    {
      "x": -7,
      "y": 9,
      "z": -2,
      "name": "Cloth_Roof_Red_Vertical",
      "rotation": 3
    },
    {
      "x": -7,
      "y": 0,
      "z": -1,
      "name": "Soil_Grass"
    },
    {
      "x": -7,
      "y": 2,
      "z": -1,
      "name": "Cloth_Roof_White_Vertical",
      "rotation": 3
    },
    {
      "x": -7,
      "y": 3,
      "z": -1,
      "name": "Cloth_Roof_White_Vertical",
      "rotation": 3
    },
    {
      "x": -7,
      "y": 4,
      "z": -1,
      "name": "Cloth_Roof_White_Vertical",
      "rotation": 3
    },
    {
      "x": -7,
      "y": 7,
      "z": -1,
      "name": "Soil_Clay_Smooth_White"
    },
    {
      "x": -7,
      "y": 8,
      "z": -1,
      "name": "Cloth_Roof_Red_Vertical",
      "rotation": 3
    },
    {
      "x": -7,
      "y": 9,
      "z": -1,
      "name": "Cloth_Roof_Red_Vertical",
      "rotation": 3
    },
    {
      "x": -7,
      "y": 0,
      "z": 0,
      "name": "Soil_Grass"
    },
    {
      "x": -7,
      "y": 2,
      "z": 0,
      "name": "Cloth_Roof_White_Vertical",
      "rotation": 3
    },
    {
      "x": -7,
      "y": 3,
      "z": 0,
      "name": "Cloth_Roof_White_Vertical",
      "rotation": 3
    },
    {
      "x": -7,
      "y": 4,
      "z": 0,
      "name": "Cloth_Roof_White_Vertical",
      "rotation": 3
    },
    {
      "x": -7,
      "y": 7,
      "z": 0,
      "name": "Soil_Clay_Smooth_White"
    },
    {
      "x": -7,
      "y": 8,
      "z": 0,
      "name": "Cloth_Roof_Red_Vertical",
      "rotation": 3
    },
    {
      "x": -7,
      "y": 9,
      "z": 0,
      "name": "Cloth_Roof_Red_Vertical",
      "rotation": 3
    },
    {
      "x": -7,
      "y": 0,
      "z": 1,
      "name": "Soil_Grass"
    },
    {
      "x": -7,
      "y": 2,
      "z": 1,
      "name": "Cloth_Roof_White_Vertical",
      "rotation": 3
    },
    {
      "x": -7,
      "y": 3,
      "z": 1,
      "name": "Cloth_Roof_White_Vertical",
      "rotation": 3
    },
    {
      "x": -7,
      "y": 4,
      "z": 1,
      "name": "Cloth_Roof_White_Vertical",
      "rotation": 3
    },
    {
      "x": -7,
      "y": 7,
      "z": 1,
      "name": "Soil_Clay_Smooth_White"
    },
    {
      "x": -7,
      "y": 8,
      "z": 1,
      "name": "Cloth_Roof_Red_Vertical",
      "rotation": 3
    },
    {
      "x": -7,
      "y": 9,
      "z": 1,
      "name": "Cloth_Roof_Red_Vertical",
      "rotation": 3
    },
    {
      "x": -7,
      "y": 0,
      "z": 2,
      "name": "Soil_Grass"
    },
    {
      "x": -7,
      "y": 2,
      "z": 2,
      "name": "Cloth_Roof_White_Vertical",
      "rotation": 3
    },
    {
      "x": -7,
      "y": 3,
      "z": 2,
      "name": "Cloth_Roof_White_Vertical",
      "rotation": 3
    },
    {
      "x": -7,
      "y": 4,
      "z": 2,
      "name": "Cloth_Roof_White_Vertical",
      "rotation": 3
    },
    {
      "x": -7,
      "y": 7,
      "z": 2,
      "name": "Soil_Clay_Smooth_White"
    },
    {
      "x": -7,
      "y": 8,
      "z": 2,
      "name": "Cloth_Roof_Red_Vertical",
      "rotation": 3
    },
    {
      "x": -7,
      "y": 9,
      "z": 2,
      "name": "Cloth_Roof_Red_Vertical",
      "rotation": 3
    },
    {
      "x": -7,
      "y": 0,
      "z": 3,
      "name": "Soil_Grass"
    },
    {
      "x": -7,
      "y": 2,
      "z": 3,
      "name": "Cloth_Roof_White_Vertical",
      "rotation": 3
    },
    {
      "x": -7,
      "y": 3,
      "z": 3,
      "name": "Cloth_Roof_White_Vertical",
      "rotation": 3
    },
    {
      "x": -7,
      "y": 4,
      "z": 3,
      "name": "Cloth_Roof_White_Vertical",
      "rotation": 3
    },
    {
      "x": -7,
      "y": 7,
      "z": 3,
      "name": "Soil_Clay_Smooth_White"
    },
    {
      "x": -7,
      "y": 8,
      "z": 3,
      "name": "Cloth_Roof_Red_Vertical",
      "rotation": 3
    },
    {
      "x": -7,
      "y": 9,
      "z": 3,
      "name": "Cloth_Roof_Red_Vertical",
      "rotation": 3
    },
    {
      "x": -7,
      "y": 0,
      "z": 4,
      "name": "Soil_Grass"
    },
    {
      "x": -7,
      "y": 2,
      "z": 4,
      "name": "Cloth_Roof_White_Vertical",
      "rotation": 3
    },
    {
      "x": -7,
      "y": 3,
      "z": 4,
      "name": "Cloth_Roof_White_Vertical",
      "rotation": 3
    },
    {
      "x": -7,
      "y": 4,
      "z": 4,
      "name": "Cloth_Roof_White_Vertical",
      "rotation": 3
    },
    {
      "x": -7,
      "y": 7,
      "z": 4,
      "name": "Soil_Clay_Smooth_White"
    },
    {
      "x": -7,
      "y": 8,
      "z": 4,
      "name": "Cloth_Roof_Red_Vertical",
      "rotation": 3
    },
    {
      "x": -7,
      "y": 9,
      "z": 4,
      "name": "Cloth_Roof_Red_Vertical",
      "rotation": 3
    },
    {
      "x": -7,
      "y": 0,
      "z": 5,
      "name": "Soil_Grass"
    },
    {
      "x": -7,
      "y": 2,
      "z": 5,
      "name": "Cloth_Roof_White_Vertical",
      "rotation": 3
    },
    {
      "x": -7,
      "y": 3,
      "z": 5,
      "name": "Cloth_Roof_White_Vertical",
      "rotation": 3
    },
    {
      "x": -7,
      "y": 4,
      "z": 5,
      "name": "Cloth_Roof_White_Vertical",
      "rotation": 3
    },
    {
      "x": -7,
      "y": 7,
      "z": 5,
      "name": "Soil_Clay_Smooth_White"
    },
    {
      "x": -7,
      "y": 8,
      "z": 5,
      "name": "Cloth_Roof_Red_Vertical",
      "rotation": 3
    },
    {
      "x": -7,
      "y": 9,
      "z": 5,
      "name": "Cloth_Roof_Red_Vertical",
      "rotation": 3
    },
    {
      "x": -7,
      "y": 0,
      "z": 6,
      "name": "Soil_Grass"
    },
    {
      "x": -7,
      "y": 2,
      "z": 6,
      "name": "Cloth_Roof_White_Vertical",
      "rotation": 3
    },
    {
      "x": -7,
      "y": 3,
      "z": 6,
      "name": "Cloth_Roof_White_Vertical",
      "rotation": 3
    },
    {
      "x": -7,
      "y": 4,
      "z": 6,
      "name": "Cloth_Roof_White_Vertical",
      "rotation": 3
    },
    {
      "x": -7,
      "y": 7,
      "z": 6,
      "name": "Soil_Clay_Smooth_White"
    },
    {
      "x": -7,
      "y": 8,
      "z": 6,
      "name": "Cloth_Roof_Red_Vertical",
      "rotation": 3
    },
    {
      "x": -7,
      "y": 9,
      "z": 6,
      "name": "Cloth_Roof_Red_Vertical",
      "rotation": 3
    },
    {
      "x": -7,
      "y": 0,
      "z": 7,
      "name": "Soil_Grass"
    },
    {
      "x": -7,
      "y": 2,
      "z": 7,
      "name": "Cloth_Roof_White_Vertical",
      "rotation": 3
    },
    {
      "x": -7,
      "y": 3,
      "z": 7,
      "name": "Cloth_Roof_White_Vertical",
      "rotation": 3
    },
    {
      "x": -7,
      "y": 4,
      "z": 7,
      "name": "Cloth_Roof_White_Vertical",
      "rotation": 3
    },
    {
      "x": -7,
      "y": 7,
      "z": 7,
      "name": "Soil_Clay_Smooth_White"
    },
    {
      "x": -7,
      "y": 8,
      "z": 7,
      "name": "Cloth_Roof_Red_Vertical",
      "rotation": 3
    },
    {
      "x": -7,
      "y": 9,
      "z": 7,
      "name": "Cloth_Roof_Red_Vertical",
      "rotation": 3
    },
    {
      "x": -7,
      "y": 0,
      "z": 8,
      "name": "Soil_Grass"
    },
    {
      "x": -7,
      "y": 2,
      "z": 8,
      "name": "Cloth_Roof_White_Vertical",
      "rotation": 3
    },
    {
      "x": -7,
      "y": 3,
      "z": 8,
      "name": "Cloth_Roof_White_Vertical",
      "rotation": 3
    },
    {
      "x": -7,
      "y": 4,
      "z": 8,
      "name": "Cloth_Roof_White_Vertical",
      "rotation": 3
    },
    {
      "x": -7,
      "y": 7,
      "z": 8,
      "name": "Soil_Clay_Smooth_White"
    },
    {
      "x": -7,
      "y": 8,
      "z": 8,
      "name": "Cloth_Roof_Red_Vertical",
      "rotation": 3
    },
    {
      "x": -7,
      "y": 9,
      "z": 8,
      "name": "Cloth_Roof_Red_Vertical",
      "rotation": 3
    },
    {
      "x": -7,
      "y": 0,
      "z": 9,
      "name": "Soil_Grass"
    },
    {
      "x": -7,
      "y": 7,
      "z": 9,
      "name": "Cloth_Roof_White_Vertical",
      "rotation": 3
    },
    {
      "x": -7,
      "y": 0,
      "z": 10,
      "name": "Soil_Grass"
    },
    {
      "x": -6,
      "y": 0,
      "z": -10,
      "name": "Soil_Grass"
    },
    {
      "x": -6,
      "y": 7,
      "z": -10,
      "name": "Cloth_Roof_White_Vertical",
      "rotation": 3
    },
    {
      "x": -6,
      "y": 0,
      "z": -9,
      "name": "Rock_Stone",
      "rotation": 3
    },
    {
      "x": -6,
      "y": 2,
      "z": -9,
      "name": "Cloth_Roof_White_Vertical",
      "rotation": 3
    },
    {
      "x": -6,
      "y": 3,
      "z": -9,
      "name": "Cloth_Roof_White_Vertical",
      "rotation": 3
    },
    {
      "x": -6,
      "y": 4,
      "z": -9,
      "name": "Cloth_Roof_White_Vertical",
      "rotation": 3
    },
    {
      "x": -6,
      "y": 6,
      "z": -9,
      "name": "Cloth_Roof_White_Vertical",
      "rotation": 3
    },
    {
      "x": -6,
      "y": 7,
      "z": -9,
      "name": "Soil_Clay_Smooth_White"
    },
    {
      "x": -6,
      "y": 8,
      "z": -9,
      "name": "Cloth_Roof_Red_Vertical",
      "rotation": 2
    },
    {
      "x": -6,
      "y": 9,
      "z": -9,
      "name": "Cloth_Roof_Red_Vertical",
      "rotation": 2
    },
    {
      "x": -6,
      "y": 0,
      "z": -8,
      "name": "Cloth_Block_Wool_White"
    },
    {
      "x": -6,
      "y": 1,
      "z": -8,
      "name": "Soil_Clay_Smooth_Grey"
    },
    {
      "x": -6,
      "y": 2,
      "z": -8,
      "name": "Soil_Clay_Smooth_White"
    },
    {
      "x": -6,
      "y": 3,
      "z": -8,
      "name": "Soil_Clay_Smooth_White"
    },
    {
      "x": -6,
      "y": 4,
      "z": -8,
      "name": "Soil_Clay_Smooth_White"
    },
    {
      "x": -6,
      "y": 5,
      "z": -8,
      "name": "Soil_Clay_Smooth_Grey"
    },
    {
      "x": -6,
      "y": 6,
      "z": -8,
      "name": "Soil_Clay_Smooth_White"
    },
    {
      "x": -6,
      "y": 7,
      "z": -8,
      "name": "Soil_Clay_Smooth_White"
    },
    {
      "x": -6,
      "y": 8,
      "z": -8,
      "name": "Soil_Clay_Smooth_Red"
    },
    {
      "x": -6,
      "y": 9,
      "z": -8,
      "name": "Soil_Clay_Smooth_Red"
    },
    {
      "x": -6,
      "y": 0,
      "z": -7,
      "name": "Cloth_Block_Wool_White"
    },
    {
      "x": -6,
      "y": 1,
      "z": -7,
      "name": "Soil_Clay_Smooth_Grey"
    },
    {
      "x": -6,
      "y": 2,
      "z": -7,
      "name": "Soil_Clay_Smooth_White"
    },
    {
      "x": -6,
      "y": 3,
      "z": -7,
      "name": "Soil_Clay_Smooth_White"
    },
    {
      "x": -6,
      "y": 4,
      "z": -7,
      "name": "Soil_Clay_Smooth_White"
    },
    {
      "x": -6,
      "y": 5,
      "z": -7,
      "name": "Soil_Clay_Smooth_Grey"
    },
    {
      "x": -6,
      "y": 6,
      "z": -7,
      "name": "Furniture_Human_Ruins_Window",
      "rotation": 1
    },
    {
      "x": -6,
      "y": 7,
      "z": -7,
      "name": "Soil_Clay_Smooth_White"
    },
    {
      "x": -6,
      "y": 8,
      "z": -7,
      "name": "Soil_Clay_Smooth_Red"
    },
    {
      "x": -6,
      "y": 9,
      "z": -7,
      "name": "Soil_Clay_Smooth_Red"
    },
    {
      "x": -6,
      "y": 10,
      "z": -7,
      "name": "Cloth_Roof_Red_Vertical",
      "rotation": 3
    },
    {
      "x": -6,
      "y": 11,
      "z": -7,
      "name": "Cloth_Roof_Red_Vertical",
      "rotation": 3
    },
    {
      "x": -6,
      "y": 0,
      "z": -6,
      "name": "Cloth_Block_Wool_White"
    },
    {
      "x": -6,
      "y": 1,
      "z": -6,
      "name": "Soil_Clay_Smooth_Grey"
    },
    {
      "x": -6,
      "y": 2,
      "z": -6,
      "name": "Soil_Clay_Smooth_White"
    },
    {
      "x": -6,
      "y": 3,
      "z": -6,
      "name": "Soil_Clay_Smooth_White"
    },
    {
      "x": -6,
      "y": 4,
      "z": -6,
      "name": "Soil_Clay_Smooth_White"
    },
    {
      "x": -6,
      "y": 5,
      "z": -6,
      "name": "Soil_Clay_Smooth_Grey"
    },
    {
      "x": -6,
      "y": 6,
      "z": -6,
      "name": "Furniture_Human_Ruins_Window",
      "rotation": 1
    },
    {
      "x": -6,
      "y": 7,
      "z": -6,
      "name": "Soil_Clay_Smooth_White"
    },
    {
      "x": -6,
      "y": 8,
      "z": -6,
      "name": "Soil_Clay_Smooth_Red"
    },
    {
      "x": -6,
      "y": 9,
      "z": -6,
      "name": "Soil_Clay_Smooth_Red"
    },
    {
      "x": -6,
      "y": 10,
      "z": -6,
      "name": "Cloth_Roof_Red_Vertical",
      "rotation": 3
    },
    {
      "x": -6,
      "y": 11,
      "z": -6,
      "name": "Cloth_Roof_Red_Vertical",
      "rotation": 3
    },
    {
      "x": -6,
      "y": 0,
      "z": -5,
      "name": "Cloth_Block_Wool_White"
    },
    {
      "x": -6,
      "y": 1,
      "z": -5,
      "name": "Soil_Clay_Smooth_Grey"
    },
    {
      "x": -6,
      "y": 2,
      "z": -5,
      "name": "Soil_Clay_Smooth_White"
    },
    {
      "x": -6,
      "y": 3,
      "z": -5,
      "name": "Soil_Clay_Smooth_White"
    },
    {
      "x": -6,
      "y": 4,
      "z": -5,
      "name": "Soil_Clay_Smooth_White"
    },
    {
      "x": -6,
      "y": 5,
      "z": -5,
      "name": "Soil_Clay_Smooth_Grey"
    },
    {
      "x": -6,
      "y": 6,
      "z": -5,
      "name": "Furniture_Human_Ruins_Window",
      "rotation": 1
    },
    {
      "x": -6,
      "y": 7,
      "z": -5,
      "name": "Soil_Clay_Smooth_White"
    },
    {
      "x": -6,
      "y": 8,
      "z": -5,
      "name": "Soil_Clay_Smooth_Red"
    },
    {
      "x": -6,
      "y": 9,
      "z": -5,
      "name": "Soil_Clay_Smooth_Red"
    },
    {
      "x": -6,
      "y": 10,
      "z": -5,
      "name": "Cloth_Roof_Red_Vertical",
      "rotation": 3
    },
    {
      "x": -6,
      "y": 11,
      "z": -5,
      "name": "Cloth_Roof_Red_Vertical",
      "rotation": 3
    },
    {
      "x": -6,
      "y": 0,
      "z": -4,
      "name": "Cloth_Block_Wool_White"
    },
    {
      "x": -6,
      "y": 1,
      "z": -4,
      "name": "Soil_Clay_Smooth_Grey"
    },
    {
      "x": -6,
      "y": 2,
      "z": -4,
      "name": "Soil_Clay_Smooth_White"
    },
    {
      "x": -6,
      "y": 3,
      "z": -4,
      "name": "Soil_Clay_Smooth_White"
    },
    {
      "x": -6,
      "y": 4,
      "z": -4,
      "name": "Soil_Clay_Smooth_White"
    },
    {
      "x": -6,
      "y": 5,
      "z": -4,
      "name": "Soil_Clay_Smooth_Grey"
    },
    {
      "x": -6,
      "y": 6,
      "z": -4,
      "name": "Furniture_Human_Ruins_Window",
      "rotation": 1
    },
    {
      "x": -6,
      "y": 7,
      "z": -4,
      "name": "Soil_Clay_Smooth_White"
    },
    {
      "x": -6,
      "y": 8,
      "z": -4,
      "name": "Soil_Clay_Smooth_Red"
    },
    {
      "x": -6,
      "y": 9,
      "z": -4,
      "name": "Soil_Clay_Smooth_Red"
    },
    {
      "x": -6,
      "y": 10,
      "z": -4,
      "name": "Cloth_Roof_Red_Vertical",
      "rotation": 3
    },
    {
      "x": -6,
      "y": 11,
      "z": -4,
      "name": "Cloth_Roof_Red_Vertical",
      "rotation": 3
    },
    {
      "x": -6,
      "y": 0,
      "z": -3,
      "name": "Cloth_Block_Wool_White"
    },
    {
      "x": -6,
      "y": 1,
      "z": -3,
      "name": "Soil_Clay_Smooth_Grey"
    },
    {
      "x": -6,
      "y": 2,
      "z": -3,
      "name": "Soil_Clay_Smooth_White"
    },
    {
      "x": -6,
      "y": 3,
      "z": -3,
      "name": "Soil_Clay_Smooth_White"
    },
    {
      "x": -6,
      "y": 4,
      "z": -3,
      "name": "Soil_Clay_Smooth_White"
    },
    {
      "x": -6,
      "y": 5,
      "z": -3,
      "name": "Soil_Clay_Smooth_Grey"
    },
    {
      "x": -6,
      "y": 6,
      "z": -3,
      "name": "Furniture_Human_Ruins_Window",
      "rotation": 1
    },
    {
      "x": -6,
      "y": 7,
      "z": -3,
      "name": "Soil_Clay_Smooth_White"
    },
    {
      "x": -6,
      "y": 8,
      "z": -3,
      "name": "Soil_Clay_Smooth_Red"
    },
    {
      "x": -6,
      "y": 9,
      "z": -3,
      "name": "Soil_Clay_Smooth_Red"
    },
    {
      "x": -6,
      "y": 10,
      "z": -3,
      "name": "Cloth_Roof_Red_Vertical",
      "rotation": 3
    },
    {
      "x": -6,
      "y": 11,
      "z": -3,
      "name": "Cloth_Roof_Red_Vertical",
      "rotation": 3
    },
    {
      "x": -6,
      "y": 0,
      "z": -2,
      "name": "Cloth_Block_Wool_White"
    },
    {
      "x": -6,
      "y": 1,
      "z": -2,
      "name": "Soil_Clay_Smooth_Grey"
    },
    {
      "x": -6,
      "y": 2,
      "z": -2,
      "name": "Soil_Clay_Smooth_White"
    },
    {
      "x": -6,
      "y": 3,
      "z": -2,
      "name": "Soil_Clay_Smooth_White"
    },
    {
      "x": -6,
      "y": 4,
      "z": -2,
      "name": "Soil_Clay_Smooth_White"
    },
    {
      "x": -6,
      "y": 5,
      "z": -2,
      "name": "Soil_Clay_Smooth_Grey"
    },
    {
      "x": -6,
      "y": 6,
      "z": -2,
      "name": "Furniture_Human_Ruins_Window",
      "rotation": 1
    },
    {
      "x": -6,
      "y": 7,
      "z": -2,
      "name": "Soil_Clay_Smooth_White"
    },
    {
      "x": -6,
      "y": 8,
      "z": -2,
      "name": "Soil_Clay_Smooth_Red"
    },
    {
      "x": -6,
      "y": 9,
      "z": -2,
      "name": "Soil_Clay_Smooth_Red"
    },
    {
      "x": -6,
      "y": 10,
      "z": -2,
      "name": "Cloth_Roof_Red_Vertical",
      "rotation": 3
    },
    {
      "x": -6,
      "y": 11,
      "z": -2,
      "name": "Cloth_Roof_Red_Vertical",
      "rotation": 3
    },
    {
      "x": -6,
      "y": 0,
      "z": -1,
      "name": "Cloth_Block_Wool_White"
    },
    {
      "x": -6,
      "y": 1,
      "z": -1,
      "name": "Soil_Clay_Smooth_Grey"
    },
    {
      "x": -6,
      "y": 2,
      "z": -1,
      "name": "Soil_Clay_Smooth_White"
    },
    {
      "x": -6,
      "y": 3,
      "z": -1,
      "name": "Soil_Clay_Smooth_White"
    },
    {
      "x": -6,
      "y": 4,
      "z": -1,
      "name": "Soil_Clay_Smooth_White"
    },
    {
      "x": -6,
      "y": 5,
      "z": -1,
      "name": "Soil_Clay_Smooth_Grey"
    },
    {
      "x": -6,
      "y": 6,
      "z": -1,
      "name": "Furniture_Human_Ruins_Window",
      "rotation": 1
    },
    {
      "x": -6,
      "y": 7,
      "z": -1,
      "name": "Soil_Clay_Smooth_White"
    },
    {
      "x": -6,
      "y": 8,
      "z": -1,
      "name": "Soil_Clay_Smooth_Red"
    },
    {
      "x": -6,
      "y": 9,
      "z": -1,
      "name": "Soil_Clay_Smooth_Red"
    },
    {
      "x": -6,
      "y": 10,
      "z": -1,
      "name": "Cloth_Roof_Red_Vertical",
      "rotation": 3
    },
    {
      "x": -6,
      "y": 11,
      "z": -1,
      "name": "Cloth_Roof_Red_Vertical",
      "rotation": 3
    },
    {
      "x": -6,
      "y": 0,
      "z": 0,
      "name": "Cloth_Block_Wool_White"
    },
    {
      "x": -6,
      "y": 1,
      "z": 0,
      "name": "Soil_Clay_Smooth_Grey"
    },
    {
      "x": -6,
      "y": 2,
      "z": 0,
      "name": "Soil_Clay_Smooth_White"
    },
    {
      "x": -6,
      "y": 3,
      "z": 0,
      "name": "Soil_Clay_Smooth_White"
    },
    {
      "x": -6,
      "y": 4,
      "z": 0,
      "name": "Soil_Clay_Smooth_White"
    },
    {
      "x": -6,
      "y": 5,
      "z": 0,
      "name": "Soil_Clay_Smooth_Grey"
    },
    {
      "x": -6,
      "y": 6,
      "z": 0,
      "name": "Furniture_Human_Ruins_Window",
      "rotation": 1
    },
    {
      "x": -6,
      "y": 7,
      "z": 0,
      "name": "Soil_Clay_Smooth_White"
    },
    {
      "x": -6,
      "y": 8,
      "z": 0,
      "name": "Soil_Clay_Smooth_Red"
    },
    {
      "x": -6,
      "y": 9,
      "z": 0,
      "name": "Soil_Clay_Smooth_Red"
    },
    {
      "x": -6,
      "y": 10,
      "z": 0,
      "name": "Cloth_Roof_Red_Vertical",
      "rotation": 3
    },
    {
      "x": -6,
      "y": 11,
      "z": 0,
      "name": "Cloth_Roof_Red_Vertical",
      "rotation": 3
    },
    {
      "x": -6,
      "y": 0,
      "z": 1,
      "name": "Cloth_Block_Wool_White"
    },
    {
      "x": -6,
      "y": 1,
      "z": 1,
      "name": "Soil_Clay_Smooth_Grey"
    },
    {
      "x": -6,
      "y": 2,
      "z": 1,
      "name": "Soil_Clay_Smooth_White"
    },
    {
      "x": -6,
      "y": 3,
      "z": 1,
      "name": "Soil_Clay_Smooth_White"
    },
    {
      "x": -6,
      "y": 4,
      "z": 1,
      "name": "Soil_Clay_Smooth_White"
    },
    {
      "x": -6,
      "y": 5,
      "z": 1,
      "name": "Soil_Clay_Smooth_Grey"
    },
    {
      "x": -6,
      "y": 6,
      "z": 1,
      "name": "Furniture_Human_Ruins_Window",
      "rotation": 1
    },
    {
      "x": -6,
      "y": 7,
      "z": 1,
      "name": "Soil_Clay_Smooth_White"
    },
    {
      "x": -6,
      "y": 8,
      "z": 1,
      "name": "Soil_Clay_Smooth_Red"
    },
    {
      "x": -6,
      "y": 9,
      "z": 1,
      "name": "Soil_Clay_Smooth_Red"
    },
    {
      "x": -6,
      "y": 10,
      "z": 1,
      "name": "Cloth_Roof_Red_Vertical",
      "rotation": 3
    },
    {
      "x": -6,
      "y": 11,
      "z": 1,
      "name": "Cloth_Roof_Red_Vertical",
      "rotation": 3
    },
    {
      "x": -6,
      "y": 0,
      "z": 2,
      "name": "Cloth_Block_Wool_White"
    },
    {
      "x": -6,
      "y": 1,
      "z": 2,
      "name": "Soil_Clay_Smooth_Grey"
    },
    {
      "x": -6,
      "y": 2,
      "z": 2,
      "name": "Soil_Clay_Smooth_White"
    },
    {
      "x": -6,
      "y": 3,
      "z": 2,
      "name": "Soil_Clay_Smooth_White"
    },
    {
      "x": -6,
      "y": 4,
      "z": 2,
      "name": "Soil_Clay_Smooth_White"
    },
    {
      "x": -6,
      "y": 5,
      "z": 2,
      "name": "Soil_Clay_Smooth_Grey"
    },
    {
      "x": -6,
      "y": 6,
      "z": 2,
      "name": "Furniture_Human_Ruins_Window",
      "rotation": 1
    },
    {
      "x": -6,
      "y": 7,
      "z": 2,
      "name": "Soil_Clay_Smooth_White"
    },
    {
      "x": -6,
      "y": 8,
      "z": 2,
      "name": "Soil_Clay_Smooth_Red"
    },
    {
      "x": -6,
      "y": 9,
      "z": 2,
      "name": "Soil_Clay_Smooth_Red"
    },
    {
      "x": -6,
      "y": 10,
      "z": 2,
      "name": "Cloth_Roof_Red_Vertical",
      "rotation": 3
    },
    {
      "x": -6,
      "y": 11,
      "z": 2,
      "name": "Cloth_Roof_Red_Vertical",
      "rotation": 3
    },
    {
      "x": -6,
      "y": 0,
      "z": 3,
      "name": "Cloth_Block_Wool_White"
    },
    {
      "x": -6,
      "y": 1,
      "z": 3,
      "name": "Soil_Clay_Smooth_Grey"
    },
    {
      "x": -6,
      "y": 2,
      "z": 3,
      "name": "Soil_Clay_Smooth_White"
    },
    {
      "x": -6,
      "y": 3,
      "z": 3,
      "name": "Soil_Clay_Smooth_White"
    },
    {
      "x": -6,
      "y": 4,
      "z": 3,
      "name": "Soil_Clay_Smooth_White"
    },
    {
      "x": -6,
      "y": 5,
      "z": 3,
      "name": "Soil_Clay_Smooth_Grey"
    },
    {
      "x": -6,
      "y": 6,
      "z": 3,
      "name": "Furniture_Human_Ruins_Window",
      "rotation": 1
    },
    {
      "x": -6,
      "y": 7,
      "z": 3,
      "name": "Soil_Clay_Smooth_White"
    },
    {
      "x": -6,
      "y": 8,
      "z": 3,
      "name": "Soil_Clay_Smooth_Red"
    },
    {
      "x": -6,
      "y": 9,
      "z": 3,
      "name": "Soil_Clay_Smooth_Red"
    },
    {
      "x": -6,
      "y": 10,
      "z": 3,
      "name": "Cloth_Roof_Red_Vertical",
      "rotation": 3
    },
    {
      "x": -6,
      "y": 11,
      "z": 3,
      "name": "Cloth_Roof_Red_Vertical",
      "rotation": 3
    },
    {
      "x": -6,
      "y": 0,
      "z": 4,
      "name": "Cloth_Block_Wool_White"
    },
    {
      "x": -6,
      "y": 1,
      "z": 4,
      "name": "Soil_Clay_Smooth_Grey"
    },
    {
      "x": -6,
      "y": 2,
      "z": 4,
      "name": "Soil_Clay_Smooth_White"
    },
    {
      "x": -6,
      "y": 3,
      "z": 4,
      "name": "Soil_Clay_Smooth_White"
    },
    {
      "x": -6,
      "y": 4,
      "z": 4,
      "name": "Soil_Clay_Smooth_White"
    },
    {
      "x": -6,
      "y": 5,
      "z": 4,
      "name": "Soil_Clay_Smooth_Grey"
    },
    {
      "x": -6,
      "y": 6,
      "z": 4,
      "name": "Furniture_Human_Ruins_Window",
      "rotation": 1
    },
    {
      "x": -6,
      "y": 7,
      "z": 4,
      "name": "Soil_Clay_Smooth_White"
    },
    {
      "x": -6,
      "y": 8,
      "z": 4,
      "name": "Soil_Clay_Smooth_Red"
    },
    {
      "x": -6,
      "y": 9,
      "z": 4,
      "name": "Soil_Clay_Smooth_Red"
    },
    {
      "x": -6,
      "y": 10,
      "z": 4,
      "name": "Cloth_Roof_Red_Vertical",
      "rotation": 3
    },
    {
      "x": -6,
      "y": 11,
      "z": 4,
      "name": "Cloth_Roof_Red_Vertical",
      "rotation": 3
    },
    {
      "x": -6,
      "y": 0,
      "z": 5,
      "name": "Cloth_Block_Wool_White"
    },
    {
      "x": -6,
      "y": 1,
      "z": 5,
      "name": "Soil_Clay_Smooth_Grey"
    },
    {
      "x": -6,
      "y": 2,
      "z": 5,
      "name": "Soil_Clay_Smooth_White"
    },
    {
      "x": -6,
      "y": 3,
      "z": 5,
      "name": "Soil_Clay_Smooth_White"
    },
    {
      "x": -6,
      "y": 4,
      "z": 5,
      "name": "Soil_Clay_Smooth_White"
    },
    {
      "x": -6,
      "y": 5,
      "z": 5,
      "name": "Soil_Clay_Smooth_Grey"
    },
    {
      "x": -6,
      "y": 6,
      "z": 5,
      "name": "Furniture_Human_Ruins_Window",
      "rotation": 1
    },
    {
      "x": -6,
      "y": 7,
      "z": 5,
      "name": "Soil_Clay_Smooth_White"
    },
    {
      "x": -6,
      "y": 8,
      "z": 5,
      "name": "Soil_Clay_Smooth_Red"
    },
    {
      "x": -6,
      "y": 9,
      "z": 5,
      "name": "Soil_Clay_Smooth_Red"
    },
    {
      "x": -6,
      "y": 10,
      "z": 5,
      "name": "Cloth_Roof_Red_Vertical",
      "rotation": 3
    },
    {
      "x": -6,
      "y": 11,
      "z": 5,
      "name": "Cloth_Roof_Red_Vertical",
      "rotation": 3
    },
    {
      "x": -6,
      "y": 0,
      "z": 6,
      "name": "Cloth_Block_Wool_White"
    },
    {
      "x": -6,
      "y": 1,
      "z": 6,
      "name": "Soil_Clay_Smooth_Grey"
    },
    {
      "x": -6,
      "y": 2,
      "z": 6,
      "name": "Soil_Clay_Smooth_White"
    },
    {
      "x": -6,
      "y": 3,
      "z": 6,
      "name": "Soil_Clay_Smooth_White"
    },
    {
      "x": -6,
      "y": 4,
      "z": 6,
      "name": "Soil_Clay_Smooth_White"
    },
    {
      "x": -6,
      "y": 5,
      "z": 6,
      "name": "Soil_Clay_Smooth_Grey"
    },
    {
      "x": -6,
      "y": 6,
      "z": 6,
      "name": "Furniture_Human_Ruins_Window",
      "rotation": 1
    },
    {
      "x": -6,
      "y": 7,
      "z": 6,
      "name": "Soil_Clay_Smooth_White"
    },
    {
      "x": -6,
      "y": 8,
      "z": 6,
      "name": "Soil_Clay_Smooth_Red"
    },
    {
      "x": -6,
      "y": 9,
      "z": 6,
      "name": "Soil_Clay_Smooth_Red"
    },
    {
      "x": -6,
      "y": 10,
      "z": 6,
      "name": "Cloth_Roof_Red_Vertical",
      "rotation": 3
    },
    {
      "x": -6,
      "y": 11,
      "z": 6,
      "name": "Cloth_Roof_Red_Vertical",
      "rotation": 3
    },
    {
      "x": -6,
      "y": 0,
      "z": 7,
      "name": "Cloth_Block_Wool_White"
    },
    {
      "x": -6,
      "y": 1,
      "z": 7,
      "name": "Soil_Clay_Smooth_Grey"
    },
    {
      "x": -6,
      "y": 2,
      "z": 7,
      "name": "Soil_Clay_Smooth_White"
    },
    {
      "x": -6,
      "y": 3,
      "z": 7,
      "name": "Soil_Clay_Smooth_White"
    },
    {
      "x": -6,
      "y": 4,
      "z": 7,
      "name": "Soil_Clay_Smooth_White"
    },
    {
      "x": -6,
      "y": 5,
      "z": 7,
      "name": "Soil_Clay_Smooth_Grey"
    },
    {
      "x": -6,
      "y": 6,
      "z": 7,
      "name": "Furniture_Human_Ruins_Window",
      "rotation": 1
    },
    {
      "x": -6,
      "y": 7,
      "z": 7,
      "name": "Soil_Clay_Smooth_White"
    },
    {
      "x": -6,
      "y": 8,
      "z": 7,
      "name": "Soil_Clay_Smooth_Red"
    },
    {
      "x": -6,
      "y": 9,
      "z": 7,
      "name": "Soil_Clay_Smooth_Red"
    },
    {
      "x": -6,
      "y": 10,
      "z": 7,
      "name": "Cloth_Roof_Red_Vertical",
      "rotation": 3
    },
    {
      "x": -6,
      "y": 11,
      "z": 7,
      "name": "Cloth_Roof_Red_Vertical",
      "rotation": 3
    },
    {
      "x": -6,
      "y": 0,
      "z": 8,
      "name": "Cloth_Block_Wool_White"
    },
    {
      "x": -6,
      "y": 1,
      "z": 8,
      "name": "Soil_Clay_Smooth_Grey"
    },
    {
      "x": -6,
      "y": 2,
      "z": 8,
      "name": "Soil_Clay_Smooth_White"
    },
    {
      "x": -6,
      "y": 3,
      "z": 8,
      "name": "Soil_Clay_Smooth_White"
    },
    {
      "x": -6,
      "y": 4,
      "z": 8,
      "name": "Soil_Clay_Smooth_White"
    },
    {
      "x": -6,
      "y": 5,
      "z": 8,
      "name": "Soil_Clay_Smooth_Grey"
    },
    {
      "x": -6,
      "y": 6,
      "z": 8,
      "name": "Soil_Clay_Smooth_White"
    },
    {
      "x": -6,
      "y": 7,
      "z": 8,
      "name": "Soil_Clay_Smooth_White"
    },
    {
      "x": -6,
      "y": 8,
      "z": 8,
      "name": "Soil_Clay_Smooth_Red"
    },
    {
      "x": -6,
      "y": 9,
      "z": 8,
      "name": "Soil_Clay_Smooth_Red"
    },
    {
      "x": -6,
      "y": 0,
      "z": 9,
      "name": "Soil_Grass_Full"
    },
    {
      "x": -6,
      "y": 2,
      "z": 9,
      "name": "Cloth_Roof_White_Vertical",
      "rotation": 3
    },
    {
      "x": -6,
      "y": 3,
      "z": 9,
      "name": "Cloth_Roof_White_Vertical",
      "rotation": 3
    },
    {
      "x": -6,
      "y": 4,
      "z": 9,
      "name": "Cloth_Roof_White_Vertical",
      "rotation": 3
    },
    {
      "x": -6,
      "y": 6,
      "z": 9,
      "name": "Cloth_Roof_White_Vertical",
      "rotation": 3
    },
    {
      "x": -6,
      "y": 7,
      "z": 9,
      "name": "Soil_Clay_Smooth_White"
    },
    {
      "x": -6,
      "y": 8,
      "z": 9,
      "name": "Cloth_Roof_Red_Vertical"
    },
    {
      "x": -6,
      "y": 9,
      "z": 9,
      "name": "Cloth_Roof_Red_Vertical"
    },
    {
      "x": -6,
      "y": 0,
      "z": 10,
      "name": "Soil_Grass"
    },
    {
      "x": -6,
      "y": 7,
      "z": 10,
      "name": "Cloth_Roof_White_Vertical",
      "rotation": 3
    },
    {
      "x": -5,
      "y": 0,
      "z": -10,
      "name": "Soil_Grass"
    },
    {
      "x": -5,
      "y": 2,
      "z": -10,
      "name": "Cloth_Roof_White_Vertical",
      "rotation": 2
    },
    {
      "x": -5,
      "y": 3,
      "z": -10,
      "name": "Cloth_Roof_White_Vertical",
      "rotation": 2
    },
    {
      "x": -5,
      "y": 4,
      "z": -10,
      "name": "Cloth_Roof_White_Vertical",
      "rotation": 2
    },
    {
      "x": -5,
      "y": 6,
      "z": -10,
      "name": "Cloth_Roof_White_Vertical",
      "rotation": 2
    },
    {
      "x": -5,
      "y": 7,
      "z": -10,
      "name": "Soil_Clay_Smooth_White"
    },
    {
      "x": -5,
      "y": 8,
      "z": -10,
      "name": "Cloth_Roof_Red_Vertical",
      "rotation": 2
    },
    {
      "x": -5,
      "y": 9,
      "z": -10,
      "name": "Cloth_Roof_Red_Vertical",
      "rotation": 2
    },
    {
      "x": -5,
      "y": 0,
      "z": -9,
      "name": "Cloth_Block_Wool_White"
    },
    {
      "x": -5,
      "y": 1,
      "z": -9,
      "name": "Soil_Clay_Smooth_Grey"
    },
    {
      "x": -5,
      "y": 2,
      "z": -9,
      "name": "Soil_Clay_Smooth_White"
    },
    {
      "x": -5,
      "y": 3,
      "z": -9,
      "name": "Soil_Clay_Smooth_White"
    },
    {
      "x": -5,
      "y": 4,
      "z": -9,
      "name": "Soil_Clay_Smooth_White"
    },
    {
      "x": -5,
      "y": 5,
      "z": -9,
      "name": "Soil_Clay_Smooth_Grey"
    },
    {
      "x": -5,
      "y": 6,
      "z": -9,
      "name": "Soil_Clay_Smooth_White"
    },
    {
      "x": -5,
      "y": 7,
      "z": -9,
      "name": "Soil_Clay_Smooth_White"
    },
    {
      "x": -5,
      "y": 8,
      "z": -9,
      "name": "Soil_Clay_Smooth_Red"
    },
    {
      "x": -5,
      "y": 9,
      "z": -9,
      "name": "Soil_Clay_Smooth_Red"
    },
    {
      "x": -5,
      "y": 0,
      "z": -8,
      "name": "Prototype_Rock_Concrete_Brick"
    },
    {
      "x": -5,
      "y": 1,
      "z": -8,
      "name": "Soil_Clay_Smooth_Grey"
    },
    {
      "x": -5,
      "y": 2,
      "z": -8,
      "name": "Soil_Clay_Smooth_White"
    },
    {
      "x": -5,
      "y": 3,
      "z": -8,
      "name": "Soil_Clay_Smooth_White"
    },
    {
      "x": -5,
      "y": 4,
      "z": -8,
      "name": "Soil_Clay_Smooth_White"
    },
    {
      "x": -5,
      "y": 5,
      "z": -8,
      "name": "Soil_Clay_Smooth_Grey"
    },
    {
      "x": -5,
      "y": 6,
      "z": -8,
      "name": "Soil_Clay_Smooth_White"
    },
    {
      "x": -5,
      "y": 7,
      "z": -8,
      "name": "Soil_Clay_Smooth_White"
    },
    {
      "x": -5,
      "y": 8,
      "z": -8,
      "name": "Soil_Clay_Smooth_Red"
    },
    {
      "x": -5,
      "y": 9,
      "z": -8,
      "name": "Soil_Clay_Smooth_Red"
    },
    {
      "x": -5,
      "y": 10,
      "z": -8,
      "name": "Cloth_Roof_Red_Vertical",
      "rotation": 2
    },
    {
      "x": -5,
      "y": 11,
      "z": -8,
      "name": "Cloth_Roof_Red_Vertical",
      "rotation": 2
    },
    {
      "x": -5,
      "y": 0,
      "z": -7,
      "name": "Prototype_Rock_Concrete_Brick"
    },
    {
      "x": -5,
      "y": 1,
      "z": -7,
      "name": "Furniture_Temple_Dark_Candle"
    },
    {
      "x": -5,
      "y": 2,
      "z": -7,
      "name": "Furniture_Temple_Dark_Candle",
      "filler": 1024
    },
    {
      "x": -5,
      "y": 10,
      "z": -7,
      "name": "Soil_Clay_Smooth_Red"
    },
    {
      "x": -5,
      "y": 11,
      "z": -7,
      "name": "Soil_Clay_Smooth_Red"
    },
    {
      "x": -5,
      "y": 0,
      "z": -6,
      "name": "Prototype_Rock_Concrete_Brick"
    },
    {
      "x": -5,
      "y": 10,
      "z": -6,
      "name": "Soil_Clay_Smooth_Red"
    },
    {
      "x": -5,
      "y": 11,
      "z": -6,
      "name": "Soil_Clay_Smooth_Red"
    },
    {
      "x": -5,
      "y": 0,
      "z": -5,
      "name": "Prototype_Rock_Concrete_Brick"
    },
    {
      "x": -5,
      "y": 10,
      "z": -5,
      "name": "Soil_Clay_Smooth_Red"
    },
    {
      "x": -5,
      "y": 11,
      "z": -5,
      "name": "Soil_Clay_Smooth_Red"
    },
    {
      "x": -5,
      "y": 0,
      "z": -4,
      "name": "Prototype_Rock_Concrete_Brick"
    },
    {
      "x": -5,
      "y": 10,
      "z": -4,
      "name": "Soil_Clay_Smooth_Red"
    },
    {
      "x": -5,
      "y": 11,
      "z": -4,
      "name": "Soil_Clay_Smooth_Red"
    },
    {
      "x": -5,
      "y": 0,
      "z": -3,
      "name": "Prototype_Rock_Concrete_Brick"
    },
    {
      "x": -5,
      "y": 1,
      "z": -3,
      "name": "Wood_Hardwood_Fence_Gate",
      "rotation": 2
    },
    {
      "x": -5,
      "y": 10,
      "z": -3,
      "name": "Soil_Clay_Smooth_Red"
    },
    {
      "x": -5,
      "y": 11,
      "z": -3,
      "name": "Soil_Clay_Smooth_Red"
    },
    {
      "x": -5,
      "y": 0,
      "z": -2,
      "name": "Prototype_Rock_Concrete_Brick"
    },
    {
      "x": -5,
      "y": 10,
      "z": -2,
      "name": "Soil_Clay_Smooth_Red"
    },
    {
      "x": -5,
      "y": 11,
      "z": -2,
      "name": "Soil_Clay_Smooth_Red"
    },
    {
      "x": -5,
      "y": 0,
      "z": -1,
      "name": "Prototype_Rock_Concrete_Brick"
    },
    {
      "x": -5,
      "y": 10,
      "z": -1,
      "name": "Soil_Clay_Smooth_Red"
    },
    {
      "x": -5,
      "y": 11,
      "z": -1,
      "name": "Soil_Clay_Smooth_Red"
    },
    {
      "x": -5,
      "y": 0,
      "z": 0,
      "name": "Prototype_Rock_Concrete_Brick"
    },
    {
      "x": -5,
      "y": 10,
      "z": 0,
      "name": "Soil_Clay_Smooth_Red"
    },
    {
      "x": -5,
      "y": 11,
      "z": 0,
      "name": "Soil_Clay_Smooth_Red"
    },
    {
      "x": -5,
      "y": 0,
      "z": 1,
      "name": "Prototype_Rock_Concrete_Brick"
    },
    {
      "x": -5,
      "y": 10,
      "z": 1,
      "name": "Soil_Clay_Smooth_Red"
    },
    {
      "x": -5,
      "y": 11,
      "z": 1,
      "name": "Soil_Clay_Smooth_Red"
    },
    {
      "x": -5,
      "y": 0,
      "z": 2,
      "name": "Prototype_Rock_Concrete_Brick"
    },
    {
      "x": -5,
      "y": 10,
      "z": 2,
      "name": "Soil_Clay_Smooth_Red"
    },
    {
      "x": -5,
      "y": 11,
      "z": 2,
      "name": "Soil_Clay_Smooth_Red"
    },
    {
      "x": -5,
      "y": 0,
      "z": 3,
      "name": "Prototype_Rock_Concrete_Brick"
    },
    {
      "x": -5,
      "y": 1,
      "z": 3,
      "name": "Wood_Hardwood_Fence_Gate",
      "rotation": 2
    },
    {
      "x": -5,
      "y": 10,
      "z": 3,
      "name": "Soil_Clay_Smooth_Red"
    },
    {
      "x": -5,
      "y": 11,
      "z": 3,
      "name": "Soil_Clay_Smooth_Red"
    },
    {
      "x": -5,
      "y": 0,
      "z": 4,
      "name": "Prototype_Rock_Concrete_Brick"
    },
    {
      "x": -5,
      "y": 10,
      "z": 4,
      "name": "Soil_Clay_Smooth_Red"
    },
    {
      "x": -5,
      "y": 11,
      "z": 4,
      "name": "Soil_Clay_Smooth_Red"
    },
    {
      "x": -5,
      "y": 0,
      "z": 5,
      "name": "Prototype_Rock_Concrete_Brick"
    },
    {
      "x": -5,
      "y": 10,
      "z": 5,
      "name": "Soil_Clay_Smooth_Red"
    },
    {
      "x": -5,
      "y": 11,
      "z": 5,
      "name": "Soil_Clay_Smooth_Red"
    },
    {
      "x": -5,
      "y": 0,
      "z": 6,
      "name": "Prototype_Rock_Concrete_Brick"
    },
    {
      "x": -5,
      "y": 10,
      "z": 6,
      "name": "Soil_Clay_Smooth_Red"
    },
    {
      "x": -5,
      "y": 11,
      "z": 6,
      "name": "Soil_Clay_Smooth_Red"
    },
    {
      "x": -5,
      "y": 0,
      "z": 7,
      "name": "Prototype_Rock_Concrete_Brick"
    },
    {
      "x": -5,
      "y": 1,
      "z": 7,
      "name": "Furniture_Temple_Dark_Candle"
    },
    {
      "x": -5,
      "y": 2,
      "z": 7,
      "name": "Furniture_Temple_Dark_Candle",
      "filler": 1024
    },
    {
      "x": -5,
      "y": 10,
      "z": 7,
      "name": "Soil_Clay_Smooth_Red"
    },
    {
      "x": -5,
      "y": 11,
      "z": 7,
      "name": "Soil_Clay_Smooth_Red"
    },
    {
      "x": -5,
      "y": 0,
      "z": 8,
      "name": "Prototype_Rock_Concrete_Brick"
    },
    {
      "x": -5,
      "y": 1,
      "z": 8,
      "name": "Soil_Clay_Smooth_Grey"
    },
    {
      "x": -5,
      "y": 2,
      "z": 8,
      "name": "Soil_Clay_Smooth_White"
    },
    {
      "x": -5,
      "y": 3,
      "z": 8,
      "name": "Soil_Clay_Smooth_White"
    },
    {
      "x": -5,
      "y": 4,
      "z": 8,
      "name": "Soil_Clay_Smooth_White"
    },
    {
      "x": -5,
      "y": 5,
      "z": 8,
      "name": "Soil_Clay_Smooth_Grey"
    },
    {
      "x": -5,
      "y": 6,
      "z": 8,
      "name": "Soil_Clay_Smooth_White"
    },
    {
      "x": -5,
      "y": 7,
      "z": 8,
      "name": "Soil_Clay_Smooth_White"
    },
    {
      "x": -5,
      "y": 8,
      "z": 8,
      "name": "Soil_Clay_Smooth_Red"
    },
    {
      "x": -5,
      "y": 9,
      "z": 8,
      "name": "Soil_Clay_Smooth_Red"
    },
    {
      "x": -5,
      "y": 10,
      "z": 8,
      "name": "Cloth_Roof_Red_Vertical"
    },
    {
      "x": -5,
      "y": 11,
      "z": 8,
      "name": "Cloth_Roof_Red_Vertical"
    },
    {
      "x": -5,
      "y": 0,
      "z": 9,
      "name": "Cloth_Block_Wool_White"
    },
    {
      "x": -5,
      "y": 1,
      "z": 9,
      "name": "Soil_Clay_Smooth_Grey"
    },
    {
      "x": -5,
      "y": 2,
      "z": 9,
      "name": "Soil_Clay_Smooth_White"
    },
    {
      "x": -5,
      "y": 3,
      "z": 9,
      "name": "Soil_Clay_Smooth_White"
    },
    {
      "x": -5,
      "y": 4,
      "z": 9,
      "name": "Soil_Clay_Smooth_White"
    },
    {
      "x": -5,
      "y": 5,
      "z": 9,
      "name": "Soil_Clay_Smooth_Grey"
    },
    {
      "x": -5,
      "y": 6,
      "z": 9,
      "name": "Soil_Clay_Smooth_White"
    },
    {
      "x": -5,
      "y": 7,
      "z": 9,
      "name": "Soil_Clay_Smooth_White"
    },
    {
      "x": -5,
      "y": 8,
      "z": 9,
      "name": "Soil_Clay_Smooth_Red"
    },
    {
      "x": -5,
      "y": 9,
      "z": 9,
      "name": "Soil_Clay_Smooth_Red"
    },
    {
      "x": -5,
      "y": 0,
      "z": 10,
      "name": "Soil_Grass"
    },
    {
      "x": -5,
      "y": 2,
      "z": 10,
      "name": "Cloth_Roof_White_Vertical"
    },
    {
      "x": -5,
      "y": 3,
      "z": 10,
      "name": "Cloth_Roof_White_Vertical"
    },
    {
      "x": -5,
      "y": 4,
      "z": 10,
      "name": "Cloth_Roof_White_Vertical"
    },
    {
      "x": -5,
      "y": 6,
      "z": 10,
      "name": "Cloth_Roof_White_Vertical"
    },
    {
      "x": -5,
      "y": 7,
      "z": 10,
      "name": "Soil_Clay_Smooth_White"
    },
    {
      "x": -5,
      "y": 8,
      "z": 10,
      "name": "Cloth_Roof_Red_Vertical"
    },
    {
      "x": -5,
      "y": 9,
      "z": 10,
      "name": "Cloth_Roof_Red_Vertical"
    },
    {
      "x": -4,
      "y": 0,
      "z": -10,
      "name": "Soil_Grass"
    },
    {
      "x": -4,
      "y": 2,
      "z": -10,
      "name": "Cloth_Roof_White_Vertical",
      "rotation": 2
    },
    {
      "x": -4,
      "y": 3,
      "z": -10,
      "name": "Cloth_Roof_White_Vertical",
      "rotation": 2
    },
    {
      "x": -4,
      "y": 4,
      "z": -10,
      "name": "Cloth_Roof_White_Vertical",
      "rotation": 2
    },
    {
      "x": -4,
      "y": 7,
      "z": -10,
      "name": "Soil_Clay_Smooth_White"
    },
    {
      "x": -4,
      "y": 8,
      "z": -10,
      "name": "Cloth_Roof_Red_Vertical",
      "rotation": 2
    },
    {
      "x": -4,
      "y": 9,
      "z": -10,
      "name": "Cloth_Roof_Red_Vertical",
      "rotation": 2
    },
    {
      "x": -4,
      "y": 0,
      "z": -9,
      "name": "Cloth_Block_Wool_White"
    },
    {
      "x": -4,
      "y": 1,
      "z": -9,
      "name": "Soil_Clay_Smooth_Grey"
    },
    {
      "x": -4,
      "y": 2,
      "z": -9,
      "name": "Soil_Clay_Smooth_White"
    },
    {
      "x": -4,
      "y": 3,
      "z": -9,
      "name": "Soil_Clay_Smooth_White"
    },
    {
      "x": -4,
      "y": 4,
      "z": -9,
      "name": "Soil_Clay_Smooth_White"
    },
    {
      "x": -4,
      "y": 5,
      "z": -9,
      "name": "Soil_Clay_Smooth_Grey"
    },
    {
      "x": -4,
      "y": 6,
      "z": -9,
      "name": "Furniture_Human_Ruins_Window"
    },
    {
      "x": -4,
      "y": 7,
      "z": -9,
      "name": "Soil_Clay_Smooth_White"
    },
    {
      "x": -4,
      "y": 8,
      "z": -9,
      "name": "Soil_Clay_Smooth_Red"
    },
    {
      "x": -4,
      "y": 9,
      "z": -9,
      "name": "Soil_Clay_Smooth_Red"
    },
    {
      "x": -4,
      "y": 10,
      "z": -9,
      "name": "Cloth_Roof_Red_Vertical",
      "rotation": 2
    },
    {
      "x": -4,
      "y": 11,
      "z": -9,
      "name": "Cloth_Roof_Red_Vertical",
      "rotation": 2
    },
    {
      "x": -4,
      "y": 0,
      "z": -8,
      "name": "Prototype_Rock_Concrete_Brick"
    },
    {
      "x": -4,
      "y": 1,
      "z": -8,
      "name": "Furniture_Human_Ruins_Planter"
    },
    {
      "x": -4,
      "y": 2,
      "z": -8,
      "name": "Plant_Leaves_Oak",
      "support": 15
    },
    {
      "x": -4,
      "y": 10,
      "z": -8,
      "name": "Soil_Clay_Smooth_Red"
    },
    {
      "x": -4,
      "y": 11,
      "z": -8,
      "name": "Soil_Clay_Smooth_Red"
    },
    {
      "x": -4,
      "y": 0,
      "z": -7,
      "name": "Prototype_Rock_Concrete_Brick"
    },
    {
      "x": -4,
      "y": 10,
      "z": -7,
      "name": "Soil_Clay_Smooth_Red"
    },
    {
      "x": -4,
      "y": 11,
      "z": -7,
      "name": "Soil_Clay_Smooth_Red"
    },
    {
      "x": -4,
      "y": 0,
      "z": -6,
      "name": "Prototype_Rock_Concrete_Brick"
    },
    {
      "x": -4,
      "y": 10,
      "z": -6,
      "name": "Soil_Clay_Smooth_Red"
    },
    {
      "x": -4,
      "y": 11,
      "z": -6,
      "name": "Soil_Clay_Smooth_Red"
    },
    {
      "x": -4,
      "y": 0,
      "z": -5,
      "name": "Prototype_Rock_Concrete_Brick"
    },
    {
      "x": -4,
      "y": 10,
      "z": -5,
      "name": "Soil_Clay_Smooth_Red"
    },
    {
      "x": -4,
      "y": 11,
      "z": -5,
      "name": "Soil_Clay_Smooth_Red"
    },
    {
      "x": -4,
      "y": 0,
      "z": -4,
      "name": "Prototype_Rock_Concrete_Brick"
    },
    {
      "x": -4,
      "y": 10,
      "z": -4,
      "name": "Soil_Clay_Smooth_Red"
    },
    {
      "x": -4,
      "y": 11,
      "z": -4,
      "name": "Soil_Clay_Smooth_Red"
    },
    {
      "x": -4,
      "y": 0,
      "z": -3,
      "name": "Prototype_Rock_Concrete_Brick"
    },
    {
      "x": -4,
      "y": 1,
      "z": -3,
      "name": "Furniture_Village_Counter",
      "filler": 31
    },
    {
      "x": -4,
      "y": 10,
      "z": -3,
      "name": "Soil_Clay_Smooth_Red"
    },
    {
      "x": -4,
      "y": 11,
      "z": -3,
      "name": "Soil_Clay_Smooth_Red"
    },
    {
      "x": -4,
      "y": 0,
      "z": -2,
      "name": "Prototype_Rock_Concrete_Brick"
    },
    {
      "x": -4,
      "y": 10,
      "z": -2,
      "name": "Soil_Clay_Smooth_Red"
    },
    {
      "x": -4,
      "y": 11,
      "z": -2,
      "name": "Soil_Clay_Smooth_Red"
    },
    {
      "x": -4,
      "y": 0,
      "z": -1,
      "name": "Prototype_Rock_Concrete_Brick"
    },
    {
      "x": -4,
      "y": 10,
      "z": -1,
      "name": "Soil_Clay_Smooth_Red"
    },
    {
      "x": -4,
      "y": 11,
      "z": -1,
      "name": "Soil_Clay_Smooth_Red"
    },
    {
      "x": -4,
      "y": 0,
      "z": 0,
      "name": "Prototype_Rock_Concrete_Brick"
    },
    {
      "x": -4,
      "y": 10,
      "z": 0,
      "name": "Soil_Clay_Smooth_Red"
    },
    {
      "x": -4,
      "y": 11,
      "z": 0,
      "name": "Soil_Clay_Smooth_Red"
    },
    {
      "x": -4,
      "y": 0,
      "z": 1,
      "name": "Prototype_Rock_Concrete_Brick"
    },
    {
      "x": -4,
      "y": 10,
      "z": 1,
      "name": "Soil_Clay_Smooth_Red"
    },
    {
      "x": -4,
      "y": 11,
      "z": 1,
      "name": "Soil_Clay_Smooth_Red"
    },
    {
      "x": -4,
      "y": 0,
      "z": 2,
      "name": "Prototype_Rock_Concrete_Brick"
    },
    {
      "x": -4,
      "y": 10,
      "z": 2,
      "name": "Soil_Clay_Smooth_Red"
    },
    {
      "x": -4,
      "y": 11,
      "z": 2,
      "name": "Soil_Clay_Smooth_Red"
    },
    {
      "x": -4,
      "y": 0,
      "z": 3,
      "name": "Prototype_Rock_Concrete_Brick"
    },
    {
      "x": -4,
      "y": 1,
      "z": 3,
      "name": "Furniture_Village_Counter",
      "rotation": 2
    },
    {
      "x": -4,
      "y": 10,
      "z": 3,
      "name": "Soil_Clay_Smooth_Red"
    },
    {
      "x": -4,
      "y": 11,
      "z": 3,
      "name": "Soil_Clay_Smooth_Red"
    },
    {
      "x": -4,
      "y": 0,
      "z": 4,
      "name": "Prototype_Rock_Concrete_Brick"
    },
    {
      "x": -4,
      "y": 10,
      "z": 4,
      "name": "Soil_Clay_Smooth_Red"
    },
    {
      "x": -4,
      "y": 11,
      "z": 4,
      "name": "Soil_Clay_Smooth_Red"
    },
    {
      "x": -4,
      "y": 0,
      "z": 5,
      "name": "Prototype_Rock_Concrete_Brick"
    },
    {
      "x": -4,
      "y": 10,
      "z": 5,
      "name": "Soil_Clay_Smooth_Red"
    },
    {
      "x": -4,
      "y": 11,
      "z": 5,
      "name": "Soil_Clay_Smooth_Red"
    },
    {
      "x": -4,
      "y": 0,
      "z": 6,
      "name": "Prototype_Rock_Concrete_Brick"
    },
    {
      "x": -4,
      "y": 10,
      "z": 6,
      "name": "Soil_Clay_Smooth_Red"
    },
    {
      "x": -4,
      "y": 11,
      "z": 6,
      "name": "Soil_Clay_Smooth_Red"
    },
    {
      "x": -4,
      "y": 0,
      "z": 7,
      "name": "Prototype_Rock_Concrete_Brick"
    },
    {
      "x": -4,
      "y": 10,
      "z": 7,
      "name": "Soil_Clay_Smooth_Red"
    },
    {
      "x": -4,
      "y": 11,
      "z": 7,
      "name": "Soil_Clay_Smooth_Red"
    },
    {
      "x": -4,
      "y": 0,
      "z": 8,
      "name": "Prototype_Rock_Concrete_Brick"
    },
    {
      "x": -4,
      "y": 1,
      "z": 8,
      "name": "Furniture_Human_Ruins_Planter"
    },
    {
      "x": -4,
      "y": 2,
      "z": 8,
      "name": "Plant_Leaves_Oak",
      "support": 15
    },
    {
      "x": -4,
      "y": 10,
      "z": 8,
      "name": "Soil_Clay_Smooth_Red"
    },
    {
      "x": -4,
      "y": 11,
      "z": 8,
      "name": "Soil_Clay_Smooth_Red"
    },
    {
      "x": -4,
      "y": 0,
      "z": 9,
      "name": "Cloth_Block_Wool_White"
    },
    {
      "x": -4,
      "y": 1,
      "z": 9,
      "name": "Soil_Clay_Smooth_Grey"
    },
    {
      "x": -4,
      "y": 2,
      "z": 9,
      "name": "Soil_Clay_Smooth_White"
    },
    {
      "x": -4,
      "y": 3,
      "z": 9,
      "name": "Soil_Clay_Smooth_White"
    },
    {
      "x": -4,
      "y": 4,
      "z": 9,
      "name": "Soil_Clay_Smooth_White"
    },
    {
      "x": -4,
      "y": 5,
      "z": 9,
      "name": "Soil_Clay_Smooth_Grey"
    },
    {
      "x": -4,
      "y": 6,
      "z": 9,
      "name": "Furniture_Human_Ruins_Window"
    },
    {
      "x": -4,
      "y": 7,
      "z": 9,
      "name": "Soil_Clay_Smooth_White"
    },
    {
      "x": -4,
      "y": 8,
      "z": 9,
      "name": "Soil_Clay_Smooth_Red"
    },
    {
      "x": -4,
      "y": 9,
      "z": 9,
      "name": "Soil_Clay_Smooth_Red"
    },
    {
      "x": -4,
      "y": 10,
      "z": 9,
      "name": "Cloth_Roof_Red_Vertical"
    },
    {
      "x": -4,
      "y": 11,
      "z": 9,
      "name": "Cloth_Roof_Red_Vertical"
    },
    {
      "x": -4,
      "y": 0,
      "z": 10,
      "name": "Soil_Grass"
    },
    {
      "x": -4,
      "y": 2,
      "z": 10,
      "name": "Cloth_Roof_White_Vertical"
    },
    {
      "x": -4,
      "y": 3,
      "z": 10,
      "name": "Cloth_Roof_White_Vertical"
    },
    {
      "x": -4,
      "y": 4,
      "z": 10,
      "name": "Cloth_Roof_White_Vertical"
    },
    {
      "x": -4,
      "y": 7,
      "z": 10,
      "name": "Soil_Clay_Smooth_White"
    },
    {
      "x": -4,
      "y": 8,
      "z": 10,
      "name": "Cloth_Roof_Red_Vertical"
    },
    {
      "x": -4,
      "y": 9,
      "z": 10,
      "name": "Cloth_Roof_Red_Vertical"
    },
    {
      "x": -3,
      "y": 0,
      "z": -10,
      "name": "Soil_Grass"
    },
    {
      "x": -3,
      "y": 2,
      "z": -10,
      "name": "Cloth_Roof_White_Vertical",
      "rotation": 2
    },
    {
      "x": -3,
      "y": 3,
      "z": -10,
      "name": "Cloth_Roof_White_Vertical",
      "rotation": 2
    },
    {
      "x": -3,
      "y": 4,
      "z": -10,
      "name": "Cloth_Roof_White_Vertical",
      "rotation": 2
    },
    {
      "x": -3,
      "y": 7,
      "z": -10,
      "name": "Soil_Clay_Smooth_White"
    },
    {
      "x": -3,
      "y": 8,
      "z": -10,
      "name": "Cloth_Roof_Red_Vertical",
      "rotation": 2
    },
    {
      "x": -3,
      "y": 9,
      "z": -10,
      "name": "Cloth_Roof_Red_Vertical",
      "rotation": 2
    },
    {
      "x": -3,
      "y": 0,
      "z": -9,
      "name": "Cloth_Block_Wool_White"
    },
    {
      "x": -3,
      "y": 1,
      "z": -9,
      "name": "Soil_Clay_Smooth_Grey"
    },
    {
      "x": -3,
      "y": 2,
      "z": -9,
      "name": "Soil_Clay_Smooth_White"
    },
    {
      "x": -3,
      "y": 3,
      "z": -9,
      "name": "Soil_Clay_Smooth_White"
    },
    {
      "x": -3,
      "y": 4,
      "z": -9,
      "name": "Soil_Clay_Smooth_White"
    },
    {
      "x": -3,
      "y": 5,
      "z": -9,
      "name": "Soil_Clay_Smooth_Grey"
    },
    {
      "x": -3,
      "y": 6,
      "z": -9,
      "name": "Furniture_Human_Ruins_Window"
    },
    {
      "x": -3,
      "y": 7,
      "z": -9,
      "name": "Soil_Clay_Smooth_White"
    },
    {
      "x": -3,
      "y": 8,
      "z": -9,
      "name": "Soil_Clay_Smooth_Red"
    },
    {
      "x": -3,
      "y": 9,
      "z": -9,
      "name": "Soil_Clay_Smooth_Red"
    },
    {
      "x": -3,
      "y": 10,
      "z": -9,
      "name": "Cloth_Roof_Red_Vertical",
      "rotation": 2
    },
    {
      "x": -3,
      "y": 11,
      "z": -9,
      "name": "Cloth_Roof_Red_Vertical",
      "rotation": 2
    },
    {
      "x": -3,
      "y": 0,
      "z": -8,
      "name": "Prototype_Rock_Concrete_Brick"
    },
    {
      "x": -3,
      "y": 10,
      "z": -8,
      "name": "Soil_Clay_Smooth_Red"
    },
    {
      "x": -3,
      "y": 11,
      "z": -8,
      "name": "Soil_Clay_Smooth_Red"
    },
    {
      "x": -3,
      "y": 0,
      "z": -7,
      "name": "Prototype_Rock_Concrete_Brick"
    },
    {
      "x": -3,
      "y": 10,
      "z": -7,
      "name": "Soil_Clay_Smooth_Red"
    },
    {
      "x": -3,
      "y": 11,
      "z": -7,
      "name": "Soil_Clay_Smooth_Red"
    },
    {
      "x": -3,
      "y": 0,
      "z": -6,
      "name": "Prototype_Rock_Concrete_Brick"
    },
    {
      "x": -3,
      "y": 10,
      "z": -6,
      "name": "Soil_Clay_Smooth_Red"
    },
    {
      "x": -3,
      "y": 11,
      "z": -6,
      "name": "Soil_Clay_Smooth_Red"
    },
    {
      "x": -3,
      "y": 0,
      "z": -5,
      "name": "Prototype_Rock_Concrete_Brick"
    },
    {
      "x": -3,
      "y": 10,
      "z": -5,
      "name": "Soil_Clay_Smooth_Red"
    },
    {
      "x": -3,
      "y": 11,
      "z": -5,
      "name": "Soil_Clay_Smooth_Red"
    },
    {
      "x": -3,
      "y": 0,
      "z": -4,
      "name": "Prototype_Rock_Concrete_Brick"
    },
    {
      "x": -3,
      "y": 10,
      "z": -4,
      "name": "Soil_Clay_Smooth_Red"
    },
    {
      "x": -3,
      "y": 11,
      "z": -4,
      "name": "Soil_Clay_Smooth_Red"
    },
    {
      "x": -3,
      "y": 0,
      "z": -3,
      "name": "Prototype_Rock_Concrete_Brick"
    },
    {
      "x": -3,
      "y": 1,
      "z": -3,
      "name": "Furniture_Village_Counter"
    },
    {
      "x": -3,
      "y": 10,
      "z": -3,
      "name": "Soil_Clay_Smooth_Red"
    },
    {
      "x": -3,
      "y": 11,
      "z": -3,
      "name": "Soil_Clay_Smooth_Red"
    },
    {
      "x": -3,
      "y": 0,
      "z": -2,
      "name": "Prototype_Rock_Concrete_Brick"
    },
    {
      "x": -3,
      "y": 10,
      "z": -2,
      "name": "Soil_Clay_Smooth_Red"
    },
    {
      "x": -3,
      "y": 11,
      "z": -2,
      "name": "Soil_Clay_Smooth_Red"
    },
    {
      "x": -3,
      "y": 0,
      "z": -1,
      "name": "Prototype_Rock_Concrete_Brick"
    },
    {
      "x": -3,
      "y": 10,
      "z": -1,
      "name": "Soil_Clay_Smooth_Red"
    },
    {
      "x": -3,
      "y": 11,
      "z": -1,
      "name": "Soil_Clay_Smooth_Red"
    },
    {
      "x": -3,
      "y": 0,
      "z": 0,
      "name": "Prototype_Rock_Concrete_Brick"
    },
    {
      "x": -3,
      "y": 10,
      "z": 0,
      "name": "Soil_Clay_Smooth_Red"
    },
    {
      "x": -3,
      "y": 11,
      "z": 0,
      "name": "Soil_Clay_Smooth_Red"
    },
    {
      "x": -3,
      "y": 0,
      "z": 1,
      "name": "Prototype_Rock_Concrete_Brick"
    },
    {
      "x": -3,
      "y": 10,
      "z": 1,
      "name": "Soil_Clay_Smooth_Red"
    },
    {
      "x": -3,
      "y": 11,
      "z": 1,
      "name": "Soil_Clay_Smooth_Red"
    },
    {
      "x": -3,
      "y": 0,
      "z": 2,
      "name": "Prototype_Rock_Concrete_Brick"
    },
    {
      "x": -3,
      "y": 10,
      "z": 2,
      "name": "Soil_Clay_Smooth_Red"
    },
    {
      "x": -3,
      "y": 11,
      "z": 2,
      "name": "Soil_Clay_Smooth_Red"
    },
    {
      "x": -3,
      "y": 0,
      "z": 3,
      "name": "Prototype_Rock_Concrete_Brick"
    },
    {
      "x": -3,
      "y": 1,
      "z": 3,
      "name": "Furniture_Village_Counter",
      "filler": 1,
      "rotation": 2
    },
    {
      "x": -3,
      "y": 10,
      "z": 3,
      "name": "Soil_Clay_Smooth_Red"
    },
    {
      "x": -3,
      "y": 11,
      "z": 3,
      "name": "Soil_Clay_Smooth_Red"
    },
    {
      "x": -3,
      "y": 0,
      "z": 4,
      "name": "Prototype_Rock_Concrete_Brick"
    },
    {
      "x": -3,
      "y": 10,
      "z": 4,
      "name": "Soil_Clay_Smooth_Red"
    },
    {
      "x": -3,
      "y": 11,
      "z": 4,
      "name": "Soil_Clay_Smooth_Red"
    },
    {
      "x": -3,
      "y": 0,
      "z": 5,
      "name": "Prototype_Rock_Concrete_Brick"
    },
    {
      "x": -3,
      "y": 10,
      "z": 5,
      "name": "Soil_Clay_Smooth_Red"
    },
    {
      "x": -3,
      "y": 11,
      "z": 5,
      "name": "Soil_Clay_Smooth_Red"
    },
    {
      "x": -3,
      "y": 0,
      "z": 6,
      "name": "Prototype_Rock_Concrete_Brick"
    },
    {
      "x": -3,
      "y": 10,
      "z": 6,
      "name": "Soil_Clay_Smooth_Red"
    },
    {
      "x": -3,
      "y": 11,
      "z": 6,
      "name": "Soil_Clay_Smooth_Red"
    },
    {
      "x": -3,
      "y": 0,
      "z": 7,
      "name": "Prototype_Rock_Concrete_Brick"
    },
    {
      "x": -3,
      "y": 10,
      "z": 7,
      "name": "Soil_Clay_Smooth_Red"
    },
    {
      "x": -3,
      "y": 11,
      "z": 7,
      "name": "Soil_Clay_Smooth_Red"
    },
    {
      "x": -3,
      "y": 0,
      "z": 8,
      "name": "Prototype_Rock_Concrete_Brick"
    },
    {
      "x": -3,
      "y": 10,
      "z": 8,
      "name": "Soil_Clay_Smooth_Red"
    },
    {
      "x": -3,
      "y": 11,
      "z": 8,
      "name": "Soil_Clay_Smooth_Red"
    },
    {
      "x": -3,
      "y": 0,
      "z": 9,
      "name": "Cloth_Block_Wool_White"
    },
    {
      "x": -3,
      "y": 1,
      "z": 9,
      "name": "Soil_Clay_Smooth_Grey"
    },
    {
      "x": -3,
      "y": 2,
      "z": 9,
      "name": "Soil_Clay_Smooth_White"
    },
    {
      "x": -3,
      "y": 3,
      "z": 9,
      "name": "Soil_Clay_Smooth_White"
    },
    {
      "x": -3,
      "y": 4,
      "z": 9,
      "name": "Soil_Clay_Smooth_White"
    },
    {
      "x": -3,
      "y": 5,
      "z": 9,
      "name": "Soil_Clay_Smooth_Grey"
    },
    {
      "x": -3,
      "y": 6,
      "z": 9,
      "name": "Furniture_Human_Ruins_Window"
    },
    {
      "x": -3,
      "y": 7,
      "z": 9,
      "name": "Soil_Clay_Smooth_White"
    },
    {
      "x": -3,
      "y": 8,
      "z": 9,
      "name": "Soil_Clay_Smooth_Red"
    },
    {
      "x": -3,
      "y": 9,
      "z": 9,
      "name": "Soil_Clay_Smooth_Red"
    },
    {
      "x": -3,
      "y": 10,
      "z": 9,
      "name": "Cloth_Roof_Red_Vertical"
    },
    {
      "x": -3,
      "y": 11,
      "z": 9,
      "name": "Cloth_Roof_Red_Vertical"
    },
    {
      "x": -3,
      "y": 0,
      "z": 10,
      "name": "Soil_Grass"
    },
    {
      "x": -3,
      "y": 2,
      "z": 10,
      "name": "Cloth_Roof_White_Vertical"
    },
    {
      "x": -3,
      "y": 3,
      "z": 10,
      "name": "Cloth_Roof_White_Vertical"
    },
    {
      "x": -3,
      "y": 4,
      "z": 10,
      "name": "Cloth_Roof_White_Vertical"
    },
    {
      "x": -3,
      "y": 7,
      "z": 10,
      "name": "Soil_Clay_Smooth_White"
    },
    {
      "x": -3,
      "y": 8,
      "z": 10,
      "name": "Cloth_Roof_Red_Vertical"
    },
    {
      "x": -3,
      "y": 9,
      "z": 10,
      "name": "Cloth_Roof_Red_Vertical"
    },
    {
      "x": -2,
      "y": 0,
      "z": -10,
      "name": "Soil_Grass"
    },
    {
      "x": -2,
      "y": 2,
      "z": -10,
      "name": "Cloth_Roof_White_Vertical",
      "rotation": 2
    },
    {
      "x": -2,
      "y": 3,
      "z": -10,
      "name": "Cloth_Roof_White_Vertical",
      "rotation": 2
    },
    {
      "x": -2,
      "y": 4,
      "z": -10,
      "name": "Cloth_Roof_White_Vertical",
      "rotation": 2
    },
    {
      "x": -2,
      "y": 7,
      "z": -10,
      "name": "Soil_Clay_Smooth_White"
    },
    {
      "x": -2,
      "y": 8,
      "z": -10,
      "name": "Cloth_Roof_Red_Vertical",
      "rotation": 2
    },
    {
      "x": -2,
      "y": 9,
      "z": -10,
      "name": "Cloth_Roof_Red_Vertical",
      "rotation": 2
    },
    {
      "x": -2,
      "y": 0,
      "z": -9,
      "name": "Cloth_Block_Wool_White"
    },
    {
      "x": -2,
      "y": 1,
      "z": -9,
      "name": "Soil_Clay_Smooth_Grey"
    },
    {
      "x": -2,
      "y": 2,
      "z": -9,
      "name": "Soil_Clay_Smooth_White"
    },
    {
      "x": -2,
      "y": 3,
      "z": -9,
      "name": "Soil_Clay_Smooth_White"
    },
    {
      "x": -2,
      "y": 4,
      "z": -9,
      "name": "Soil_Clay_Smooth_White"
    },
    {
      "x": -2,
      "y": 5,
      "z": -9,
      "name": "Soil_Clay_Smooth_Grey"
    },
    {
      "x": -2,
      "y": 6,
      "z": -9,
      "name": "Furniture_Human_Ruins_Window"
    },
    {
      "x": -2,
      "y": 7,
      "z": -9,
      "name": "Soil_Clay_Smooth_White"
    },
    {
      "x": -2,
      "y": 8,
      "z": -9,
      "name": "Soil_Clay_Smooth_Red"
    },
    {
      "x": -2,
      "y": 9,
      "z": -9,
      "name": "Soil_Clay_Smooth_Red"
    },
    {
      "x": -2,
      "y": 10,
      "z": -9,
      "name": "Cloth_Roof_Red_Vertical",
      "rotation": 2
    },
    {
      "x": -2,
      "y": 11,
      "z": -9,
      "name": "Cloth_Roof_Red_Vertical",
      "rotation": 2
    },
    {
      "x": -2,
      "y": 0,
      "z": -8,
      "name": "Prototype_Rock_Concrete_Brick"
    },
    {
      "x": -2,
      "y": 10,
      "z": -8,
      "name": "Soil_Clay_Smooth_Red"
    },
    {
      "x": -2,
      "y": 11,
      "z": -8,
      "name": "Soil_Clay_Smooth_Red"
    },
    {
      "x": -2,
      "y": 0,
      "z": -7,
      "name": "Prototype_Rock_Concrete_Brick"
    },
    {
      "x": -2,
      "y": 10,
      "z": -7,
      "name": "Soil_Clay_Smooth_Red"
    },
    {
      "x": -2,
      "y": 11,
      "z": -7,
      "name": "Soil_Clay_Smooth_Red"
    },
    {
      "x": -2,
      "y": 0,
      "z": -6,
      "name": "Prototype_Rock_Concrete_Brick"
    },
    {
      "x": -2,
      "y": 10,
      "z": -6,
      "name": "Soil_Clay_Smooth_Red"
    },
    {
      "x": -2,
      "y": 11,
      "z": -6,
      "name": "Soil_Clay_Smooth_Red"
    },
    {
      "x": -2,
      "y": 0,
      "z": -5,
      "name": "Prototype_Rock_Concrete_Brick"
    },
    {
      "x": -2,
      "y": 10,
      "z": -5,
      "name": "Soil_Clay_Smooth_Red"
    },
    {
      "x": -2,
      "y": 11,
      "z": -5,
      "name": "Soil_Clay_Smooth_Red"
    },
    {
      "x": -2,
      "y": 0,
      "z": -4,
      "name": "Prototype_Rock_Concrete_Brick"
    },
    {
      "x": -2,
      "y": 10,
      "z": -4,
      "name": "Soil_Clay_Smooth_Red"
    },
    {
      "x": -2,
      "y": 11,
      "z": -4,
      "name": "Soil_Clay_Smooth_Red"
    },
    {
      "x": -2,
      "y": 0,
      "z": -3,
      "name": "Prototype_Rock_Concrete_Brick"
    },
    {
      "x": -2,
      "y": 1,
      "z": -3,
      "name": "Wood_Hardwood_Ornate"
    },
    {
      "x": -2,
      "y": 2,
      "z": -3,
      "name": "Deco_Lantern"
    },
    {
      "x": -2,
      "y": 10,
      "z": -3,
      "name": "Soil_Clay_Smooth_Red"
    },
    {
      "x": -2,
      "y": 11,
      "z": -3,
      "name": "Soil_Clay_Smooth_Red"
    },
    {
      "x": -2,
      "y": 0,
      "z": -2,
      "name": "Prototype_Rock_Concrete_Brick"
    },
    {
      "x": -2,
      "y": 1,
      "z": -2,
      "name": "Furniture_Village_Counter",
      "filler": 992,
      "rotation": 3
    },
    {
      "x": -2,
      "y": 10,
      "z": -2,
      "name": "Soil_Clay_Smooth_Red"
    },
    {
      "x": -2,
      "y": 11,
      "z": -2,
      "name": "Soil_Clay_Smooth_Red"
    },
    {
      "x": -2,
      "y": 0,
      "z": -1,
      "name": "Prototype_Rock_Concrete_Brick"
    },
    {
      "x": -2,
      "y": 1,
      "z": -1,
      "name": "Furniture_Village_Counter",
      "rotation": 3
    },
    {
      "x": -2,
      "y": 10,
      "z": -1,
      "name": "Soil_Clay_Smooth_Red"
    },
    {
      "x": -2,
      "y": 11,
      "z": -1,
      "name": "Soil_Clay_Smooth_Red"
    },
    {
      "x": -2,
      "y": 0,
      "z": 0,
      "name": "Prototype_Rock_Concrete_Brick"
    },
    {
      "x": -2,
      "y": 1,
      "z": 0,
      "name": "Wood_Hardwood_Ornate"
    },
    {
      "x": -2,
      "y": 10,
      "z": 0,
      "name": "Soil_Clay_Smooth_Red"
    },
    {
      "x": -2,
      "y": 11,
      "z": 0,
      "name": "Soil_Clay_Smooth_Red"
    },
    {
      "x": -2,
      "y": 0,
      "z": 1,
      "name": "Prototype_Rock_Concrete_Brick"
    },
    {
      "x": -2,
      "y": 1,
      "z": 1,
      "name": "Furniture_Village_Counter",
      "filler": 992,
      "rotation": 3
    },
    {
      "x": -2,
      "y": 10,
      "z": 1,
      "name": "Soil_Clay_Smooth_Red"
    },
    {
      "x": -2,
      "y": 11,
      "z": 1,
      "name": "Soil_Clay_Smooth_Red"
    },
    {
      "x": -2,
      "y": 0,
      "z": 2,
      "name": "Prototype_Rock_Concrete_Brick"
    },
    {
      "x": -2,
      "y": 1,
      "z": 2,
      "name": "Furniture_Village_Counter",
      "rotation": 3
    },
    {
      "x": -2,
      "y": 10,
      "z": 2,
      "name": "Soil_Clay_Smooth_Red"
    },
    {
      "x": -2,
      "y": 11,
      "z": 2,
      "name": "Soil_Clay_Smooth_Red"
    },
    {
      "x": -2,
      "y": 0,
      "z": 3,
      "name": "Prototype_Rock_Concrete_Brick"
    },
    {
      "x": -2,
      "y": 1,
      "z": 3,
      "name": "Wood_Hardwood_Ornate"
    },
    {
      "x": -2,
      "y": 2,
      "z": 3,
      "name": "Deco_Lantern"
    },
    {
      "x": -2,
      "y": 10,
      "z": 3,
      "name": "Soil_Clay_Smooth_Red"
    },
    {
      "x": -2,
      "y": 11,
      "z": 3,
      "name": "Soil_Clay_Smooth_Red"
    },
    {
      "x": -2,
      "y": 0,
      "z": 4,
      "name": "Prototype_Rock_Concrete_Brick"
    },
    {
      "x": -2,
      "y": 10,
      "z": 4,
      "name": "Soil_Clay_Smooth_Red"
    },
    {
      "x": -2,
      "y": 11,
      "z": 4,
      "name": "Soil_Clay_Smooth_Red"
    },
    {
      "x": -2,
      "y": 0,
      "z": 5,
      "name": "Prototype_Rock_Concrete_Brick"
    },
    {
      "x": -2,
      "y": 10,
      "z": 5,
      "name": "Soil_Clay_Smooth_Red"
    },
    {
      "x": -2,
      "y": 11,
      "z": 5,
      "name": "Soil_Clay_Smooth_Red"
    },
    {
      "x": -2,
      "y": 0,
      "z": 6,
      "name": "Prototype_Rock_Concrete_Brick"
    },
    {
      "x": -2,
      "y": 10,
      "z": 6,
      "name": "Soil_Clay_Smooth_Red"
    },
    {
      "x": -2,
      "y": 11,
      "z": 6,
      "name": "Soil_Clay_Smooth_Red"
    },
    {
      "x": -2,
      "y": 0,
      "z": 7,
      "name": "Prototype_Rock_Concrete_Brick"
    },
    {
      "x": -2,
      "y": 10,
      "z": 7,
      "name": "Soil_Clay_Smooth_Red"
    },
    {
      "x": -2,
      "y": 11,
      "z": 7,
      "name": "Soil_Clay_Smooth_Red"
    },
    {
      "x": -2,
      "y": 0,
      "z": 8,
      "name": "Prototype_Rock_Concrete_Brick"
    },
    {
      "x": -2,
      "y": 10,
      "z": 8,
      "name": "Soil_Clay_Smooth_Red"
    },
    {
      "x": -2,
      "y": 11,
      "z": 8,
      "name": "Soil_Clay_Smooth_Red"
    },
    {
      "x": -2,
      "y": 0,
      "z": 9,
      "name": "Cloth_Block_Wool_White"
    },
    {
      "x": -2,
      "y": 1,
      "z": 9,
      "name": "Soil_Clay_Smooth_Grey"
    },
    {
      "x": -2,
      "y": 2,
      "z": 9,
      "name": "Soil_Clay_Smooth_White"
    },
    {
      "x": -2,
      "y": 3,
      "z": 9,
      "name": "Soil_Clay_Smooth_White"
    },
    {
      "x": -2,
      "y": 4,
      "z": 9,
      "name": "Soil_Clay_Smooth_White"
    },
    {
      "x": -2,
      "y": 5,
      "z": 9,
      "name": "Soil_Clay_Smooth_Grey"
    },
    {
      "x": -2,
      "y": 6,
      "z": 9,
      "name": "Furniture_Human_Ruins_Window"
    },
    {
      "x": -2,
      "y": 7,
      "z": 9,
      "name": "Soil_Clay_Smooth_White"
    },
    {
      "x": -2,
      "y": 8,
      "z": 9,
      "name": "Soil_Clay_Smooth_Red"
    },
    {
      "x": -2,
      "y": 9,
      "z": 9,
      "name": "Soil_Clay_Smooth_Red"
    },
    {
      "x": -2,
      "y": 10,
      "z": 9,
      "name": "Cloth_Roof_Red_Vertical"
    },
    {
      "x": -2,
      "y": 11,
      "z": 9,
      "name": "Cloth_Roof_Red_Vertical"
    },
    {
      "x": -2,
      "y": 0,
      "z": 10,
      "name": "Soil_Grass"
    },
    {
      "x": -2,
      "y": 2,
      "z": 10,
      "name": "Cloth_Roof_White_Vertical"
    },
    {
      "x": -2,
      "y": 3,
      "z": 10,
      "name": "Cloth_Roof_White_Vertical"
    },
    {
      "x": -2,
      "y": 4,
      "z": 10,
      "name": "Cloth_Roof_White_Vertical"
    },
    {
      "x": -2,
      "y": 7,
      "z": 10,
      "name": "Soil_Clay_Smooth_White"
    },
    {
      "x": -2,
      "y": 8,
      "z": 10,
      "name": "Cloth_Roof_Red_Vertical"
    },
    {
      "x": -2,
      "y": 9,
      "z": 10,
      "name": "Cloth_Roof_Red_Vertical"
    },
    {
      "x": -1,
      "y": 0,
      "z": -10,
      "name": "Soil_Grass"
    },
    {
      "x": -1,
      "y": 2,
      "z": -10,
      "name": "Cloth_Roof_White_Vertical",
      "rotation": 2
    },
    {
      "x": -1,
      "y": 3,
      "z": -10,
      "name": "Cloth_Roof_White_Vertical",
      "rotation": 2
    },
    {
      "x": -1,
      "y": 4,
      "z": -10,
      "name": "Cloth_Roof_White_Vertical",
      "rotation": 2
    },
    {
      "x": -1,
      "y": 7,
      "z": -10,
      "name": "Soil_Clay_Smooth_White"
    },
    {
      "x": -1,
      "y": 8,
      "z": -10,
      "name": "Cloth_Roof_Red_Vertical",
      "rotation": 2
    },
    {
      "x": -1,
      "y": 9,
      "z": -10,
      "name": "Cloth_Roof_Red_Vertical",
      "rotation": 2
    },
    {
      "x": -1,
      "y": 0,
      "z": -9,
      "name": "Cloth_Block_Wool_White"
    },
    {
      "x": -1,
      "y": 1,
      "z": -9,
      "name": "Soil_Clay_Smooth_Grey"
    },
    {
      "x": -1,
      "y": 2,
      "z": -9,
      "name": "Soil_Clay_Smooth_White"
    },
    {
      "x": -1,
      "y": 3,
      "z": -9,
      "name": "Soil_Clay_Smooth_White"
    },
    {
      "x": -1,
      "y": 4,
      "z": -9,
      "name": "Soil_Clay_Smooth_White"
    },
    {
      "x": -1,
      "y": 5,
      "z": -9,
      "name": "Soil_Clay_Smooth_Grey"
    },
    {
      "x": -1,
      "y": 6,
      "z": -9,
      "name": "Furniture_Human_Ruins_Window"
    },
    {
      "x": -1,
      "y": 7,
      "z": -9,
      "name": "Soil_Clay_Smooth_White"
    },
    {
      "x": -1,
      "y": 8,
      "z": -9,
      "name": "Soil_Clay_Smooth_Red"
    },
    {
      "x": -1,
      "y": 9,
      "z": -9,
      "name": "Soil_Clay_Smooth_Red"
    },
    {
      "x": -1,
      "y": 10,
      "z": -9,
      "name": "Cloth_Roof_Red_Vertical",
      "rotation": 2
    },
    {
      "x": -1,
      "y": 11,
      "z": -9,
      "name": "Cloth_Roof_Red_Vertical",
      "rotation": 2
    },
    {
      "x": -1,
      "y": 0,
      "z": -8,
      "name": "Prototype_Rock_Concrete_Brick"
    },
    {
      "x": -1,
      "y": 10,
      "z": -8,
      "name": "Soil_Clay_Smooth_Red"
    },
    {
      "x": -1,
      "y": 11,
      "z": -8,
      "name": "Soil_Clay_Smooth_Red"
    },
    {
      "x": -1,
      "y": 0,
      "z": -7,
      "name": "Prototype_Rock_Concrete_Brick"
    },
    {
      "x": -1,
      "y": 10,
      "z": -7,
      "name": "Soil_Clay_Smooth_Red"
    },
    {
      "x": -1,
      "y": 11,
      "z": -7,
      "name": "Soil_Clay_Smooth_Red"
    },
    {
      "x": -1,
      "y": 0,
      "z": -6,
      "name": "Prototype_Rock_Concrete_Brick"
    },
    {
      "x": -1,
      "y": 10,
      "z": -6,
      "name": "Soil_Clay_Smooth_Red"
    },
    {
      "x": -1,
      "y": 11,
      "z": -6,
      "name": "Soil_Clay_Smooth_Red"
    },
    {
      "x": -1,
      "y": 0,
      "z": -5,
      "name": "Prototype_Rock_Concrete_Brick"
    },
    {
      "x": -1,
      "y": 10,
      "z": -5,
      "name": "Soil_Clay_Smooth_Red"
    },
    {
      "x": -1,
      "y": 11,
      "z": -5,
      "name": "Soil_Clay_Smooth_Red"
    },
    {
      "x": -1,
      "y": 0,
      "z": -4,
      "name": "Prototype_Rock_Concrete_Brick"
    },
    {
      "x": -1,
      "y": 10,
      "z": -4,
      "name": "Soil_Clay_Smooth_Red"
    },
    {
      "x": -1,
      "y": 11,
      "z": -4,
      "name": "Soil_Clay_Smooth_Red"
    },
    {
      "x": -1,
      "y": 0,
      "z": -3,
      "name": "Prototype_Rock_Concrete_Brick"
    },
    {
      "x": -1,
      "y": 10,
      "z": -3,
      "name": "Soil_Clay_Smooth_Red"
    },
    {
      "x": -1,
      "y": 11,
      "z": -3,
      "name": "Soil_Clay_Smooth_Red"
    },
    {
      "x": -1,
      "y": 0,
      "z": -2,
      "name": "Prototype_Rock_Concrete_Brick"
    },
    {
      "x": -1,
      "y": 10,
      "z": -2,
      "name": "Soil_Clay_Smooth_Red"
    },
    {
      "x": -1,
      "y": 11,
      "z": -2,
      "name": "Soil_Clay_Smooth_Red"
    },
    {
      "x": -1,
      "y": 0,
      "z": -1,
      "name": "Cloth_Block_Wool_Red"
    },
    {
      "x": -1,
      "y": 10,
      "z": -1,
      "name": "Soil_Clay_Smooth_Red"
    },
    {
      "x": -1,
      "y": 11,
      "z": -1,
      "name": "Soil_Clay_Smooth_Red"
    },
    {
      "x": -1,
      "y": 0,
      "z": 0,
      "name": "Cloth_Block_Wool_Red"
    },
    {
      "x": -1,
      "y": 10,
      "z": 0,
      "name": "Soil_Clay_Smooth_Red"
    },
    {
      "x": -1,
      "y": 11,
      "z": 0,
      "name": "Soil_Clay_Smooth_Red"
    },
    {
      "x": -1,
      "y": 0,
      "z": 1,
      "name": "Cloth_Block_Wool_Red"
    },
    {
      "x": -1,
      "y": 10,
      "z": 1,
      "name": "Soil_Clay_Smooth_Red"
    },
    {
      "x": -1,
      "y": 11,
      "z": 1,
      "name": "Soil_Clay_Smooth_Red"
    },
    {
      "x": -1,
      "y": 0,
      "z": 2,
      "name": "Prototype_Rock_Concrete_Brick"
    },
    {
      "x": -1,
      "y": 10,
      "z": 2,
      "name": "Soil_Clay_Smooth_Red"
    },
    {
      "x": -1,
      "y": 11,
      "z": 2,
      "name": "Soil_Clay_Smooth_Red"
    },
    {
      "x": -1,
      "y": 0,
      "z": 3,
      "name": "Prototype_Rock_Concrete_Brick"
    },
    {
      "x": -1,
      "y": 10,
      "z": 3,
      "name": "Soil_Clay_Smooth_Red"
    },
    {
      "x": -1,
      "y": 11,
      "z": 3,
      "name": "Soil_Clay_Smooth_Red"
    },
    {
      "x": -1,
      "y": 0,
      "z": 4,
      "name": "Prototype_Rock_Concrete_Brick"
    },
    {
      "x": -1,
      "y": 10,
      "z": 4,
      "name": "Soil_Clay_Smooth_Red"
    },
    {
      "x": -1,
      "y": 11,
      "z": 4,
      "name": "Soil_Clay_Smooth_Red"
    },
    {
      "x": -1,
      "y": 0,
      "z": 5,
      "name": "Prototype_Rock_Concrete_Brick"
    },
    {
      "x": -1,
      "y": 10,
      "z": 5,
      "name": "Soil_Clay_Smooth_Red"
    },
    {
      "x": -1,
      "y": 11,
      "z": 5,
      "name": "Soil_Clay_Smooth_Red"
    },
    {
      "x": -1,
      "y": 0,
      "z": 6,
      "name": "Prototype_Rock_Concrete_Brick"
    },
    {
      "x": -1,
      "y": 10,
      "z": 6,
      "name": "Soil_Clay_Smooth_Red"
    },
    {
      "x": -1,
      "y": 11,
      "z": 6,
      "name": "Soil_Clay_Smooth_Red"
    },
    {
      "x": -1,
      "y": 0,
      "z": 7,
      "name": "Prototype_Rock_Concrete_Brick"
    },
    {
      "x": -1,
      "y": 10,
      "z": 7,
      "name": "Soil_Clay_Smooth_Red"
    },
    {
      "x": -1,
      "y": 11,
      "z": 7,
      "name": "Soil_Clay_Smooth_Red"
    },
    {
      "x": -1,
      "y": 0,
      "z": 8,
      "name": "Prototype_Rock_Concrete_Brick"
    },
    {
      "x": -1,
      "y": 10,
      "z": 8,
      "name": "Soil_Clay_Smooth_Red"
    },
    {
      "x": -1,
      "y": 11,
      "z": 8,
      "name": "Soil_Clay_Smooth_Red"
    },
    {
      "x": -1,
      "y": 0,
      "z": 9,
      "name": "Cloth_Block_Wool_White"
    },
    {
      "x": -1,
      "y": 1,
      "z": 9,
      "name": "Soil_Clay_Smooth_Grey"
    },
    {
      "x": -1,
      "y": 2,
      "z": 9,
      "name": "Soil_Clay_Smooth_White"
    },
    {
      "x": -1,
      "y": 3,
      "z": 9,
      "name": "Soil_Clay_Smooth_White"
    },
    {
      "x": -1,
      "y": 4,
      "z": 9,
      "name": "Soil_Clay_Smooth_White"
    },
    {
      "x": -1,
      "y": 5,
      "z": 9,
      "name": "Soil_Clay_Smooth_Grey"
    },
    {
      "x": -1,
      "y": 6,
      "z": 9,
      "name": "Furniture_Human_Ruins_Window"
    },
    {
      "x": -1,
      "y": 7,
      "z": 9,
      "name": "Soil_Clay_Smooth_White"
    },
    {
      "x": -1,
      "y": 8,
      "z": 9,
      "name": "Soil_Clay_Smooth_Red"
    },
    {
      "x": -1,
      "y": 9,
      "z": 9,
      "name": "Soil_Clay_Smooth_Red"
    },
    {
      "x": -1,
      "y": 10,
      "z": 9,
      "name": "Cloth_Roof_Red_Vertical"
    },
    {
      "x": -1,
      "y": 11,
      "z": 9,
      "name": "Cloth_Roof_Red_Vertical"
    },
    {
      "x": -1,
      "y": 0,
      "z": 10,
      "name": "Soil_Grass"
    },
    {
      "x": -1,
      "y": 2,
      "z": 10,
      "name": "Cloth_Roof_White_Vertical"
    },
    {
      "x": -1,
      "y": 3,
      "z": 10,
      "name": "Cloth_Roof_White_Vertical"
    },
    {
      "x": -1,
      "y": 4,
      "z": 10,
      "name": "Cloth_Roof_White_Vertical"
    },
    {
      "x": -1,
      "y": 7,
      "z": 10,
      "name": "Soil_Clay_Smooth_White"
    },
    {
      "x": -1,
      "y": 8,
      "z": 10,
      "name": "Cloth_Roof_Red_Vertical"
    },
    {
      "x": -1,
      "y": 9,
      "z": 10,
      "name": "Cloth_Roof_Red_Vertical"
    },
    {
      "x": 0,
      "y": 0,
      "z": -10,
      "name": "Soil_Grass"
    },
    {
      "x": 0,
      "y": 2,
      "z": -10,
      "name": "Cloth_Roof_White_Vertical",
      "rotation": 2
    },
    {
      "x": 0,
      "y": 3,
      "z": -10,
      "name": "Cloth_Roof_White_Vertical",
      "rotation": 2
    },
    {
      "x": 0,
      "y": 4,
      "z": -10,
      "name": "Cloth_Roof_White_Vertical",
      "rotation": 2
    },
    {
      "x": 0,
      "y": 7,
      "z": -10,
      "name": "Soil_Clay_Smooth_White"
    },
    {
      "x": 0,
      "y": 8,
      "z": -10,
      "name": "Cloth_Roof_Red_Vertical",
      "rotation": 2
    },
    {
      "x": 0,
      "y": 9,
      "z": -10,
      "name": "Cloth_Roof_Red_Vertical",
      "rotation": 2
    },
    {
      "x": 0,
      "y": 0,
      "z": -9,
      "name": "Cloth_Block_Wool_White"
    },
    {
      "x": 0,
      "y": 1,
      "z": -9,
      "name": "Soil_Clay_Smooth_Grey"
    },
    {
      "x": 0,
      "y": 2,
      "z": -9,
      "name": "Soil_Clay_Smooth_White"
    },
    {
      "x": 0,
      "y": 3,
      "z": -9,
      "name": "Soil_Clay_Smooth_White"
    },
    {
      "x": 0,
      "y": 4,
      "z": -9,
      "name": "Soil_Clay_Smooth_White"
    },
    {
      "x": 0,
      "y": 5,
      "z": -9,
      "name": "Soil_Clay_Smooth_Grey"
    },
    {
      "x": 0,
      "y": 6,
      "z": -9,
      "name": "Furniture_Human_Ruins_Window"
    },
    {
      "x": 0,
      "y": 7,
      "z": -9,
      "name": "Soil_Clay_Smooth_White"
    },
    {
      "x": 0,
      "y": 8,
      "z": -9,
      "name": "Soil_Clay_Smooth_Red"
    },
    {
      "x": 0,
      "y": 9,
      "z": -9,
      "name": "Soil_Clay_Smooth_Red"
    },
    {
      "x": 0,
      "y": 10,
      "z": -9,
      "name": "Cloth_Roof_Red_Vertical",
      "rotation": 2
    },
    {
      "x": 0,
      "y": 11,
      "z": -9,
      "name": "Cloth_Roof_Red_Vertical",
      "rotation": 2
    },
    {
      "x": 0,
      "y": 0,
      "z": -8,
      "name": "Prototype_Rock_Concrete_Brick"
    },
    {
      "x": 0,
      "y": 10,
      "z": -8,
      "name": "Soil_Clay_Smooth_Red"
    },
    {
      "x": 0,
      "y": 11,
      "z": -8,
      "name": "Soil_Clay_Smooth_Red"
    },
    {
      "x": 0,
      "y": 0,
      "z": -7,
      "name": "Prototype_Rock_Concrete_Brick"
    },
    {
      "x": 0,
      "y": 10,
      "z": -7,
      "name": "Soil_Clay_Smooth_Red"
    },
    {
      "x": 0,
      "y": 11,
      "z": -7,
      "name": "Soil_Clay_Smooth_Red"
    },
    {
      "x": 0,
      "y": 0,
      "z": -6,
      "name": "Prototype_Rock_Concrete_Brick"
    },
    {
      "x": 0,
      "y": 10,
      "z": -6,
      "name": "Soil_Clay_Smooth_Red"
    },
    {
      "x": 0,
      "y": 11,
      "z": -6,
      "name": "Soil_Clay_Smooth_Red"
    },
    {
      "x": 0,
      "y": 0,
      "z": -5,
      "name": "Prototype_Rock_Concrete_Brick"
    },
    {
      "x": 0,
      "y": 10,
      "z": -5,
      "name": "Soil_Clay_Smooth_Red"
    },
    {
      "x": 0,
      "y": 11,
      "z": -5,
      "name": "Soil_Clay_Smooth_Red"
    },
    {
      "x": 0,
      "y": 0,
      "z": -4,
      "name": "Prototype_Rock_Concrete_Brick"
    },
    {
      "x": 0,
      "y": 10,
      "z": -4,
      "name": "Soil_Clay_Smooth_Red"
    },
    {
      "x": 0,
      "y": 11,
      "z": -4,
      "name": "Soil_Clay_Smooth_Red"
    },
    {
      "x": 0,
      "y": 0,
      "z": -3,
      "name": "Prototype_Rock_Concrete_Brick"
    },
    {
      "x": 0,
      "y": 10,
      "z": -3,
      "name": "Soil_Clay_Smooth_Red"
    },
    {
      "x": 0,
      "y": 11,
      "z": -3,
      "name": "Soil_Clay_Smooth_Red"
    },
    {
      "x": 0,
      "y": 0,
      "z": -2,
      "name": "Cloth_Block_Wool_Red"
    },
    {
      "x": 0,
      "y": 10,
      "z": -2,
      "name": "Soil_Clay_Smooth_Red"
    },
    {
      "x": 0,
      "y": 11,
      "z": -2,
      "name": "Soil_Clay_Smooth_Red"
    },
    {
      "x": 0,
      "y": 0,
      "z": -1,
      "name": "Cloth_Block_Wool_Red"
    },
    {
      "x": 0,
      "y": 10,
      "z": -1,
      "name": "Soil_Clay_Smooth_Red"
    },
    {
      "x": 0,
      "y": 11,
      "z": -1,
      "name": "Soil_Clay_Smooth_Red"
    },
    {
      "x": 0,
      "y": 0,
      "z": 0,
      "name": "Cloth_Block_Wool_Red"
    },
    {
      "x": 0,
      "y": 10,
      "z": 0,
      "name": "Soil_Clay_Smooth_Red"
    },
    {
      "x": 0,
      "y": 11,
      "z": 0,
      "name": "Soil_Clay_Smooth_Red"
    },
    {
      "x": 0,
      "y": 0,
      "z": 1,
      "name": "Cloth_Block_Wool_Red"
    },
    {
      "x": 0,
      "y": 10,
      "z": 1,
      "name": "Soil_Clay_Smooth_Red"
    },
    {
      "x": 0,
      "y": 11,
      "z": 1,
      "name": "Soil_Clay_Smooth_Red"
    },
    {
      "x": 0,
      "y": 0,
      "z": 2,
      "name": "Cloth_Block_Wool_Red"
    },
    {
      "x": 0,
      "y": 10,
      "z": 2,
      "name": "Soil_Clay_Smooth_Red"
    },
    {
      "x": 0,
      "y": 11,
      "z": 2,
      "name": "Soil_Clay_Smooth_Red"
    },
    {
      "x": 0,
      "y": 0,
      "z": 3,
      "name": "Prototype_Rock_Concrete_Brick"
    },
    {
      "x": 0,
      "y": 10,
      "z": 3,
      "name": "Soil_Clay_Smooth_Red"
    },
    {
      "x": 0,
      "y": 11,
      "z": 3,
      "name": "Soil_Clay_Smooth_Red"
    },
    {
      "x": 0,
      "y": 0,
      "z": 4,
      "name": "Prototype_Rock_Concrete_Brick"
    },
    {
      "x": 0,
      "y": 10,
      "z": 4,
      "name": "Soil_Clay_Smooth_Red"
    },
    {
      "x": 0,
      "y": 11,
      "z": 4,
      "name": "Soil_Clay_Smooth_Red"
    },
    {
      "x": 0,
      "y": 0,
      "z": 5,
      "name": "Prototype_Rock_Concrete_Brick"
    },
    {
      "x": 0,
      "y": 10,
      "z": 5,
      "name": "Soil_Clay_Smooth_Red"
    },
    {
      "x": 0,
      "y": 11,
      "z": 5,
      "name": "Soil_Clay_Smooth_Red"
    },
    {
      "x": 0,
      "y": 0,
      "z": 6,
      "name": "Prototype_Rock_Concrete_Brick"
    },
    {
      "x": 0,
      "y": 10,
      "z": 6,
      "name": "Soil_Clay_Smooth_Red"
    },
    {
      "x": 0,
      "y": 11,
      "z": 6,
      "name": "Soil_Clay_Smooth_Red"
    },
    {
      "x": 0,
      "y": 0,
      "z": 7,
      "name": "Prototype_Rock_Concrete_Brick"
    },
    {
      "x": 0,
      "y": 10,
      "z": 7,
      "name": "Soil_Clay_Smooth_Red"
    },
    {
      "x": 0,
      "y": 11,
      "z": 7,
      "name": "Soil_Clay_Smooth_Red"
    },
    {
      "x": 0,
      "y": 0,
      "z": 8,
      "name": "Prototype_Rock_Concrete_Brick"
    },
    {
      "x": 0,
      "y": 10,
      "z": 8,
      "name": "Soil_Clay_Smooth_Red"
    },
    {
      "x": 0,
      "y": 11,
      "z": 8,
      "name": "Soil_Clay_Smooth_Red"
    },
    {
      "x": 0,
      "y": 0,
      "z": 9,
      "name": "Cloth_Block_Wool_White"
    },
    {
      "x": 0,
      "y": 1,
      "z": 9,
      "name": "Soil_Clay_Smooth_Grey"
    },
    {
      "x": 0,
      "y": 2,
      "z": 9,
      "name": "Soil_Clay_Smooth_White"
    },
    {
      "x": 0,
      "y": 3,
      "z": 9,
      "name": "Soil_Clay_Smooth_White"
    },
    {
      "x": 0,
      "y": 4,
      "z": 9,
      "name": "Soil_Clay_Smooth_White"
    },
    {
      "x": 0,
      "y": 5,
      "z": 9,
      "name": "Soil_Clay_Smooth_Grey"
    },
    {
      "x": 0,
      "y": 6,
      "z": 9,
      "name": "Furniture_Human_Ruins_Window"
    },
    {
      "x": 0,
      "y": 7,
      "z": 9,
      "name": "Soil_Clay_Smooth_White"
    },
    {
      "x": 0,
      "y": 8,
      "z": 9,
      "name": "Soil_Clay_Smooth_Red"
    },
    {
      "x": 0,
      "y": 9,
      "z": 9,
      "name": "Soil_Clay_Smooth_Red"
    },
    {
      "x": 0,
      "y": 10,
      "z": 9,
      "name": "Cloth_Roof_Red_Vertical"
    },
    {
      "x": 0,
      "y": 11,
      "z": 9,
      "name": "Cloth_Roof_Red_Vertical"
    },
    {
      "x": 0,
      "y": 0,
      "z": 10,
      "name": "Soil_Grass"
    },
    {
      "x": 0,
      "y": 2,
      "z": 10,
      "name": "Cloth_Roof_White_Vertical"
    },
    {
      "x": 0,
      "y": 3,
      "z": 10,
      "name": "Cloth_Roof_White_Vertical"
    },
    {
      "x": 0,
      "y": 4,
      "z": 10,
      "name": "Cloth_Roof_White_Vertical"
    },
    {
      "x": 0,
      "y": 7,
      "z": 10,
      "name": "Soil_Clay_Smooth_White"
    },
    {
      "x": 0,
      "y": 8,
      "z": 10,
      "name": "Cloth_Roof_Red_Vertical"
    },
    {
      "x": 0,
      "y": 9,
      "z": 10,
      "name": "Cloth_Roof_Red_Vertical"
    },
    {
      "x": 1,
      "y": 0,
      "z": -10,
      "name": "Soil_Grass"
    },
    {
      "x": 1,
      "y": 2,
      "z": -10,
      "name": "Cloth_Roof_White_Vertical",
      "rotation": 2
    },
    {
      "x": 1,
      "y": 3,
      "z": -10,
      "name": "Cloth_Roof_White_Vertical",
      "rotation": 2
    },
    {
      "x": 1,
      "y": 4,
      "z": -10,
      "name": "Cloth_Roof_White_Vertical",
      "rotation": 2
    },
    {
      "x": 1,
      "y": 7,
      "z": -10,
      "name": "Soil_Clay_Smooth_White"
    },
    {
      "x": 1,
      "y": 8,
      "z": -10,
      "name": "Cloth_Roof_Red_Vertical",
      "rotation": 2
    },
    {
      "x": 1,
      "y": 9,
      "z": -10,
      "name": "Cloth_Roof_Red_Vertical",
      "rotation": 2
    },
    {
      "x": 1,
      "y": 0,
      "z": -9,
      "name": "Cloth_Block_Wool_White"
    },
    {
      "x": 1,
      "y": 1,
      "z": -9,
      "name": "Soil_Clay_Smooth_Grey"
    },
    {
      "x": 1,
      "y": 2,
      "z": -9,
      "name": "Soil_Clay_Smooth_White"
    },
    {
      "x": 1,
      "y": 3,
      "z": -9,
      "name": "Soil_Clay_Smooth_White"
    },
    {
      "x": 1,
      "y": 4,
      "z": -9,
      "name": "Soil_Clay_Smooth_White"
    },
    {
      "x": 1,
      "y": 5,
      "z": -9,
      "name": "Soil_Clay_Smooth_Grey"
    },
    {
      "x": 1,
      "y": 6,
      "z": -9,
      "name": "Furniture_Human_Ruins_Window"
    },
    {
      "x": 1,
      "y": 7,
      "z": -9,
      "name": "Soil_Clay_Smooth_White"
    },
    {
      "x": 1,
      "y": 8,
      "z": -9,
      "name": "Soil_Clay_Smooth_Red"
    },
    {
      "x": 1,
      "y": 9,
      "z": -9,
      "name": "Soil_Clay_Smooth_Red"
    },
    {
      "x": 1,
      "y": 10,
      "z": -9,
      "name": "Cloth_Roof_Red_Vertical",
      "rotation": 2
    },
    {
      "x": 1,
      "y": 11,
      "z": -9,
      "name": "Cloth_Roof_Red_Vertical",
      "rotation": 2
    },
    {
      "x": 1,
      "y": 0,
      "z": -8,
      "name": "Prototype_Rock_Concrete_Brick"
    },
    {
      "x": 1,
      "y": 10,
      "z": -8,
      "name": "Soil_Clay_Smooth_Red"
    },
    {
      "x": 1,
      "y": 11,
      "z": -8,
      "name": "Soil_Clay_Smooth_Red"
    },
    {
      "x": 1,
      "y": 0,
      "z": -7,
      "name": "Prototype_Rock_Concrete_Brick"
    },
    {
      "x": 1,
      "y": 10,
      "z": -7,
      "name": "Soil_Clay_Smooth_Red"
    },
    {
      "x": 1,
      "y": 11,
      "z": -7,
      "name": "Soil_Clay_Smooth_Red"
    },
    {
      "x": 1,
      "y": 0,
      "z": -6,
      "name": "Prototype_Rock_Concrete_Brick"
    },
    {
      "x": 1,
      "y": 10,
      "z": -6,
      "name": "Soil_Clay_Smooth_Red"
    },
    {
      "x": 1,
      "y": 11,
      "z": -6,
      "name": "Soil_Clay_Smooth_Red"
    },
    {
      "x": 1,
      "y": 0,
      "z": -5,
      "name": "Prototype_Rock_Concrete_Brick"
    },
    {
      "x": 1,
      "y": 10,
      "z": -5,
      "name": "Soil_Clay_Smooth_Red"
    },
    {
      "x": 1,
      "y": 11,
      "z": -5,
      "name": "Soil_Clay_Smooth_Red"
    },
    {
      "x": 1,
      "y": 0,
      "z": -4,
      "name": "Prototype_Rock_Concrete_Brick"
    },
    {
      "x": 1,
      "y": 10,
      "z": -4,
      "name": "Soil_Clay_Smooth_Red"
    },
    {
      "x": 1,
      "y": 11,
      "z": -4,
      "name": "Soil_Clay_Smooth_Red"
    },
    {
      "x": 1,
      "y": 0,
      "z": -3,
      "name": "Prototype_Rock_Concrete_Brick"
    },
    {
      "x": 1,
      "y": 10,
      "z": -3,
      "name": "Soil_Clay_Smooth_Red"
    },
    {
      "x": 1,
      "y": 11,
      "z": -3,
      "name": "Soil_Clay_Smooth_Red"
    },
    {
      "x": 1,
      "y": 0,
      "z": -2,
      "name": "Cloth_Block_Wool_Gray"
    },
    {
      "x": 1,
      "y": 10,
      "z": -2,
      "name": "Soil_Clay_Smooth_Red"
    },
    {
      "x": 1,
      "y": 11,
      "z": -2,
      "name": "Soil_Clay_Smooth_Red"
    },
    {
      "x": 1,
      "y": 0,
      "z": -1,
      "name": "Cloth_Block_Wool_Gray"
    },
    {
      "x": 1,
      "y": 10,
      "z": -1,
      "name": "Soil_Clay_Smooth_Red"
    },
    {
      "x": 1,
      "y": 11,
      "z": -1,
      "name": "Soil_Clay_Smooth_Red"
    },
    {
      "x": 1,
      "y": 0,
      "z": 0,
      "name": "Cloth_Block_Wool_Gray_Light"
    },
    {
      "x": 1,
      "y": 10,
      "z": 0,
      "name": "Soil_Clay_Smooth_Red"
    },
    {
      "x": 1,
      "y": 11,
      "z": 0,
      "name": "Soil_Clay_Smooth_Red"
    },
    {
      "x": 1,
      "y": 0,
      "z": 1,
      "name": "Cloth_Block_Wool_Gray"
    },
    {
      "x": 1,
      "y": 10,
      "z": 1,
      "name": "Soil_Clay_Smooth_Red"
    },
    {
      "x": 1,
      "y": 11,
      "z": 1,
      "name": "Soil_Clay_Smooth_Red"
    },
    {
      "x": 1,
      "y": 0,
      "z": 2,
      "name": "Cloth_Block_Wool_Gray"
    },
    {
      "x": 1,
      "y": 10,
      "z": 2,
      "name": "Soil_Clay_Smooth_Red"
    },
    {
      "x": 1,
      "y": 11,
      "z": 2,
      "name": "Soil_Clay_Smooth_Red"
    },
    {
      "x": 1,
      "y": 0,
      "z": 3,
      "name": "Prototype_Rock_Concrete_Brick"
    },
    {
      "x": 1,
      "y": 10,
      "z": 3,
      "name": "Soil_Clay_Smooth_Red"
    },
    {
      "x": 1,
      "y": 11,
      "z": 3,
      "name": "Soil_Clay_Smooth_Red"
    },
    {
      "x": 1,
      "y": 0,
      "z": 4,
      "name": "Prototype_Rock_Concrete_Brick"
    },
    {
      "x": 1,
      "y": 10,
      "z": 4,
      "name": "Soil_Clay_Smooth_Red"
    },
    {
      "x": 1,
      "y": 11,
      "z": 4,
      "name": "Soil_Clay_Smooth_Red"
    },
    {
      "x": 1,
      "y": 0,
      "z": 5,
      "name": "Prototype_Rock_Concrete_Brick"
    },
    {
      "x": 1,
      "y": 10,
      "z": 5,
      "name": "Soil_Clay_Smooth_Red"
    },
    {
      "x": 1,
      "y": 11,
      "z": 5,
      "name": "Soil_Clay_Smooth_Red"
    },
    {
      "x": 1,
      "y": 0,
      "z": 6,
      "name": "Prototype_Rock_Concrete_Brick"
    },
    {
      "x": 1,
      "y": 10,
      "z": 6,
      "name": "Soil_Clay_Smooth_Red"
    },
    {
      "x": 1,
      "y": 11,
      "z": 6,
      "name": "Soil_Clay_Smooth_Red"
    },
    {
      "x": 1,
      "y": 0,
      "z": 7,
      "name": "Prototype_Rock_Concrete_Brick"
    },
    {
      "x": 1,
      "y": 10,
      "z": 7,
      "name": "Soil_Clay_Smooth_Red"
    },
    {
      "x": 1,
      "y": 11,
      "z": 7,
      "name": "Soil_Clay_Smooth_Red"
    },
    {
      "x": 1,
      "y": 0,
      "z": 8,
      "name": "Prototype_Rock_Concrete_Brick"
    },
    {
      "x": 1,
      "y": 10,
      "z": 8,
      "name": "Soil_Clay_Smooth_Red"
    },
    {
      "x": 1,
      "y": 11,
      "z": 8,
      "name": "Soil_Clay_Smooth_Red"
    },
    {
      "x": 1,
      "y": 0,
      "z": 9,
      "name": "Cloth_Block_Wool_White"
    },
    {
      "x": 1,
      "y": 1,
      "z": 9,
      "name": "Soil_Clay_Smooth_Grey"
    },
    {
      "x": 1,
      "y": 2,
      "z": 9,
      "name": "Soil_Clay_Smooth_White"
    },
    {
      "x": 1,
      "y": 3,
      "z": 9,
      "name": "Soil_Clay_Smooth_White"
    },
    {
      "x": 1,
      "y": 4,
      "z": 9,
      "name": "Soil_Clay_Smooth_White"
    },
    {
      "x": 1,
      "y": 5,
      "z": 9,
