{
  "version": 8,
  "blockIdVersion": 10,
  "anchorX": 0,
  "anchorY": 0,
  "anchorZ": 0,
  "blocks": [
    {
      "x": -2,
      "y": 3,
      "z": 0,
      "name": "Plant_Crop_Apricorn_T1_Block_Wall",
      "components": {
        "Components": {
          "FarmingBlock": {}
        }
      },
      "rotation": 3
    },
    {
      "x": -1,
      "y": 2,
      "z": -1,
      "name": "Plant_Crop_Apricorn_T1_Block",
      "components": {
        "Components": {
          "FarmingBlock": {}
        }
      },
      "rotation": 3
    },
    {
      "x": -1,
      "y": 3,
      "z": -1,
      "name": "Plant_Leaves_Oak"
    },
    {
      "x": -1,
      "y": 2,
      "z": 0,
      "name": "Plant_Leaves_Oak"
    },
    {
      "x": -1,
      "y": 3,
      "z": 0,
      "name": "Plant_Leaves_Oak"
    },
    {
      "x": -1,
      "y": 4,
      "z": 0,
      "name": "Plant_Leaves_Oak"
    },
    {
      "x": -1,
      "y": 2,
      "z": 1,
      "name": "Plant_Crop_Apricorn_T1_Block",
      "components": {
        "Components": {
          "FarmingBlock": {}
        }
      },
      "rotation": 3
    },
    {
      "x": -1,
      "y": 3,
      "z": 1,
      "name": "Plant_Leaves_Oak"
    },
    {
      "x": 0,
      "y": 3,
      "z": -2,
      "name": "Plant_Crop_Apricorn_T1_Block_Wall",
      "components": {
        "Components": {
          "FarmingBlock": {}
        }
      },
      "rotation": 2
    },
    {
      "x": 0,
      "y": 2,
      "z": -1,
      "name": "Plant_Leaves_Oak"
    },
    {
      "x": 0,
      "y": 3,
      "z": -1,
      "name": "Plant_Leaves_Oak"
    },
    {
      "x": 0,
      "y": 4,
      "z": -1,
      "name": "Plant_Leaves_Oak"
    },
    {
      "x": 0,
      "y": 0,
      "z": 0,
      "name": "Wood_Oak_Branch_Long"
    },
    {
      "x": 0,
      "y": 1,
      "z": 0,
      "name": "Wood_Oak_Branch_Long"
    },
    {
      "x": 0,
      "y": 2,
      "z": 0,
      "name": "Wood_Oak_Branch_Long"
    },
    {
      "x": 0,
      "y": 3,
      "z": 0,
      "name": "Wood_Oak_Trunk"
    },
    {
      "x": 0,
      "y": 4,
      "z": 0,
      "name": "Plant_Leaves_Oak"
    },
    {
      "x": 0,
      "y": 5,
      "z": 0,
      "name": "Plant_Leaves_Oak"
    },
    {
      "x": 0,
      "y": 2,
      "z": 1,
      "name": "Plant_Leaves_Oak"
    },
    {
      "x": 0,
      "y": 3,
      "z": 1,
      "name": "Plant_Leaves_Oak"
    },
    {
      "x": 0,
      "y": 4,
      "z": 1,
      "name": "Plant_Leaves_Oak"
    },
    {
      "x": 0,
      "y": 3,
      "z": 2,
      "name": "Plant_Crop_Apricorn_T1_Block_Wall",
      "components": {
        "Components": {
          "FarmingBlock": {}
        }
      }
    },
    {
      "x": 1,
      "y": 2,
      "z": -1,
      "name": "Plant_Crop_Apricorn_T1_Block",
      "components": {
        "Components": {
          "FarmingBlock": {}
        }
      },
      "rotation": 1
    },
    {
      "x": 1,
      "y": 3,
      "z": -1,
      "name": "Plant_Leaves_Oak"
    },
    {
      "x": 1,
      "y": 2,
      "z": 0,
      "name": "Plant_Leaves_Oak"
    },
    {
      "x": 1,
      "y": 3,
      "z": 0,
      "name": "Plant_Leaves_Oak"
    },
    {
      "x": 1,
      "y": 4,
      "z": 0,
      "name": "Plant_Leaves_Oak"
    },
    {
      "x": 1,
      "y": 2,
      "z": 1,
      "name": "Plant_Crop_Apricorn_T1_Block",
      "components": {
        "Components": {
          "FarmingBlock": {}
        }
      }
    },
    {
      "x": 1,
      "y": 3,
      "z": 1,
      "name": "Plant_Leaves_Oak"
    },
    {
      "x": 2,
      "y": 3,
      "z": 0,
      "name": "Plant_Crop_Apricorn_T1_Block_Wall",
      "components": {
        "Components": {
          "FarmingBlock": {}
        }
      },
      "rotation": 1
    }
  ],
  "fluids": [
    {
      "x": -2,
      "y": 3,
      "z": 0,
      "name": "Empty",
      "level": 0
    },
    {
      "x": -1,
      "y": 2,
      "z": -1,
      "name": "Empty",
      "level": 0
    },
    {
      "x": -1,
      "y": 3,
      "z": -1,
      "name": "Empty",
      "level": 0
    },
    {
      "x": -1,
      "y": 2,
      "z": 0,
      "name": "Empty",
      "level": 0
    },
    {
      "x": -1,
      "y": 3,
      "z": 0,
      "name": "Empty",
      "level": 0
    },
    {
      "x": -1,
      "y": 4,
      "z": 0,
      "name": "Empty",
      "level": 0
    },
    {
      "x": -1,
      "y": 2,
      "z": 1,
      "name": "Empty",
      "level": 0
    },
    {
      "x": -1,
      "y": 3,
      "z": 1,
      "name": "Empty",
      "level": 0
    },
    {
      "x": 0,
      "y": 3,
      "z": -2,
      "name": "Empty",
      "level": 0
    },
    {
      "x": 0,
      "y": 2,
      "z": -1,
      "name": "Empty",
      "level": 0
    },
    {
      "x": 0,
      "y": 3,
      "z": -1,
      "name": "Empty",
      "level": 0
    },
    {
      "x": 0,
      "y": 4,
      "z": -1,
      "name": "Empty",
      "level": 0
    },
    {
      "x": 0,
      "y": 0,
      "z": 0,
      "name": "Empty",
      "level": 0
    },
    {
      "x": 0,
      "y": 1,
      "z": 0,
      "name": "Empty",
      "level": 0
    },
    {
      "x": 0,
      "y": 2,
      "z": 0,
      "name": "Empty",
      "level": 0
    },
    {
      "x": 0,
      "y": 3,
      "z": 0,
      "name": "Empty",
      "level": 0
    },
    {
      "x": 0,
      "y": 4,
      "z": 0,
      "name": "Empty",
      "level": 0
    },
    {
      "x": 0,
      "y": 5,
      "z": 0,
      "name": "Empty",
      "level": 0
    },
    {
      "x": 0,
      "y": 2,
      "z": 1,
      "name": "Empty",
      "level": 0
    },
    {
      "x": 0,
      "y": 3,
      "z": 1,
      "name": "Empty",
      "level": 0
    },
    {
      "x": 0,
      "y": 4,
      "z": 1,
      "name": "Empty",
      "level": 0
    },
    {
      "x": 0,
      "y": 3,
      "z": 2,
      "name": "Empty",
      "level": 0
    },
    {
      "x": 1,
      "y": 2,
      "z": -1,
      "name": "Empty",
      "level": 0
    },
    {
      "x": 1,
      "y": 3,
      "z": -1,
      "name": "Empty",
      "level": 0
    },
    {
      "x": 1,
      "y": 2,
      "z": 0,
      "name": "Empty",
      "level": 0
    },
    {
      "x": 1,
      "y": 3,
      "z": 0,
      "name": "Empty",
      "level": 0
    },
    {
      "x": 1,
      "y": 4,
      "z": 0,
      "name": "Empty",
      "level": 0
    },
    {
      "x": 1,
      "y": 2,
      "z": 1,
      "name": "Empty",
      "level": 0
    },
    {
      "x": 1,
      "y": 3,
      "z": 1,
      "name": "Empty",
      "level": 0
    },
    {
      "x": 2,
      "y": 3,
      "z": 0,
      "name": "Empty",
      "level": 0
    }
  ]
}